Workbook

Sheet Base de Dados
A1: Área | B1: Sistema | C1: Tipo | D1: TAG | E1: Descrição | F1: (PC) Etapa | G1: (PC) Pergunta 01 | H1: (PC) Pergunta 01 [Monitoramento] | I1: (PC) Pergunta 02 | J1: (PC) Pergunta 02 [Monitoramento] | K1: (PC) Pergunta 03 | L1: (PC) Pergunta 03 [Monitoramento] | M1: (PC) Pergunta 04 | N1: (PC) Pergunta 04 [Monitoramento] | O1: (PC) Pergunta 05 | P1: (PC) Pergunta 05 [Monitoramento] | Q1: (PC) Pergunta 06 | R1: (PC) Pergunta 06 [Monitoramento] | S1: (PC) Pergunta 07 | T1: (PC) Pergunta 07 [Monitoramento] | U1: (PC) Pergunta 08 | V1: (PC) Pergunta 08 [Monitoramento] | W1: (PC) Pergunta 09 | X1: (PC) Pergunta 09 [Monitoramento] | Y1: (PC) Pergunta 10 | Z1: (PC) Pergunta 10 [Monitoramento] | AA1: (PC) Pergunta 11 | AB1: (PC) Pergunta 11 [Monitoramento] | AC1: (PC) Pergunta 12 | AD1: (PC) Pergunta 12 [Monitoramento] | AE1: (PC) Pergunta 13 | AF1: (PC) Pergunta 13 [Monitoramento] | AG1: (PC) Pergunta 14 | AH1: (PC) Pergunta 14 [Monitoramento] | AI1: (PC) Pergunta 15 | AJ1: (PC) Pergunta 15 [Monitoramento] | AK1: (PC) Pergunta 16 | AL1: (PC) Pergunta 16 [Monitoramento] | AM1: (PC) Pergunta 17 | AN1: (PC) Pergunta 17 [Monitoramento] | AO1: (PC) Pergunta 18 | AP1: (PC) Pergunta 18 [Monitoramento] | AQ1: (PC) Pergunta 19 | AR1: (PC) Pergunta 19 [Monitoramento] | AS1: (PC) Pergunta 20 | AT1: (PC) Pergunta 20 [Monitoramento] | AU1: (PC) Pergunta 21 | AV1: (PC) Pergunta 21 [Monitoramento] | AW1: (PC) Pergunta 22 | AX1: (PC) Pergunta 22 [Monitoramento] | AY1: (PC) Pergunta 23 | AZ1: (PC) Pergunta 23 [Monitoramento] | BA1: (PC) Pergunta 24 | BB1: (PC) Pergunta 24 [Monitoramento] | BC1: (PC) Pergunta 25 | BD1: (PC) Pergunta 25 [Monitoramento] | BE1: (PC) Pergunta 26 | BF1: (PC) Pergunta 26 [Monitoramento] | BG1: (PC) Pergunta 27 | BH1: (PC) Pergunta 27 [Monitoramento] | BI1: (PC) Pergunta 28 | BJ1: (PC) Pergunta 28 [Monitoramento] | BK1: (PC) Pergunta 29 | BL1: (PC) Pergunta 29 [Monitoramento] | BM1: (PC) Pergunta 30 | BN1: (PC) Pergunta 30 [Monitoramento] | BO1: (PC) Não Conformidade ? | BP1: (PC) Status Mecânica | BQ1: (PC) Mecânica Concluída: | BR1: (PC) Status Elétrica | BS1: (PC) Elétrica Concluída: | BT1: (PC) Status Checklist | BU1: (PC) Checklist Concluído: | BV1: (CE) Etapa | BW1: (CE) Pergunta 01 | BX1: (CE) Pergunta 01 [Monitoramento] | BY1: (CE) Pergunta 02 | BZ1: (CE) Pergunta 02 [Monitoramento] | CA1: (CE) Pergunta 03 | CB1: (CE) Pergunta 03 [Monitoramento] | CC1: (CE) Pergunta 04 | CD1: (CE) Pergunta 04 [Monitoramento] | CE1: (CE) Pergunta 05 | CF1: (CE) Pergunta 05 [Monitoramento] | CG1: (CE) Pergunta 06 | CH1: (CE) Pergunta 06 [Monitoramento] | CI1: (CE) Pergunta 07 | CJ1: (CE) Pergunta 07 [Monitoramento] | CK1: (CE) Pergunta 08 | CL1: (CE) Pergunta 08 [Monitoramento] | CM1: (CE) Pergunta 09 | CN1: (CE) Pergunta 09 [Monitoramento] | CO1: (CE) Pergunta 10 | CP1: (CE) Pergunta 10 [Monitoramento] | CQ1: (CE) Pergunta 11 | CR1: (CE) Pergunta 11 [Monitoramento] | CS1: (CE) Pergunta 12 | CT1: (CE) Pergunta 12 [Monitoramento] | CU1: (CE) Pergunta 13 | CV1: (CE) Pergunta 13 [Monitoramento] | CW1: (CE) Pergunta 14 | CX1: (CE) Pergunta 14 [Monitoramento] | CY1: (CE) Pergunta 15 | CZ1: (CE) Pergunta 15 [Monitoramento] | DA1: (CE) Não Conformidade ? | DB1: (CE) Status Mecânica | DC1: (CE) Mecânica Concluída: | DD1: (CE) Status Elétrica | DE1: (CE) Elétrica Concluída: | DF1: (CE) Status Checklist | DG1: (CE) Checklist Concluído: | DH1: (DF) Etapa | DI1: (DF) Pergunta 01 | DJ1: (DF) Pergunta 01 [Monitoramento] | DK1: (DF) Pergunta 02 | DL1: (DF) Pergunta 02 [Monitoramento] | DM1: (DF) Pergunta 03 | DN1: (DF) Pergunta 03 [Monitoramento] | DO1: (DF) Pergunta 04 | DP1: (DF) Pergunta 04 [Monitoramento] | DQ1: (DF) Pergunta 05 | DR1: (DF) Pergunta 05 [Monitoramento] | DS1: (DF) Pergunta 06 | DT1: (DF) Pergunta 06 [Monitoramento] | DU1: (DF) Pergunta 07 | DV1: (DF) Pergunta 07 [Monitoramento] | DW1: (DF) Pergunta 08 | DX1: (DF) Pergunta 08 [Monitoramento] | DY1: (DF) Pergunta 09 | DZ1: (DF) Pergunta 09 [Monitoramento] | EA1: (DF) Pergunta 10 | EB1: (DF) Pergunta 10 [Monitoramento] | EC1: (DF) Não Conformidade ? | ED1: (DF) Status Checklist | EE1: (DF) Checklist Concluído: | EF1: (DQ) Etapa | EG1: (DQ) Pergunta 01 | EH1: (DQ) Pergunta 01 [Monitoramento] | EI1: (DQ) Pergunta 02 | EJ1: (DQ) Pergunta 02 [Monitoramento] | EK1: (DQ) Pergunta 03 | EL1: (DQ) Pergunta 03 [Monitoramento] | EM1: (DQ) Pergunta 04 | EN1: (DQ) Pergunta 04 [Monitoramento] | EO1: (DQ) Pergunta 05 | EP1: (DQ) Pergunta 05 [Monitoramento] | EQ1: (DQ) Pergunta 06 | ER1: (DQ) Pergunta 06 [Monitoramento] | ES1: (DQ) Pergunta 07 | ET1: (DQ) Pergunta 07 [Monitoramento] | EU1: (DQ) Pergunta 08 | EV1: (DQ) Pergunta 08 [Monitoramento] | EW1: (DQ) Pergunta 09 | EX1: (DQ) Pergunta 09 [Monitoramento] | EY1: (DQ) Pergunta 10 | EZ1: (DQ) Pergunta 10 [Monitoramento] | FA1: (DQ) Pergunta 11 | FB1: (DQ) Pergunta 11 [Monitoramento] | FC1: (DQ) Não Conformidade ? | FD1: (DQ) Status Checklist | FE1: (DQ) Checklist Concluído: | FF1: Observação: | FG1: Observação Registrada em: | FH1: Tem Observação? | FI1: Status do Questionário | FJ1: Status do Questionário Concluído: | FK1: Última atualização: | FL1: Imagem do Equipamento: | FM1: Imagem do Equipamento Registrada em: | FN1: Imagem da Plaqueta do Motor: | FO1: Imagem da Plaqueta do Motor Registrada em: | FP1: Imagem (Display) | FQ1: Imagem Indisponível | FR1: Imagem Indisponível [Monitoramento]
A2: 10&20 - R.P.E | B2: Hilo | C2: Motoredutor | D2: HL-1001 | E2: DESCARREGADOR DE CANA | F2: Pré-Comissionamento | G2: Conforme | H2: Rafael De Carvalho Vasconcelos - 20/02/2025 13:55:41 | I2: Conforme | J2: Rafael De Carvalho Vasconcelos - 22/01/2025 16:03:56 | K2: Conforme | L2: Rafael De Carvalho Vasconcelos - 22/01/2025 16:04:02 | M2: Conforme | N2: Rafael De Carvalho Vasconcelos - 22/01/2025 16:04:08 | O2: Conforme | P2: Rafael De Carvalho Vasconcelos - 22/01/2025 16:04:18 | Q2: Conforme | R2: Rafael De Carvalho Vasconcelos - 22/01/2025 16:04:21 | S2: Conforme | T2: Danilo Estanislau Pereira - 21/01/2025 09:13:19 | U2: Conforme | V2: Danilo Estanislau Pereira - 21/01/2025 09:13:20 | W2: Conforme | X2: Danilo Estanislau Pereira - 21/01/2025 09:13:22 | Y2: Conforme | Z2: Danilo Estanislau Pereira - 21/01/2025 09:13:24 | AA2: Conforme | AB2: Danilo Estanislau Pereira - 21/01/2025 09:13:25 | AC2: Conforme | AD2: Danilo Estanislau Pereira - 21/01/2025 09:13:26 | BO2: Não | BP2: Sim | BQ2: 45708.58 | BR2: Sim | BS2: 45678.384 | BT2: Sim | BU2: 45708.58 | BV2: Comissionamento Estático | BW2: Conforme | BX2: Denis Ueslei Lopes Romero - 12/03/2025 08:11:21 | BY2: Conforme | BZ2: Denis Ueslei Lopes Romero - 12/03/2025 08:11:23 | CA2: Conforme | CB2: Denis Ueslei Lopes Romero - 12/03/2025 08:11:25 | CC2: Conforme | CD2: Denis Ueslei Lopes Romero - 12/03/2025 08:11:27 | DA2: Não | DB2: Sim | DC2: 45728.341 | DD2: Sim | DE2: 45728.341 | DF2: Sim | DG2: 45728.341 | DH2: Dinâmico Frio | DI2: Conforme | DJ2: Rafael Schafaschek - 15/03/2025 10:31:44 | DK2: Conforme | DL2: Rafael Schafaschek - 15/03/2025 10:31:43 | DM2: Conforme | DN2: Rafael Schafaschek - 15/03/2025 10:31:43 | DO2: Conforme | DP2: Rafael Schafaschek - 15/03/2025 10:31:42 | DQ2: Conforme | DR2: Rafael Schafaschek - 15/03/2025 10:31:45 | EC2: Não | ED2: Sim | EE2: 45731.439 | EF2: Dinâmico Quente | EG2: Não Aplicável | EH2: Rafael Schafaschek - 15/03/2025 12:59:42 | EI2: Conforme | EJ2: Rafael Schafaschek - 15/03/2025 12:59:43 | EK2: Conforme | EL2: Rafael Schafaschek - 15/03/2025 12:59:43 | EM2: Conforme | EN2: Rafael Schafaschek - 15/03/2025 12:59:43 | FC2: Não | FD2: Sim | FE2: 45731.541 | FH2: Não | FI2: Feito | FJ2: 45731.541 | FK2: Rafael Schafaschek - 15/03/2025 12:59:43 | FL2: Base de Dados_Images/HL-1001.Imagem do Equipamento-.121315.jpg | FM2: Danilo Estanislau Pereira - 21/01/2025 09:12:58 | FN2: Base de Dados_Images/HL-1001.Imagem da Plaqueta do Motor-.121315.jpg | FO2: Danilo Estanislau Pereira - 21/01/2025 09:13:08 | FP2: =FL2 -> Base de Dados_Images/HL-1001.Imagem do Equipamento-.121315.jpg
A3: 10&20 - R.P.E | B3: Hilo | C3: Motor e Bomba | D3: HL-1001B | E3: BOMBA DE LUBRIFICAÇÃO HILO | F3: Pré-Comissionamento | G3: Conforme | H3: Rafael De Carvalho Vasconcelos - 20/02/2025 13:56:06 | I3: Conforme | J3: Rafael De Carvalho Vasconcelos - 22/01/2025 16:03:09 | K3: Conforme | L3: Rafael De Carvalho Vasconcelos - 22/01/2025 16:03:15 | M3: Conforme | N3: Rafael De Carvalho Vasconcelos - 22/01/2025 16:03:24 | O3: Conforme | P3: Rafael De Carvalho Vasconcelos - 22/01/2025 16:03:26 | Q3: Conforme | R3: Rafael De Carvalho Vasconcelos - 22/01/2025 16:03:28 | S3: Conforme | T3: Rafael De Carvalho Vasconcelos - 22/01/2025 16:03:30 | U3: Conforme | V3: Rafael De Carvalho Vasconcelos - 22/01/2025 16:03:32 | W3: Não Aplicável | X3: Rafael De Carvalho Vasconcelos - 22/01/2025 16:03:37 | Y3: Não Aplicável | Z3: Rafael De Carvalho Vasconcelos - 22/01/2025 16:03:38 | AA3: Conforme | AB3: Danilo Estanislau Pereira - 21/01/2025 09:15:19 | AC3: Conforme | AD3: Danilo Estanislau Pereira - 21/01/2025 09:15:20 | AE3: Conforme | AF3: Danilo Estanislau Pereira - 21/01/2025 09:15:23 | AG3: Conforme | AH3: Danilo Estanislau Pereira - 21/01/2025 09:15:27 | AI3: Conforme | AJ3: Danilo Estanislau Pereira - 21/01/2025 09:15:28 | AK3: Conforme | AL3: Danilo Estanislau Pereira - 21/01/2025 09:15:31 | BO3: Não | BP3: Sim | BQ3: 45679.669 | BR3: Sim | BS3: 45708.581 | BT3: Sim | BU3: 45708.581 | BV3: Comissionamento Estático | BW3: Conforme | BX3: Denis Ueslei Lopes Romero - 12/03/2025 08:10:37 | BY3: Conforme | BZ3: Denis Ueslei Lopes Romero - 12/03/2025 08:10:38 | CA3: Conforme | CB3: Denis Ueslei Lopes Romero - 12/03/2025 08:10:41 | CC3: Conforme | CD3: Denis Ueslei Lopes Romero - 12/03/2025 08:10:47 | CE3: Conforme | CF3: Denis Ueslei Lopes Romero - 12/03/2025 08:10:51 | CG3: Conforme | CH3: Denis Ueslei Lopes Romero - 12/03/2025 08:10:53 | DA3: Não | DB3: Sim | DC3: 45728.341 | DD3: Sim | DE3: 45728.341 | DF3: Sim | DG3: 45728.341 | DH3: Dinâmico Frio | DI3: Conforme | DJ3: Rafael Schafaschek - 15/03/2025 10:31:37 | DK3: Conforme | DL3: Rafael Schafaschek - 15/03/2025 10:31:37 | DM3: Conforme | DN3: Rafael Schafaschek - 15/03/2025 10:31:36 | DO3: Conforme | DP3: Rafael Schafaschek - 15/03/2025 10:31:36 | EC3: Não | ED3: Sim | EE3: 45731.439 | EF3: Dinâmico Quente | EG3: Não Aplicável | EH3: Rafael Schafaschek - 15/03/2025 12:59:36 | EI3: Conforme | EJ3: Rafael Schafaschek - 15/03/2025 12:59:38 | EK3: Conforme | EL3: Rafael Schafaschek - 15/03/2025 12:59:37 | EM3: Conforme | EN3: Rafael Schafaschek - 15/03/2025 12:59:37 | FC3: Não | FD3: Sim | FE3: 45731.541 | FH3: Não | FI3: Feito | FJ3: 45731.541 | FK3: Rafael Schafaschek - 15/03/2025 12:59:38 | FL3: Base de Dados_Images/HL-1001B.Imagem do Equipamento-.121507.jpg | FM3: Danilo Estanislau Pereira - 21/01/2025 09:14:37 | FN3: Base de Dados_Images/HL-1001B.Imagem da Plaqueta do Motor-.121507.jpg | FO3: Danilo Estanislau Pereira - 21/01/2025 09:15:01 | FP3: =FL3 -> Base de Dados_Images/HL-1001B.Imagem do Equipamento-.121507.jpg
A4: 10&20 - R.P.E | B4: Cush Cush | C4: Esteira Metálica | D4: ER-1001 | E4: ESTEIRA CUSH X CUSH DE PALHA | F4: Pré-Comissionamento | G4: Conforme | H4: Denis Ueslei Lopes Romero - 12/03/2025 08:18:04 | I4: Conforme | J4: Denis Ueslei Lopes Romero - 12/03/2025 08:18:04 | K4: Conforme | L4: Denis Ueslei Lopes Romero - 12/03/2025 08:18:06 | M4: Conforme | N4: Denis Ueslei Lopes Romero - 12/03/2025 08:18:08 | O4: Conforme | P4: Denis Ueslei Lopes Romero - 12/03/2025 08:18:10 | Q4: Conforme | R4: Denis Ueslei Lopes Romero - 12/03/2025 08:18:11 | S4: Conforme | T4: Denis Ueslei Lopes Romero - 12/03/2025 08:18:14 | U4: Conforme | V4: Denis Ueslei Lopes Romero - 12/03/2025 08:18:16 | W4: Conforme | X4: Denis Ueslei Lopes Romero - 12/03/2025 08:18:20 | Y4: Conforme | Z4: Denis Ueslei Lopes Romero - 12/03/2025 08:18:22 | AA4: Conforme | AB4: Denis Ueslei Lopes Romero - 12/03/2025 08:18:25 | AC4: Conforme | AD4: Denis Ueslei Lopes Romero - 12/03/2025 08:18:27 | AE4: Conforme | AF4: Denis Ueslei Lopes Romero - 12/03/2025 08:18:28 | AG4: Conforme | AH4: Denis Ueslei Lopes Romero - 12/03/2025 08:18:32 | AI4: Conforme | AJ4: Luis Antonio Batista - 11/03/2025 14:57:46 | AK4: Conforme | AL4: Denis Ueslei Lopes Romero - 12/03/2025 08:18:37 | AM4: Conforme | AN4: Luis Antonio Batista - 11/03/2025 14:57:53 | AO4: Conforme | AP4: Rafael Schafaschek - 14/03/2025 17:55:12 | AQ4: Conforme | AR4: Luis Antonio Batista - 11/03/2025 14:57:58 | AS4: Conforme | AT4: Luis Antonio Batista - 11/03/2025 14:58:01 | BO4: Não | BP4: Sim | BQ4: 45728.346 | BR4: Sim | BS4: 45730.747 | BT4: Sim | BU4: 45730.747 | BV4: Comissionamento Estático | BW4: Conforme | BX4: Rafael Schafaschek - 15/03/2025 09:49:54 | BY4: Conforme | BZ4: Rafael Schafaschek - 15/03/2025 09:49:54 | CA4: Conforme | CB4: Rafael Schafaschek - 15/03/2025 09:49:53 | CC4: Conforme | CD4: Rafael Schafaschek - 15/03/2025 09:49:55 | DA4: Não | DB4: Sim | DC4: 45731.41 | DD4: Sim | DE4: 45731.41 | DF4: Sim | DG4: 45731.41 | DH4: Dinâmico Frio | DI4: Conforme | DJ4: Rafael Schafaschek - 15/03/2025 09:50:05 | DK4: Conforme | DL4: Rafael Schafaschek - 15/03/2025 09:50:05 | DM4: Conforme | DN4: Rafael Schafaschek - 15/03/2025 09:50:05 | DO4: Conforme | DP4: Rafael Schafaschek - 15/03/2025 09:50:08 | DQ4: Conforme | DR4: Rafael Schafaschek - 15/03/2025 09:50:07 | DS4: Conforme | DT4: Rafael Schafaschek - 15/03/2025 09:50:09 | EC4: Não | ED4: Sim | EE4: 45731.41 | EF4: Dinâmico Quente | EG4: Conforme | EH4: Rafael Schafaschek - 15/03/2025 12:59:53 | EI4: Conforme | EJ4: Rafael Schafaschek - 15/03/2025 12:59:54 | FC4: Não | FD4: Sim | FE4: 45731.542 | FH4: Não | FI4: Feito | FJ4: 45731.542 | FK4: Rafael Schafaschek - 15/03/2025 12:59:54 | FL4: Base de Dados_Images/ER-1001.Imagem do Equipamento-.175735.jpg | FM4: Luis Antonio Batista - 11/03/2025 14:57:30 | FP4: =FL4 -> Base de Dados_Images/ER-1001.Imagem do Equipamento-.175735.jpg
A5: 10&20 - R.P.E | B5: Mesa N°1 | C5: Mesa Alimentadora | D5: MA-1001-A | E5: ACIONAMENTO MESA Nº1 LD | F5: Pré-Comissionamento | G5: Conforme | H5: Denis Ueslei Lopes Romero - 12/03/2025 08:13:52 | I5: Conforme | J5: Denis Ueslei Lopes Romero - 12/03/2025 08:13:53 | K5: Conforme | L5: Denis Ueslei Lopes Romero - 12/03/2025 08:13:58 | M5: Conforme | N5: Denis Ueslei Lopes Romero - 12/03/2025 08:13:59 | O5: Conforme | P5: Denis Ueslei Lopes Romero - 12/03/2025 08:14:02 | Q5: Conforme | R5: Denis Ueslei Lopes Romero - 12/03/2025 08:14:03 | S5: Conforme | T5: Denis Ueslei Lopes Romero - 12/03/2025 08:14:26 | U5: Conforme | V5: Denis Ueslei Lopes Romero - 12/03/2025 08:14:27 | W5: Conforme | X5: Denis Ueslei Lopes Romero - 12/03/2025 08:14:30 | Y5: Conforme | Z5: Denis Ueslei Lopes Romero - 12/03/2025 08:14:32 | AA5: Conforme | AB5: Rafael Schafaschek - 14/03/2025 17:55:26 | AC5: Conforme | AD5: Denis Ueslei Lopes Romero - 12/03/2025 08:14:53 | AE5: Conforme | AF5: Denis Ueslei Lopes Romero - 12/03/2025 08:14:54 | AG5: Conforme | AH5: Denis Ueslei Lopes Romero - 12/03/2025 08:14:56 | AI5: Conforme | AJ5: Denis Ueslei Lopes Romero - 12/03/2025 08:14:58 | AK5: Conforme | AL5: Denis Ueslei Lopes Romero - 12/03/2025 08:15:00 | AM5: Conforme | AN5: Denis Ueslei Lopes Romero - 12/03/2025 08:15:01 | AO5: Conforme | AP5: Denis Ueslei Lopes Romero - 12/03/2025 08:15:02 | AQ5: Conforme | AR5: Denis Ueslei Lopes Romero - 12/03/2025 08:15:03 | AS5: Conforme | AT5: Denis Ueslei Lopes Romero - 12/03/2025 08:15:04 | AU5: Conforme | AV5: Denis Ueslei Lopes Romero - 12/03/2025 08:15:06 | BO5: Não | BP5: Sim | BQ5: 45730.747 | BR5: Sim | BS5: 45728.344 | BT5: Sim | BU5: 45730.747 | BV5: Comissionamento Estático | BW5: Conforme | BX5: Gabriel Batista Cousso - 12/03/2025 13:35:12 | BY5: Conforme | BZ5: Denis Ueslei Lopes Romero - 15/03/2025 08:22:55 | CA5: Conforme | CB5: Denis Ueslei Lopes Romero - 15/03/2025 08:22:55 | CC5: Conforme | CD5: Denis Ueslei Lopes Romero - 15/03/2025 08:22:55 | DA5: Não | DB5: Sim | DC5: 45728.566 | DD5: Sim | DE5: 45731.349 | DF5: Sim | DG5: 45731.349 | DH5: Dinâmico Frio | DI5: Conforme | DJ5: Rafael Schafaschek - 15/03/2025 10:18:06 | DK5: Conforme | DL5: Rafael Schafaschek - 15/03/2025 10:18:06 | DM5: Conforme | DN5: Rafael Schafaschek - 15/03/2025 10:18:06 | EC5: Não | ED5: Sim | EE5: 45731.429 | EF5: Dinâmico Quente | FC5: Não | FD5: Não Aplica | FH5: Não | FI5: Feito | FJ5: 45731.429 | FK5: Rafael Schafaschek - 15/03/2025 10:18:06 | FP5: =FL5
A6: 10&20 - R.P.E | B6: Mesa N°1 | C6: Mesa Alimentadora | D6: MA-1001-B | E6: ACIONAMENTO MESA Nº1 LE | F6: Pré-Comissionamento | G6: Conforme | H6: Denis Ueslei Lopes Romero - 12/03/2025 08:15:58 | I6: Conforme | J6: Denis Ueslei Lopes Romero - 12/03/2025 08:15:58 | K6: Conforme | L6: Denis Ueslei Lopes Romero - 12/03/2025 08:16:01 | M6: Conforme | N6: Denis Ueslei Lopes Romero - 12/03/2025 08:16:03 | O6: Conforme | P6: Denis Ueslei Lopes Romero - 12/03/2025 08:16:28 | Q6: Conforme | R6: Denis Ueslei Lopes Romero - 12/03/2025 08:16:30 | S6: Conforme | T6: Denis Ueslei Lopes Romero - 12/03/2025 08:16:31 | U6: Conforme | V6: Denis Ueslei Lopes Romero - 12/03/2025 08:16:33 | W6: Conforme | X6: Denis Ueslei Lopes Romero - 12/03/2025 08:16:34 | Y6: Conforme | Z6: Denis Ueslei Lopes Romero - 12/03/2025 08:16:41 | AA6: Conforme | AB6: Rafael Schafaschek - 14/03/2025 17:55:34 | AC6: Conforme | AD6: Denis Ueslei Lopes Romero - 12/03/2025 08:16:46 | AE6: Conforme | AF6: Denis Ueslei Lopes Romero - 12/03/2025 08:16:48 | AG6: Conforme | AH6: Denis Ueslei Lopes Romero - 12/03/2025 08:16:48 | AI6: Conforme | AJ6: Denis Ueslei Lopes Romero - 12/03/2025 08:16:49 | AK6: Conforme | AL6: Luis Antonio Batista - 11/03/2025 15:01:41 | AM6: Conforme | AN6: Luis Antonio Batista - 11/03/2025 15:01:46 | AO6: Conforme | AP6: Luis Antonio Batista - 11/03/2025 15:01:47 | AQ6: Conforme | AR6: Luis Antonio Batista - 11/03/2025 15:01:52 | AS6: Conforme | AT6: Luis Antonio Batista - 11/03/2025 15:01:55 | AU6: Conforme | AV6: Luis Antonio Batista - 11/03/2025 15:01:57 | BO6: Não | BP6: Sim | BQ6: 45730.747 | BR6: Sim | BS6: 45727.626 | BT6: Sim | BU6: 45730.747 | BV6: Comissionamento Estático | BW6: Conforme | BX6: Gabriel Batista Cousso - 12/03/2025 13:35:20 | BY6: Conforme | BZ6: Denis Ueslei Lopes Romero - 15/03/2025 08:22:44 | CA6: Conforme | CB6: Denis Ueslei Lopes Romero - 15/03/2025 08:22:44 | CC6: Conforme | CD6: Denis Ueslei Lopes Romero - 15/03/2025 08:22:43 | DA6: Não | DB6: Sim | DC6: 45728.566 | DD6: Sim | DE6: 45731.349 | DF6: Sim | DG6: 45731.349 | DH6: Dinâmico Frio | DI6: Conforme | DJ6: Rafael Schafaschek - 15/03/2025 10:18:13 | DK6: Conforme | DL6: Rafael Schafaschek - 15/03/2025 10:18:12 | DM6: Conforme | DN6: Rafael Schafaschek - 15/03/2025 10:18:12 | EC6: Não | ED6: Sim | EE6: 45731.429 | EF6: Dinâmico Quente | FC6: Não | FD6: Não Aplica | FH6: Não | FI6: Feito | FJ6: 45731.429 | FK6: Rafael Schafaschek - 15/03/2025 10:18:13 | FL6: Base de Dados_Images/MA-1001-B.Imagem do Equipamento-.180111.jpg | FM6: Luis Antonio Batista - 11/03/2025 15:01:05 | FP6: =FL6 -> Base de Dados_Images/MA-1001-B.Imagem do Equipamento-.180111.jpg
A7: 10&20 - R.P.E | B7: Mesa N°2 | C7: Mesa Alimentadora | D7: MA-1002-A | E7: ACIONAMENTO MESA Nº2 LD | F7: Pré-Comissionamento | G7: Conforme | H7: Denis Ueslei Lopes Romero - 12/03/2025 08:17:23 | I7: Conforme | J7: Denis Ueslei Lopes Romero - 12/03/2025 08:17:27 | K7: Conforme | L7: Denis Ueslei Lopes Romero - 12/03/2025 08:17:25 | M7: Conforme | N7: Denis Ueslei Lopes Romero - 12/03/2025 08:17:30 | O7: Conforme | P7: Denis Ueslei Lopes Romero - 12/03/2025 08:17:31 | Q7: Conforme | R7: Denis Ueslei Lopes Romero - 12/03/2025 08:17:33 | S7: Conforme | T7: Denis Ueslei Lopes Romero - 12/03/2025 08:17:34 | U7: Conforme | V7: Denis Ueslei Lopes Romero - 12/03/2025 08:17:46 | W7: Conforme | X7: Denis Ueslei Lopes Romero - 12/03/2025 08:17:47 | Y7: Conforme | Z7: Rafael Schafaschek - 14/03/2025 17:53:47 | AA7: Conforme | AB7: Rafael Schafaschek - 14/03/2025 17:53:47 | AC7: Conforme | AD7: Denis Ueslei Lopes Romero - 12/03/2025 09:34:15 | AE7: Conforme | AF7: Denis Ueslei Lopes Romero - 12/03/2025 09:33:49 | AG7: Conforme | AH7: Denis Ueslei Lopes Romero - 12/03/2025 09:33:47 | AI7: Conforme | AJ7: Denis Ueslei Lopes Romero - 12/03/2025 09:33:48 | AK7: Conforme | AL7: Denis Ueslei Lopes Romero - 12/03/2025 09:33:59 | AM7: Conforme | AN7: Denis Ueslei Lopes Romero - 12/03/2025 09:34:01 | AO7: Conforme | AP7: Denis Ueslei Lopes Romero - 12/03/2025 09:34:02 | AQ7: Conforme | AR7: Denis Ueslei Lopes Romero - 12/03/2025 09:34:09 | AS7: Conforme | AT7: Denis Ueslei Lopes Romero - 12/03/2025 09:34:06 | AU7: Conforme | AV7: Denis Ueslei Lopes Romero - 12/03/2025 09:34:11 | BO7: Não | BP7: Sim | BQ7: 45730.746 | BR7: Sim | BS7: 45728.399 | BT7: Sim | BU7: 45730.746 | BV7: Comissionamento Estático | BW7: Conforme | BX7: Denis Ueslei Lopes Romero - 15/03/2025 08:23:18 | BY7: Conforme | BZ7: Denis Ueslei Lopes Romero - 15/03/2025 08:23:17 | CA7: Conforme | CB7: Denis Ueslei Lopes Romero - 15/03/2025 08:23:17 | CC7: Conforme | CD7: Denis Ueslei Lopes Romero - 15/03/2025 08:23:17 | DA7: Não | DB7: Sim | DC7: 45731.35 | DD7: Sim | DE7: 45731.35 | DF7: Sim | DG7: 45731.35 | DH7: Dinâmico Frio | DI7: Conforme | DJ7: Rafael Schafaschek - 15/03/2025 10:18:22 | DK7: Conforme | DL7: Rafael Schafaschek - 15/03/2025 10:18:22 | DM7: Conforme | DN7: Rafael Schafaschek - 15/03/2025 10:18:21 | EC7: Não | ED7: Sim | EE7: 45731.429 | EF7: Dinâmico Quente | FC7: Não | FD7: Não Aplica | FH7: Não | FI7: Feito | FJ7: 45731.429 | FK7: Rafael Schafaschek - 15/03/2025 10:18:22 | FP7: =FL7
A8: 10&20 - R.P.E | B8: Mesa N°2 | C8: Mesa Alimentadora | D8: MA-1002-B | E8: ACIONAMENTO MESA Nº2 LE | F8: Pré-Comissionamento | G8: Conforme | H8: Denis Ueslei Lopes Romero - 12/03/2025 09:34:27 | I8: Conforme | J8: Denis Ueslei Lopes Romero - 12/03/2025 09:34:29 | K8: Conforme | L8: Denis Ueslei Lopes Romero - 12/03/2025 09:34:31 | M8: Conforme | N8: Denis Ueslei Lopes Romero - 12/03/2025 09:34:32 | O8: Conforme | P8: Denis Ueslei Lopes Romero - 12/03/2025 09:34:34 | Q8: Conforme | R8: Denis Ueslei Lopes Romero - 12/03/2025 09:34:35 | S8: Conforme | T8: Denis Ueslei Lopes Romero - 12/03/2025 09:34:37 | U8: Conforme | V8: Denis Ueslei Lopes Romero - 12/03/2025 09:34:38 | W8: Conforme | X8: Denis Ueslei Lopes Romero - 12/03/2025 09:34:40 | Y8: Conforme | Z8: Denis Ueslei Lopes Romero - 12/03/2025 09:34:42 | AA8: Conforme | AB8: Rafael Schafaschek - 14/03/2025 17:53:57 | AC8: Conforme | AD8: Denis Ueslei Lopes Romero - 12/03/2025 09:34:46 | AE8: Conforme | AF8: Denis Ueslei Lopes Romero - 12/03/2025 09:34:48 | AG8: Conforme | AH8: Denis Ueslei Lopes Romero - 12/03/2025 09:34:49 | AI8: Conforme | AJ8: Denis Ueslei Lopes Romero - 12/03/2025 09:34:51 | AK8: Conforme | AL8: Luis Antonio Batista - 11/03/2025 15:03:16 | AM8: Conforme | AN8: Luis Antonio Batista - 11/03/2025 15:03:19 | AO8: Conforme | AP8: Luis Antonio Batista - 11/03/2025 15:03:23 | AQ8: Conforme | AR8: Luis Antonio Batista - 11/03/2025 15:03:27 | AS8: Conforme | AT8: Luis Antonio Batista - 11/03/2025 15:03:29 | AU8: Conforme | AV8: Luis Antonio Batista - 11/03/2025 15:03:31 | BO8: Não | BP8: Sim | BQ8: 45730.746 | BR8: Sim | BS8: 45727.627 | BT8: Sim | BU8: 45730.746 | BV8: Comissionamento Estático | BW8: Conforme | BX8: Denis Ueslei Lopes Romero - 15/03/2025 08:23:26 | BY8: Conforme | BZ8: Denis Ueslei Lopes Romero - 15/03/2025 08:23:25 | CA8: Conforme | CB8: Denis Ueslei Lopes Romero - 15/03/2025 08:23:25 | CC8: Conforme | CD8: Denis Ueslei Lopes Romero - 15/03/2025 08:23:25 | DA8: Não | DB8: Sim | DC8: 45731.35 | DD8: Sim | DE8: 45731.35 | DF8: Sim | DG8: 45731.35 | DH8: Dinâmico Frio | DI8: Conforme | DJ8: Rafael Schafaschek - 15/03/2025 10:18:27 | DK8: Conforme | DL8: Rafael Schafaschek - 15/03/2025 10:18:26 | DM8: Conforme | DN8: Rafael Schafaschek - 15/03/2025 10:18:26 | EC8: Não | ED8: Sim | EE8: 45731.429 | EF8: Dinâmico Quente | FC8: Não | FD8: Não Aplica | FH8: Não | FI8: Feito | FJ8: 45731.429 | FK8: Rafael Schafaschek - 15/03/2025 10:18:27 | FL8: Base de Dados_Images/MA-1002-B.Imagem do Equipamento-.180254.jpg | FM8: Luis Antonio Batista - 11/03/2025 15:02:50 | FP8: =FL8 -> Base de Dados_Images/MA-1002-B.Imagem do Equipamento-.180254.jpg
A9: 10&20 - R.P.E | B9: Picador 2 | C9: Transmissor | D9: TRM-123-01 | E9: PRESSÃO ÓLEO DA TURBINA DO PICADOR 2 | F9: Pré-Comissionamento | G9: Conforme | H9: Gabriel Batista Cousso - 11/03/2025 11:27:24 | I9: Conforme | J9: Gabriel Batista Cousso - 11/03/2025 11:27:24 | K9: Conforme | L9: Gabriel Batista Cousso - 11/03/2025 11:27:25 | M9: Conforme | N9: Gabriel Batista Cousso - 11/03/2025 11:27:26 | BO9: Não | BP9: Sim | BQ9: 45727.477 | BR9: Sim | BS9: 45727.477 | BT9: Sim | BU9: 45727.477 | BV9: Comissionamento Estático | BW9: Conforme | BX9: Gabriel Batista Cousso - 11/03/2025 12:56:36 | BY9: Conforme | BZ9: Gabriel Batista Cousso - 11/03/2025 12:56:36 | CA9: Conforme | CB9: Gabriel Batista Cousso - 11/03/2025 12:56:37 | DA9: Não | DB9: Não Aplica | DD9: Sim | DE9: 45727.539 | DF9: Sim | DG9: 45727.539 | DH9: Dinâmico Frio | DI9: Conforme | DJ9: Gabriel Batista Cousso - 12/03/2025 14:29:42 | DK9: Conforme | DL9: Gabriel Batista Cousso - 12/03/2025 14:29:42 | EC9: Não | ED9: Sim | EE9: 45728.604 | EF9: Dinâmico Quente | EG9: Conforme | EH9: Rafael Schafaschek - 15/03/2025 13:00:17 | EI9: Conforme | EJ9: Rafael Schafaschek - 15/03/2025 13:00:17 | FC9: Não | FD9: Sim | FE9: 45731.542 | FH9: Não | FI9: Feito | FJ9: 45731.542 | FK9: Rafael Schafaschek - 15/03/2025 13:00:17 | FL9: Base de Dados_Images/TRM-123-01.Imagem do Equipamento-.194910.jpg | FM9: Eliezer Vieira Dutra - 12/03/2025 16:49:03 | FP9: =FL9 -> Base de Dados_Images/TRM-123-01.Imagem do Equipamento-.194910.jpg
A10: 10&20 - R.P.E | B10: Picador 2 | C10: Transmissor | D10: TRM-119-01 | E10: PRESSÃO VAPOR DE ADMISSÃO DO PICADOR 2 | F10: Pré-Comissionamento | G10: Conforme | H10: Gabriel Batista Cousso - 11/03/2025 11:27:29 | I10: Conforme | J10: Gabriel Batista Cousso - 11/03/2025 11:27:30 | K10: Conforme | L10: Gabriel Batista Cousso - 11/03/2025 11:27:31 | M10: Conforme | N10: Gabriel Batista Cousso - 11/03/2025 11:27:31 | BO10: Não | BP10: Sim | BQ10: 45727.477 | BR10: Sim | BS10: 45727.477 | BT10: Sim | BU10: 45727.477 | BV10: Comissionamento Estático | BW10: Conforme | BX10: Gabriel Batista Cousso - 11/03/2025 12:56:42 | BY10: Conforme | BZ10: Gabriel Batista Cousso - 11/03/2025 12:56:42 | CA10: Conforme | CB10: Gabriel Batista Cousso - 11/03/2025 12:56:42 | DA10: Não | DB10: Não Aplica | DD10: Sim | DE10: 45727.539 | DF10: Sim | DG10: 45727.539 | DH10: Dinâmico Frio | DI10: Conforme | DJ10: Gabriel Batista Cousso - 12/03/2025 14:29:46 | DK10: Conforme | DL10: Gabriel Batista Cousso - 12/03/2025 14:29:47 | EC10: Não | ED10: Sim | EE10: 45728.604 | EF10: Dinâmico Quente | EG10: Conforme | EH10: Rafael Schafaschek - 15/03/2025 13:00:20 | EI10: Conforme | EJ10: Rafael Schafaschek - 15/03/2025 13:00:20 | FC10: Não | FD10: Sim | FE10: 45731.542 | FH10: Não | FI10: Feito | FJ10: 45731.542 | FK10: Rafael Schafaschek - 15/03/2025 13:00:20 | FL10: Base de Dados_Images/TRM-119-01.Imagem do Equipamento-.194935.jpg | FM10: Eliezer Vieira Dutra - 12/03/2025 16:49:27 | FP10: =FL10 -> Base de Dados_Images/TRM-119-01.Imagem do Equipamento-.194935.jpg
A11: 10&20 - R.P.E | B11: Picador 2 | C11: Transmissor | D11: TRM-121-01 | E11: PRESSÃO VAPOR DE ESCAPE DO PICADOR 2 | F11: Pré-Comissionamento | G11: Conforme | H11: Gabriel Batista Cousso - 11/03/2025 11:27:35 | I11: Conforme | J11: Gabriel Batista Cousso - 11/03/2025 11:27:36 | K11: Conforme | L11: Gabriel Batista Cousso - 11/03/2025 11:27:36 | M11: Conforme | N11: Gabriel Batista Cousso - 11/03/2025 11:27:37 | BO11: Não | BP11: Sim | BQ11: 45727.477 | BR11: Sim | BS11: 45727.478 | BT11: Sim | BU11: 45727.478 | BV11: Comissionamento Estático | BW11: Conforme | BX11: Gabriel Batista Cousso - 11/03/2025 12:56:46 | BY11: Conforme | BZ11: Gabriel Batista Cousso - 11/03/2025 12:56:47 | CA11: Conforme | CB11: Gabriel Batista Cousso - 11/03/2025 12:56:47 | DA11: Não | DB11: Não Aplica | DD11: Sim | DE11: 45727.539 | DF11: Sim | DG11: 45727.539 | DH11: Dinâmico Frio | DI11: Conforme | DJ11: Gabriel Batista Cousso - 12/03/2025 14:29:50 | DK11: Conforme | DL11: Gabriel Batista Cousso - 12/03/2025 14:29:50 | EC11: Não | ED11: Sim | EE11: 45728.604 | EF11: Dinâmico Quente | EG11: Conforme | EH11: Rafael Schafaschek - 15/03/2025 13:00:24 | EI11: Conforme | EJ11: Rafael Schafaschek - 15/03/2025 13:00:24 | FC11: Não | FD11: Sim | FE11: 45731.542 | FH11: Não | FI11: Feito | FJ11: 45731.542 | FK11: Rafael Schafaschek - 15/03/2025 13:00:24 | FL11: Base de Dados_Images/TRM-121-01.Imagem do Equipamento-.195023.jpg | FM11: Eliezer Vieira Dutra - 12/03/2025 16:50:14 | FP11: =FL11 -> Base de Dados_Images/TRM-121-01.Imagem do Equipamento-.195023.jpg
A12: 10&20 - R.P.E | B12: Picador 2 | C12: Transmissor | D12: TRM-120-01 | E12: PRESSÃOCÂMARA DA RODA DO PICADOR 2 | F12: Pré-Comissionamento | G12: Conforme | H12: Gabriel Batista Cousso - 11/03/2025 11:27:41 | I12: Conforme | J12: Gabriel Batista Cousso - 11/03/2025 11:27:42 | K12: Conforme | L12: Gabriel Batista Cousso - 11/03/2025 11:27:43 | M12: Conforme | N12: Gabriel Batista Cousso - 11/03/2025 11:27:44 | BO12: Não | BP12: Sim | BQ12: 45727.478 | BR12: Sim | BS12: 45727.478 | BT12: Sim | BU12: 45727.478 | BV12: Comissionamento Estático | BW12: Conforme | BX12: Gabriel Batista Cousso - 11/03/2025 12:57:16 | BY12: Conforme | BZ12: Gabriel Batista Cousso - 11/03/2025 12:57:16 | CA12: Conforme | CB12: Gabriel Batista Cousso - 11/03/2025 12:57:17 | DA12: Não | DB12: Não Aplica | DD12: Sim | DE12: 45727.54 | DF12: Sim | DG12: 45727.54 | DH12: Dinâmico Frio | DI12: Conforme | DJ12: Gabriel Batista Cousso - 12/03/2025 14:29:54 | DK12: Conforme | DL12: Gabriel Batista Cousso - 12/03/2025 14:29:54 | EC12: Não | ED12: Sim | EE12: 45728.604 | EF12: Dinâmico Quente | EG12: Conforme | EH12: Rafael Schafaschek - 15/03/2025 13:00:29 | EI12: Conforme | EJ12: Rafael Schafaschek - 15/03/2025 13:00:28 | FC12: Não | FD12: Sim | FE12: 45731.542 | FH12: Não | FI12: Feito | FJ12: 45731.542 | FK12: Rafael Schafaschek - 15/03/2025 13:00:29 | FP12: =FL12
A13: 10&20 - R.P.E | B13: Picador 2 | C13: Transmissor | D13: TRM-150-01 | E13: PRESSÃO DE ÓLEO P1 | F13: Pré-Comissionamento | G13: Conforme | H13: Gabriel Batista Cousso - 11/03/2025 11:27:48 | I13: Conforme | J13: Gabriel Batista Cousso - 11/03/2025 11:27:49 | K13: Conforme | L13: Gabriel Batista Cousso - 11/03/2025 11:27:49 | M13: Conforme | N13: Gabriel Batista Cousso - 11/03/2025 11:27:50 | BO13: Não | BP13: Sim | BQ13: 45727.478 | BR13: Sim | BS13: 45727.478 | BT13: Sim | BU13: 45727.478 | BV13: Comissionamento Estático | BW13: Conforme | BX13: Gabriel Batista Cousso - 11/03/2025 12:57:22 | BY13: Conforme | BZ13: Gabriel Batista Cousso - 11/03/2025 12:57:22 | CA13: Conforme | CB13: Gabriel Batista Cousso - 11/03/2025 12:57:22 | DA13: Não | DB13: Não Aplica | DD13: Sim | DE13: 45727.54 | DF13: Sim | DG13: 45727.54 | DH13: Dinâmico Frio | DI13: Conforme | DJ13: Gabriel Batista Cousso - 12/03/2025 14:29:59 | DK13: Conforme | DL13: Gabriel Batista Cousso - 12/03/2025 14:29:59 | EC13: Não | ED13: Sim | EE13: 45728.604 | EF13: Dinâmico Quente | EG13: Conforme | EH13: Rafael Schafaschek - 15/03/2025 13:00:33 | EI13: Conforme | EJ13: Rafael Schafaschek - 15/03/2025 13:00:32 | FC13: Não | FD13: Sim | FE13: 45731.542 | FH13: Não | FI13: Feito | FJ13: 45731.542 | FK13: Rafael Schafaschek - 15/03/2025 13:00:33 | FP13: =FL13
A14: 10&20 - R.P.E | B14: Picador 2 | C14: Desfibrador/Picador | D14: PC-2002 | E14: PICADOR DE CANA Nº 2 | F14: Pré-Comissionamento | G14: Conforme | H14: Gabriel Batista Cousso - 12/03/2025 14:30:10 | I14: Conforme | J14: Denis Ueslei Lopes Romero - 12/03/2025 07:56:25 | K14: Conforme | L14: Denis Ueslei Lopes Romero - 12/03/2025 07:56:29 | M14: Conforme | N14: Denis Ueslei Lopes Romero - 12/03/2025 07:56:31 | O14: Conforme | P14: Denis Ueslei Lopes Romero - 12/03/2025 07:56:35 | Q14: Conforme | R14: Denis Ueslei Lopes Romero - 12/03/2025 07:56:44 | S14: Conforme | T14: Denis Ueslei Lopes Romero - 12/03/2025 07:56:54 | U14: Conforme | V14: Denis Ueslei Lopes Romero - 12/03/2025 07:57:00 | W14: Conforme | X14: Denis Ueslei Lopes Romero - 12/03/2025 07:57:03 | Y14: Não Aplicável | Z14: Denis Ueslei Lopes Romero - 12/03/2025 07:57:18 | AA14: Não Aplicável | AB14: Denis Ueslei Lopes Romero - 12/03/2025 07:57:29 | AC14: Conforme | AD14: Denis Ueslei Lopes Romero - 12/03/2025 07:57:52 | AE14: Conforme | AF14: Denis Ueslei Lopes Romero - 12/03/2025 07:58:18 | AG14: Conforme | AH14: Denis Ueslei Lopes Romero - 12/03/2025 07:58:21 | AI14: Não Aplicável | AJ14: Denis Ueslei Lopes Romero - 12/03/2025 07:58:27 | BO14: Não | BP14: Sim | BQ14: 45728.604 | BR14: Sim | BS14: 45728.332 | BT14: Sim | BU14: 45728.604 | BV14: Comissionamento Estático | BW14: Conforme | BX14: Denis Ueslei Lopes Romero - 12/03/2025 07:58:52 | BY14: Conforme | BZ14: Denis Ueslei Lopes Romero - 12/03/2025 07:58:58 | CA14: Conforme | CB14: Denis Ueslei Lopes Romero - 12/03/2025 07:59:02 | CC14: Conforme | CD14: Denis Ueslei Lopes Romero - 12/03/2025 07:59:11 | CE14: Conforme | CF14: Denis Ueslei Lopes Romero - 12/03/2025 07:59:16 | CG14: Conforme | CH14: Denis Ueslei Lopes Romero - 12/03/2025 07:59:20 | CI14: Conforme | CJ14: Denis Ueslei Lopes Romero - 12/03/2025 07:59:30 | CK14: Conforme | CL14: Denis Ueslei Lopes Romero - 12/03/2025 07:59:41 | DA14: Não | DB14: Sim | DC14: 45728.333 | DD14: Sim | DE14: 45728.333 | DF14: Sim | DG14: 45728.333 | DH14: Dinâmico Frio | DI14: Conforme | DJ14: Gabriel Batista Cousso - 12/03/2025 14:30:21 | DK14: Conforme | DL14: Gabriel Batista Cousso - 12/03/2025 14:30:22 | DM14: Conforme | DN14: Gabriel Batista Cousso - 12/03/2025 14:30:24 | DO14: Conforme | DP14: Gabriel Batista Cousso - 12/03/2025 14:30:28 | DQ14: Conforme | DR14: Rafael Schafaschek - 15/03/2025 10:34:08 | DS14: Conforme | DT14: Rafael Schafaschek - 15/03/2025 10:34:08 | DU14: Conforme | DV14: Rafael Schafaschek - 15/03/2025 10:34:07 | EC14: Não | ED14: Sim | EE14: 45731.44 | EF14: Dinâmico Quente | FC14: Não | FD14: Não Aplica | FH14: Não | FI14: Feito | FJ14: 45731.44 | FK14: Rafael Schafaschek - 15/03/2025 10:34:08 | FP14: =FL14
A15: 10&20 - R.P.E | B15: Picador 2 | C15: Indicador | D15: SENSOR_VIBRACAO_L_N_A_PICADOR_2 | E15: VIBRAÇÃO M L A PICADOR N°2 | F15: Pré-Comissionamento | G15: Conforme | H15: Gabriel Batista Cousso - 11/03/2025 10:47:00 | I15: Conforme | J15: Gabriel Batista Cousso - 11/03/2025 10:47:01 | K15: Conforme | L15: Gabriel Batista Cousso - 11/03/2025 10:47:02 | M15: Conforme | N15: Gabriel Batista Cousso - 11/03/2025 10:47:04 | BO15: Não | BP15: Sim | BQ15: 45727.449 | BR15: Sim | BS15: 45727.449 | BT15: Sim | BU15: 45727.449 | BV15: Comissionamento Estático | BW15: Conforme | BX15: Gabriel Batista Cousso - 11/03/2025 12:56:15 | BY15: Conforme | BZ15: Gabriel Batista Cousso - 11/03/2025 12:56:16 | CA15: Conforme | CB15: Gabriel Batista Cousso - 11/03/2025 12:56:16 | DA15: Não | DB15: Não Aplica | DD15: Sim | DE15: 45727.539 | DF15: Sim | DG15: 45727.539 | DH15: Dinâmico Frio | DI15: Conforme | DJ15: Gabriel Batista Cousso - 12/03/2025 14:27:06 | DK15: Conforme | DL15: Gabriel Batista Cousso - 12/03/2025 14:27:07 | EC15: Não | ED15: Sim | EE15: 45728.602 | EF15: Dinâmico Quente | EG15: Conforme | EH15: Rafael Schafaschek - 15/03/2025 13:00:02 | EI15: Conforme | EJ15: Rafael Schafaschek - 15/03/2025 13:00:02 | FC15: Não | FD15: Sim | FE15: 45731.542 | FH15: Não | FI15: Feito | FJ15: 45731.542 | FK15: Rafael Schafaschek - 15/03/2025 13:00:02 | FP15: =FL15
A16: 10&20 - R.P.E | B16: Picador 2 | C16: Indicador | D16: SENSOR_VIBRACAO_L_A_PICADOR_2 | E16: VIBRAÇÃO M L N A PICADOR N°2 | F16: Pré-Comissionamento | G16: Conforme | H16: Gabriel Batista Cousso - 11/03/2025 10:47:20 | I16: Conforme | J16: Gabriel Batista Cousso - 11/03/2025 10:47:21 | K16: Conforme | L16: Gabriel Batista Cousso - 11/03/2025 10:47:22 | M16: Conforme | N16: Gabriel Batista Cousso - 11/03/2025 11:27:08 | BO16: Não | BP16: Sim | BQ16: 45727.45 | BR16: Sim | BS16: 45727.477 | BT16: Sim | BU16: 45727.477 | BV16: Comissionamento Estático | BW16: Conforme | BX16: Gabriel Batista Cousso - 11/03/2025 12:56:21 | BY16: Conforme | BZ16: Gabriel Batista Cousso - 11/03/2025 12:56:21 | CA16: Conforme | CB16: Gabriel Batista Cousso - 11/03/2025 12:56:21 | DA16: Não | DB16: Não Aplica | DD16: Sim | DE16: 45727.539 | DF16: Sim | DG16: 45727.539 | DH16: Dinâmico Frio | DI16: Conforme | DJ16: Gabriel Batista Cousso - 12/03/2025 14:27:11 | DK16: Conforme | DL16: Gabriel Batista Cousso - 12/03/2025 14:27:12 | EC16: Não | ED16: Sim | EE16: 45728.602 | EF16: Dinâmico Quente | EG16: Conforme | EH16: Rafael Schafaschek - 15/03/2025 13:00:06 | EI16: Conforme | EJ16: Rafael Schafaschek - 15/03/2025 13:00:06 | FC16: Não | FD16: Sim | FE16: 45731.542 | FH16: Não | FI16: Feito | FJ16: 45731.542 | FK16: Rafael Schafaschek - 15/03/2025 13:00:06 | FP16: =FL16
A17: 10&20 - R.P.E | B17: Picador 2 | C17: Indicador | D17: SENSOR_VIBRA_REDUT_PIC_2_LNA | E17: VIBRAÇÃO REDUTOR M A L N A PICADOR 2 | F17: Pré-Comissionamento | G17: Conforme | H17: Gabriel Batista Cousso - 11/03/2025 11:27:12 | I17: Conforme | J17: Gabriel Batista Cousso - 11/03/2025 11:27:13 | K17: Conforme | L17: Gabriel Batista Cousso - 11/03/2025 11:27:13 | M17: Conforme | N17: Gabriel Batista Cousso - 11/03/2025 11:27:14 | BO17: Não | BP17: Sim | BQ17: 45727.477 | BR17: Sim | BS17: 45727.477 | BT17: Sim | BU17: 45727.477 | BV17: Comissionamento Estático | BW17: Conforme | BX17: Gabriel Batista Cousso - 11/03/2025 12:56:26 | BY17: Conforme | BZ17: Gabriel Batista Cousso - 11/03/2025 12:56:26 | CA17: Conforme | CB17: Gabriel Batista Cousso - 11/03/2025 12:56:26 | DA17: Não | DB17: Não Aplica | DD17: Sim | DE17: 45727.539 | DF17: Sim | DG17: 45727.539 | DH17: Dinâmico Frio | DI17: Conforme | DJ17: Gabriel Batista Cousso - 12/03/2025 14:29:32 | DK17: Conforme | DL17: Gabriel Batista Cousso - 12/03/2025 14:29:32 | EC17: Não | ED17: Sim | EE17: 45728.604 | EF17: Dinâmico Quente | EG17: Conforme | EH17: Rafael Schafaschek - 15/03/2025 13:00:09 | EI17: Conforme | EJ17: Rafael Schafaschek - 15/03/2025 13:00:09 | FC17: Não | FD17: Sim | FE17: 45731.542 | FH17: Não | FI17: Feito | FJ17: 45731.542 | FK17: Rafael Schafaschek - 15/03/2025 13:00:09 | FP17: =FL17
A18: 10&20 - R.P.E | B18: Picador 2 | C18: Indicador | D18: SENSOR_VIBRA_REDUT_PIC_2_LA | E18: VIBRAÇÃO REDUTOR M A L A PICADOR 2 | F18: Pré-Comissionamento | G18: Conforme | H18: Gabriel Batista Cousso - 11/03/2025 11:27:18 | I18: Conforme | J18: Gabriel Batista Cousso - 11/03/2025 11:27:19 | K18: Conforme | L18: Gabriel Batista Cousso - 11/03/2025 11:27:19 | M18: Conforme | N18: Gabriel Batista Cousso - 11/03/2025 11:27:20 | BO18: Não | BP18: Sim | BQ18: 45727.477 | BR18: Sim | BS18: 45727.477 | BT18: Sim | BU18: 45727.477 | BV18: Comissionamento Estático | BW18: Conforme | BX18: Gabriel Batista Cousso - 11/03/2025 12:56:31 | BY18: Conforme | BZ18: Gabriel Batista Cousso - 11/03/2025 12:56:31 | CA18: Conforme | CB18: Gabriel Batista Cousso - 11/03/2025 12:56:31 | DA18: Não | DB18: Não Aplica | DD18: Sim | DE18: 45727.539 | DF18: Sim | DG18: 45727.539 | DH18: Dinâmico Frio | DI18: Conforme | DJ18: Gabriel Batista Cousso - 12/03/2025 14:29:38 | DK18: Conforme | DL18: Gabriel Batista Cousso - 12/03/2025 14:29:38 | EC18: Não | ED18: Sim | EE18: 45728.604 | EF18: Dinâmico Quente | EG18: Conforme | EH18: Rafael Schafaschek - 15/03/2025 13:00:13 | EI18: Conforme | EJ18: Rafael Schafaschek - 15/03/2025 13:00:13 | FC18: Não | FD18: Sim | FE18: 45731.542 | FH18: Não | FI18: Feito | FJ18: 45731.542 | FK18: Rafael Schafaschek - 15/03/2025 13:00:13 | FP18: =FL18
A19: 10&20 - R.P.E | B19: Turbina Picador 2 | C19: Transmissor | D19: STE-081-01 | E19: TEMPERATURA MANCAL AXIAL EXTERNO TURBINA DO PICADOR 2 | F19: Pré-Comissionamento | G19: Conforme | H19: Gabriel Batista Cousso - 11/03/2025 11:14:59 | I19: Conforme | J19: Gabriel Batista Cousso - 11/03/2025 11:14:59 | K19: Conforme | L19: Gabriel Batista Cousso - 11/03/2025 11:15:00 | M19: Conforme | N19: Gabriel Batista Cousso - 11/03/2025 11:15:01 | BO19: Não | BP19: Sim | BQ19: 45727.469 | BR19: Sim | BS19: 45727.469 | BT19: Sim | BU19: 45727.469 | BV19: Comissionamento Estático | BW19: Conforme | BX19: Gabriel Batista Cousso - 11/03/2025 11:56:10 | BY19: Conforme | BZ19: Gabriel Batista Cousso - 11/03/2025 11:56:10 | CA19: Conforme | CB19: Gabriel Batista Cousso - 11/03/2025 11:56:11 | DA19: Não | DB19: Não Aplica | DD19: Sim | DE19: 45727.497 | DF19: Sim | DG19: 45727.497 | DH19: Dinâmico Frio | DI19: Conforme | DJ19: Gabriel Batista Cousso - 12/03/2025 10:28:28 | DK19: Conforme | DL19: Gabriel Batista Cousso - 12/03/2025 10:28:28 | EC19: Não | ED19: Sim | EE19: 45728.436 | EF19: Dinâmico Quente | EG19: Conforme | EH19: Rafael Schafaschek - 15/03/2025 13:01:00 | EI19: Conforme | EJ19: Rafael Schafaschek - 15/03/2025 13:01:00 | FC19: Não | FD19: Sim | FE19: 45731.542 | FH19: Não | FI19: Feito | FJ19: 45731.542 | FK19: Rafael Schafaschek - 15/03/2025 13:01:00 | FP19: =FL19
A20: 10&20 - R.P.E | B20: Turbina Picador 2 | C20: Transmissor | D20: STE-082-01 | E20: TEMPERATURA MANCAL AXIAL INTERNO TURBINA DO PICADOR 2 | F20: Pré-Comissionamento | G20: Conforme | H20: Gabriel Batista Cousso - 11/03/2025 11:15:05 | I20: Conforme | J20: Gabriel Batista Cousso - 11/03/2025 11:15:05 | K20: Conforme | L20: Gabriel Batista Cousso - 11/03/2025 11:15:06 | M20: Conforme | N20: Gabriel Batista Cousso - 11/03/2025 11:15:07 | BO20: Não | BP20: Sim | BQ20: 45727.469 | BR20: Sim | BS20: 45727.469 | BT20: Sim | BU20: 45727.469 | BV20: Comissionamento Estático | BW20: Conforme | BX20: Gabriel Batista Cousso - 11/03/2025 11:56:15 | BY20: Conforme | BZ20: Gabriel Batista Cousso - 11/03/2025 11:56:16 | CA20: Conforme | CB20: Gabriel Batista Cousso - 11/03/2025 11:56:16 | DA20: Não | DB20: Não Aplica | DD20: Sim | DE20: 45727.497 | DF20: Sim | DG20: 45727.497 | DH20: Dinâmico Frio | DI20: Conforme | DJ20: Gabriel Batista Cousso - 12/03/2025 10:28:33 | DK20: Conforme | DL20: Gabriel Batista Cousso - 12/03/2025 10:28:34 | EC20: Não | ED20: Sim | EE20: 45728.437 | EF20: Dinâmico Quente | EG20: Conforme | EH20: Rafael Schafaschek - 15/03/2025 13:01:04 | EI20: Conforme | EJ20: Rafael Schafaschek - 15/03/2025 13:01:04 | FC20: Não | FD20: Sim | FE20: 45731.542 | FH20: Não | FI20: Feito | FJ20: 45731.542 | FK20: Rafael Schafaschek - 15/03/2025 13:01:04 | FP20: =FL20
A21: 10&20 - R.P.E | B21: Turbina Picador 2 | C21: Transmissor | D21: STE-083-01 | E21: TEMPERATURA MANCAL RADIAL ANTERIOR TURBINA DO PICADOR 2 | F21: Pré-Comissionamento | G21: Conforme | H21: Gabriel Batista Cousso - 11/03/2025 11:15:12 | I21: Conforme | J21: Gabriel Batista Cousso - 11/03/2025 11:15:12 | K21: Conforme | L21: Gabriel Batista Cousso - 11/03/2025 11:15:13 | M21: Conforme | N21: Gabriel Batista Cousso - 11/03/2025 11:15:14 | BO21: Não | BP21: Sim | BQ21: 45727.469 | BR21: Sim | BS21: 45727.469 | BT21: Sim | BU21: 45727.469 | BV21: Comissionamento Estático | BW21: Conforme | BX21: Gabriel Batista Cousso - 11/03/2025 11:56:20 | BY21: Conforme | BZ21: Gabriel Batista Cousso - 11/03/2025 11:56:21 | CA21: Conforme | CB21: Gabriel Batista Cousso - 11/03/2025 11:56:21 | DA21: Não | DB21: Não Aplica | DD21: Sim | DE21: 45727.497 | DF21: Sim | DG21: 45727.497 | DH21: Dinâmico Frio | DI21: Conforme | DJ21: Gabriel Batista Cousso - 12/03/2025 10:28:40 | DK21: Conforme | DL21: Gabriel Batista Cousso - 12/03/2025 10:28:41 | EC21: Não | ED21: Sim | EE21: 45728.437 | EF21: Dinâmico Quente | EG21: Conforme | EH21: Rafael Schafaschek - 15/03/2025 13:01:07 | EI21: Conforme | EJ21: Rafael Schafaschek - 15/03/2025 13:01:07 | FC21: Não | FD21: Sim | FE21: 45731.542 | FH21: Não | FI21: Feito | FJ21: 45731.542 | FK21: Rafael Schafaschek - 15/03/2025 13:01:07 | FP21: =FL21
A22: 10&20 - R.P.E | B22: Turbina Picador 2 | C22: Transmissor | D22: STE-084-01 | E22: TEMPERATURA MANCAL RADIAL POSTERIOR TURBINA DO PICADOR 2 | F22: Pré-Comissionamento | G22: Conforme | H22: Gabriel Batista Cousso - 11/03/2025 11:15:18 | I22: Conforme | J22: Gabriel Batista Cousso - 11/03/2025 11:15:19 | K22: Conforme | L22: Gabriel Batista Cousso - 11/03/2025 11:15:19 | M22: Conforme | N22: Gabriel Batista Cousso - 11/03/2025 11:15:20 | BO22: Não | BP22: Sim | BQ22: 45727.469 | BR22: Sim | BS22: 45727.469 | BT22: Sim | BU22: 45727.469 | BV22: Comissionamento Estático | BW22: Conforme | BX22: Rafael Schafaschek - 15/03/2025 13:01:27 | BY22: Conforme | BZ22: Gabriel Batista Cousso - 11/03/2025 11:56:33 | CA22: Conforme | CB22: Gabriel Batista Cousso - 11/03/2025 11:56:33 | DA22: Não | DB22: Não Aplica | DD22: Sim | DE22: 45731.543 | DF22: Sim | DG22: 45731.543 | DH22: Dinâmico Frio | DI22: Conforme | DJ22: Gabriel Batista Cousso - 12/03/2025 10:28:46 | DK22: Conforme | DL22: Gabriel Batista Cousso - 12/03/2025 10:28:46 | EC22: Não | ED22: Sim | EE22: 45728.437 | EF22: Dinâmico Quente | EG22: Conforme | EH22: Rafael Schafaschek - 15/03/2025 13:01:31 | EI22: Conforme | EJ22: Rafael Schafaschek - 15/03/2025 13:01:31 | FC22: Não | FD22: Sim | FE22: 45731.543 | FH22: Não | FI22: Feito | FJ22: 45731.543 | FK22: Rafael Schafaschek - 15/03/2025 13:01:31 | FP22: =FL22
A23: 10&20 - R.P.E | B23: Turbina Picador 2 | C23: Transmissor | D23: STE-085-01 | E23: TEMPERATURA ÓLEO DE LUBRIFICAÇÃO DA TURBINA DO PICADOR 2 | F23: Pré-Comissionamento | G23: Conforme | H23: Gabriel Batista Cousso - 11/03/2025 11:15:24 | I23: Conforme | J23: Gabriel Batista Cousso - 11/03/2025 11:15:24 | K23: Conforme | L23: Gabriel Batista Cousso - 11/03/2025 11:15:26 | M23: Conforme | N23: Gabriel Batista Cousso - 11/03/2025 11:15:26 | BO23: Não | BP23: Sim | BQ23: 45727.469 | BR23: Sim | BS23: 45727.469 | BT23: Sim | BU23: 45727.469 | BV23: Comissionamento Estático | BW23: Conforme | BX23: Gabriel Batista Cousso - 11/03/2025 11:57:35 | BY23: Conforme | BZ23: Gabriel Batista Cousso - 11/03/2025 11:57:35 | CA23: Conforme | CB23: Gabriel Batista Cousso - 11/03/2025 11:57:36 | DA23: Não | DB23: Não Aplica | DD23: Sim | DE23: 45727.498 | DF23: Sim | DG23: 45727.498 | DH23: Dinâmico Frio | DI23: Conforme | DJ23: Gabriel Batista Cousso - 12/03/2025 10:28:51 | DK23: Conforme | DL23: Gabriel Batista Cousso - 12/03/2025 10:28:52 | EC23: Não | ED23: Sim | EE23: 45728.437 | EF23: Dinâmico Quente | EG23: Conforme | EH23: Rafael Schafaschek - 15/03/2025 13:01:36 | EI23: Conforme | EJ23: Rafael Schafaschek - 15/03/2025 13:01:35 | FC23: Não | FD23: Sim | FE23: 45731.543 | FH23: Não | FI23: Feito | FJ23: 45731.543 | FK23: Rafael Schafaschek - 15/03/2025 13:01:36 | FP23: =FL23
A24: 10&20 - R.P.E | B24: Turbina Picador 2 | C24: Transmissor | D24: STE-086-01 | E24: TEMPERATURA VAPOR DE ADMISSÃO DA TURBINA DO PICADOR 2 | F24: Pré-Comissionamento | G24: Conforme | H24: Gabriel Batista Cousso - 11/03/2025 11:15:30 | I24: Conforme | J24: Gabriel Batista Cousso - 11/03/2025 11:15:31 | K24: Conforme | L24: Gabriel Batista Cousso - 11/03/2025 11:15:31 | M24: Conforme | N24: Gabriel Batista Cousso - 11/03/2025 11:15:32 | BO24: Não | BP24: Sim | BQ24: 45727.469 | BR24: Sim | BS24: 45727.469 | BT24: Sim | BU24: 45727.469 | BV24: Comissionamento Estático | BW24: Conforme | BX24: Gabriel Batista Cousso - 11/03/2025 11:57:41 | BY24: Conforme | BZ24: Gabriel Batista Cousso - 11/03/2025 11:57:42 | CA24: Conforme | CB24: Gabriel Batista Cousso - 11/03/2025 11:57:42 | DA24: Não | DB24: Não Aplica | DD24: Sim | DE24: 45727.498 | DF24: Sim | DG24: 45727.498 | DH24: Dinâmico Frio | DI24: Conforme | DJ24: Gabriel Batista Cousso - 12/03/2025 10:28:56 | DK24: Conforme | DL24: Gabriel Batista Cousso - 12/03/2025 10:28:57 | EC24: Não | ED24: Sim | EE24: 45728.437 | EF24: Dinâmico Quente | EG24: Conforme | EH24: Rafael Schafaschek - 15/03/2025 13:01:40 | EI24: Conforme | EJ24: Rafael Schafaschek - 15/03/2025 13:01:39 | FC24: Não | FD24: Sim | FE24: 45731.543 | FH24: Não | FI24: Feito | FJ24: 45731.543 | FK24: Rafael Schafaschek - 15/03/2025 13:01:40 | FP24: =FL24
A25: 10&20 - R.P.E | B25: Turbina Picador 2 | C25: Transmissor | D25: STE-087-01 | E25: TEMPERATURA VAPOR DE ESCAPE DA TURBINA DO PICADOR 2 | F25: Pré-Comissionamento | G25: Conforme | H25: Gabriel Batista Cousso - 11/03/2025 11:15:37 | I25: Conforme | J25: Gabriel Batista Cousso - 11/03/2025 11:15:37 | K25: Conforme | L25: Gabriel Batista Cousso - 11/03/2025 11:15:38 | M25: Conforme | N25: Gabriel Batista Cousso - 11/03/2025 11:15:39 | BO25: Não | BP25: Sim | BQ25: 45727.469 | BR25: Sim | BS25: 45727.469 | BT25: Sim | BU25: 45727.469 | BV25: Comissionamento Estático | BW25: Conforme | BX25: Gabriel Batista Cousso - 11/03/2025 11:57:47 | BY25: Conforme | BZ25: Gabriel Batista Cousso - 11/03/2025 11:57:48 | CA25: Conforme | CB25: Gabriel Batista Cousso - 11/03/2025 11:57:48 | DA25: Não | DB25: Não Aplica | DD25: Sim | DE25: 45727.498 | DF25: Sim | DG25: 45727.498 | DH25: Dinâmico Frio | DI25: Conforme | DJ25: Gabriel Batista Cousso - 12/03/2025 10:29:01 | DK25: Conforme | DL25: Gabriel Batista Cousso - 12/03/2025 10:29:02 | EC25: Não | ED25: Sim | EE25: 45728.437 | EF25: Dinâmico Quente | EG25: Conforme | EH25: Rafael Schafaschek - 15/03/2025 13:01:44 | EI25: Conforme | EJ25: Rafael Schafaschek - 15/03/2025 13:01:43 | FC25: Não | FD25: Sim | FE25: 45731.543 | FH25: Não | FI25: Feito | FJ25: 45731.543 | FK25: Rafael Schafaschek - 15/03/2025 13:01:44 | FP25: =FL25
A26: 10&20 - R.P.E | B26: Turbina Picador 2 | C26: Transmissor | D26: STE-104-01 | E26: TEMPERATURA ÓLEO DO MANCAL L.A. DA TURBINA DO PICADOR 2 | F26: Pré-Comissionamento | G26: Conforme | H26: Gabriel Batista Cousso - 11/03/2025 11:15:43 | I26: Conforme | J26: Gabriel Batista Cousso - 11/03/2025 11:15:43 | K26: Conforme | L26: Gabriel Batista Cousso - 11/03/2025 11:15:44 | M26: Conforme | N26: Gabriel Batista Cousso - 11/03/2025 11:15:45 | BO26: Não | BP26: Sim | BQ26: 45727.469 | BR26: Sim | BS26: 45727.469 | BT26: Sim | BU26: 45727.469 | BV26: Comissionamento Estático | BW26: Conforme | BX26: Gabriel Batista Cousso - 11/03/2025 11:57:53 | BY26: Conforme | BZ26: Gabriel Batista Cousso - 11/03/2025 11:57:53 | CA26: Conforme | CB26: Gabriel Batista Cousso - 11/03/2025 11:57:54 | DA26: Não | DB26: Não Aplica | DD26: Sim | DE26: 45727.499 | DF26: Sim | DG26: 45727.499 | DH26: Dinâmico Frio | DI26: Conforme | DJ26: Gabriel Batista Cousso - 12/03/2025 10:29:06 | DK26: Conforme | DL26: Gabriel Batista Cousso - 12/03/2025 10:29:07 | EC26: Não | ED26: Sim | EE26: 45728.437 | EF26: Dinâmico Quente | EG26: Conforme | EH26: Rafael Schafaschek - 15/03/2025 13:01:47 | EI26: Conforme | EJ26: Rafael Schafaschek - 15/03/2025 13:01:47 | FC26: Não | FD26: Sim | FE26: 45731.543 | FH26: Não | FI26: Feito | FJ26: 45731.543 | FK26: Rafael Schafaschek - 15/03/2025 13:01:47 | FP26: =FL26
... A38: 10&20 - R.P.E | B38: Desfibrador | C38: Transmissor | D38: TRM-128-01 | E38: PRESSÃOVAPOR DE ESCAPE DO DESFIBRADOR | F38: Pré-Comissionamento | G38: Conforme | H38: Gabriel Batista Cousso - 11/03/2025 11:26:23 | I38: Conforme | J38: Gabriel Batista Cousso - 11/03/2025 11:26:23 | K38: Conforme | L38: Gabriel Batista Cousso - 11/03/2025 11:26:23 | M38: Conforme | N38: Gabriel Batista Cousso - 11/03/2025 11:26:24 | BO38: Não | BP38: Sim | BQ38: 45727.477 | BR38: Sim | BS38: 45727.477 | BT38: Sim | BU38: 45727.477 | BV38: Comissionamento Estático | BW38: Conforme | BX38: Gabriel Batista Cousso - 11/03/2025 12:07:30 | BY38: Conforme | BZ38: Gabriel Batista Cousso - 11/03/2025 12:07:31 | CA38: Conforme | CB38: Gabriel Batista Cousso - 11/03/2025 12:07:31 | DA38: Não | DB38: Não Aplica | DD38: Sim | DE38: 45727.505 | DF38: Sim | DG38: 45727.505 | DH38: Dinâmico Frio | DI38: Conforme | DJ38: Gabriel Batista Cousso - 12/03/2025 14:31:31 | DK38: Conforme | DL38: Gabriel Batista Cousso - 12/03/2025 14:31:32 | EC38: Não | ED38: Sim | EE38: 45728.605 | EF38: Dinâmico Quente | EG38: Conforme | EH38: Rafael Schafaschek - 15/03/2025 13:02:35 | EI38: Conforme | EJ38: Rafael Schafaschek - 15/03/2025 13:02:35 | FC38: Não | FD38: Sim | FE38: 45731.543 | FH38: Não | FI38: Feito | FJ38: 45731.543 | FK38: Rafael Schafaschek - 15/03/2025 13:02:35 | FP38: =FL38
A39: 10&20 - R.P.E | B39: Desfibrador | C39: Desfibrador/Picador | D39: DE-2001 | E39: DESFIBRADOR DE CANA | F39: Pré-Comissionamento | G39: Não Aplicável | H39: Denis Ueslei Lopes Romero - 12/03/2025 08:08:08 | I39: Conforme | J39: Denis Ueslei Lopes Romero - 12/03/2025 08:08:10 | K39: Conforme | L39: Denis Ueslei Lopes Romero - 12/03/2025 08:08:11 | M39: Conforme | N39: Denis Ueslei Lopes Romero - 12/03/2025 08:08:14 | O39: Conforme | P39: Denis Ueslei Lopes Romero - 12/03/2025 08:08:51 | Q39: Conforme | R39: Denis Ueslei Lopes Romero - 12/03/2025 08:08:21 | S39: Conforme | T39: Denis Ueslei Lopes Romero - 12/03/2025 08:08:22 | U39: Conforme | V39: Denis Ueslei Lopes Romero - 12/03/2025 08:08:24 | W39: Conforme | X39: Denis Ueslei Lopes Romero - 12/03/2025 08:08:26 | Y39: Não Aplicável | Z39: Denis Ueslei Lopes Romero - 12/03/2025 08:08:31 | AA39: Conforme | AB39: Denis Ueslei Lopes Romero - 12/03/2025 08:08:33 | AC39: Conforme | AD39: Denis Ueslei Lopes Romero - 12/03/2025 08:08:34 | AE39: Conforme | AF39: Denis Ueslei Lopes Romero - 12/03/2025 08:08:36 | AG39: Conforme | AH39: Denis Ueslei Lopes Romero - 12/03/2025 08:08:37 | AI39: Conforme | AJ39: Denis Ueslei Lopes Romero - 12/03/2025 08:08:39 | BO39: Não | BP39: Sim | BQ39: 45728.339 | BR39: Sim | BS39: 45728.339 | BT39: Sim | BU39: 45728.339 | BV39: Comissionamento Estático | BW39: Conforme | BX39: Denis Ueslei Lopes Romero - 12/03/2025 08:09:12 | BY39: Conforme | BZ39: Denis Ueslei Lopes Romero - 12/03/2025 08:09:19 | CA39: Conforme | CB39: Denis Ueslei Lopes Romero - 12/03/2025 08:09:22 | CC39: Conforme | CD39: Denis Ueslei Lopes Romero - 12/03/2025 08:09:24 | CE39: Conforme | CF39: Denis Ueslei Lopes Romero - 12/03/2025 08:09:43 | CG39: Conforme | CH39: Denis Ueslei Lopes Romero - 12/03/2025 08:10:07 | CI39: Conforme | CJ39: Denis Ueslei Lopes Romero - 12/03/2025 08:10:08 | CK39: Conforme | CL39: Denis Ueslei Lopes Romero - 12/03/2025 08:10:09 | DA39: Não | DB39: Sim | DC39: 45728.34 | DD39: Sim | DE39: 45728.34 | DF39: Sim | DG39: 45728.34 | DH39: Dinâmico Frio | DK39: Conforme | DL39: Rafael Schafaschek - 15/03/2025 10:33:48 | DM39: Conforme | DN39: Rafael Schafaschek - 15/03/2025 10:33:49 | DO39: Conforme | DP39: Rafael Schafaschek - 15/03/2025 10:33:50 | DQ39: Conforme | DR39: Rafael Schafaschek - 15/03/2025 10:33:50 | DS39: Conforme | DT39: Rafael Schafaschek - 15/03/2025 10:33:51 | DU39: Conforme | DV39: Rafael Schafaschek - 15/03/2025 10:33:52 | EC39: Não | ED39: Não | EF39: Dinâmico Quente | FC39: Não | FD39: Não Aplica | FH39: Não | FI39: Pendente | FK39: Rafael Schafaschek - 15/03/2025 10:33:52 | FP39: =FL39
A40: 10&20 - R.P.E | B40: Desfibrador | C40: Indicador | D40: SENSOR_VIBRACAO_L_N_A_DESFIBRADOR | E40: VIBRAÇÃO M L A DESFIBRADOR | F40: Pré-Comissionamento | G40: Conforme | H40: Gabriel Batista Cousso - 11/03/2025 11:26:30 | I40: Conforme | J40: Gabriel Batista Cousso - 11/03/2025 11:26:30 | K40: Conforme | L40: Gabriel Batista Cousso - 11/03/2025 11:26:31 | M40: Conforme | N40: Gabriel Batista Cousso - 11/03/2025 11:26:32 | BO40: Não | BP40: Sim | BQ40: 45727.477 | BR40: Sim | BS40: 45727.477 | BT40: Sim | BU40: 45727.477 | BV40: Comissionamento Estático | BW40: Conforme | BX40: Gabriel Batista Cousso - 11/03/2025 12:06:45 | BY40: Conforme | BZ40: Gabriel Batista Cousso - 11/03/2025 12:06:46 | CA40: Conforme | CB40: Gabriel Batista Cousso - 11/03/2025 12:06:46 | DA40: Não | DB40: Não Aplica | DD40: Sim | DE40: 45727.505 | DF40: Sim | DG40: 45727.505 | DH40: Dinâmico Frio | DI40: Conforme | DJ40: Gabriel Batista Cousso - 12/03/2025 14:30:55 | DK40: Conforme | DL40: Gabriel Batista Cousso - 12/03/2025 14:30:55 | EC40: Não | ED40: Sim | EE40: 45728.605 | EF40: Dinâmico Quente | EG40: Conforme | EH40: Rafael Schafaschek - 15/03/2025 13:02:01 | EI40: Conforme | EJ40: Rafael Schafaschek - 15/03/2025 13:02:00 | FC40: Não | FD40: Sim | FE40: 45731.543 | FH40: Não | FI40: Feito | FJ40: 45731.543 | FK40: Rafael Schafaschek - 15/03/2025 13:02:01 | FP40: =FL40
A41: 10&20 - R.P.E | B41: Desfibrador | C41: Indicador | D41: SENSOR_VIBRACAO_L_A_DESFIBRADOR | E41: VIBRAÇÃO M L N A DESFIBRADOR | F41: Pré-Comissionamento | G41: Conforme | H41: Gabriel Batista Cousso - 11/03/2025 11:26:35 | I41: Conforme | J41: Gabriel Batista Cousso - 11/03/2025 11:26:36 | K41: Conforme | L41: Gabriel Batista Cousso - 11/03/2025 11:26:36 | M41: Conforme | N41: Gabriel Batista Cousso - 11/03/2025 11:26:37 | BO41: Não | BP41: Sim | BQ41: 45727.477 | BR41: Sim | BS41: 45727.477 | BT41: Sim | BU41: 45727.477 | BV41: Comissionamento Estático | BW41: Conforme | BX41: Gabriel Batista Cousso - 11/03/2025 12:06:51 | BY41: Conforme | BZ41: Gabriel Batista Cousso - 11/03/2025 12:06:51 | CA41: Conforme | CB41: Gabriel Batista Cousso - 11/03/2025 12:06:52 | DA41: Não | DB41: Não Aplica | DD41: Sim | DE41: 45727.505 | DF41: Sim | DG41: 45727.505 | DH41: Dinâmico Frio | DI41: Conforme | DJ41: Gabriel Batista Cousso - 12/03/2025 14:30:59 | DK41: Conforme | DL41: Gabriel Batista Cousso - 12/03/2025 14:30:59 | EC41: Não | ED41: Sim | EE41: 45728.605 | EF41: Dinâmico Quente | EG41: Conforme | EH41: Rafael Schafaschek - 15/03/2025 13:02:04 | EI41: Conforme | EJ41: Rafael Schafaschek - 15/03/2025 13:02:04 | FC41: Não | FD41: Sim | FE41: 45731.543 | FH41: Não | FI41: Feito | FJ41: 45731.543 | FK41: Rafael Schafaschek - 15/03/2025 13:02:04 | FP41: =FL41
A42: 10&20 - R.P.E | B42: Desfibrador | C42: Indicador | D42: SENSOR_VIBRA_REDUT_DESF_LNA | E42: VIBRAÇÃO REDUTOR M A L N A DESFIBRADOR | F42: Pré-Comissionamento | G42: Conforme | H42: Gabriel Batista Cousso - 11/03/2025 11:26:41 | I42: Conforme | J42: Gabriel Batista Cousso - 11/03/2025 11:26:42 | K42: Conforme | L42: Gabriel Batista Cousso - 11/03/2025 11:26:42 | M42: Conforme | N42: Gabriel Batista Cousso - 11/03/2025 11:26:43 | BO42: Não | BP42: Sim | BQ42: 45727.477 | BR42: Sim | BS42: 45727.477 | BT42: Sim | BU42: 45727.477 | BV42: Comissionamento Estático | BW42: Conforme | BX42: Gabriel Batista Cousso - 11/03/2025 12:06:56 | BY42: Conforme | BZ42: Gabriel Batista Cousso - 11/03/2025 12:06:57 | CA42: Conforme | CB42: Gabriel Batista Cousso - 11/03/2025 12:06:57 | DA42: Não | DB42: Não Aplica | DD42: Sim | DE42: 45727.505 | DF42: Sim | DG42: 45727.505 | DH42: Dinâmico Frio | DI42: Conforme | DJ42: Gabriel Batista Cousso - 12/03/2025 14:31:03 | DK42: Conforme | DL42: Gabriel Batista Cousso - 12/03/2025 14:31:03 | EC42: Não | ED42: Sim | EE42: 45728.605 | EF42: Dinâmico Quente | EG42: Conforme | EH42: Rafael Schafaschek - 15/03/2025 13:02:08 | EI42: Conforme | EJ42: Rafael Schafaschek - 15/03/2025 13:02:08 | FC42: Não | FD42: Sim | FE42: 45731.543 | FH42: Não | FI42: Feito | FJ42: 45731.543 | FK42: Rafael Schafaschek - 15/03/2025 13:02:08 | FP42: =FL42
