Workbook

Sheet Base de Dados
A1: Área | B1: Sistema | C1: Tipo | D1: TAG | E1: Descrição | F1: (PC) Etapa | G1: (PC) Pergunta 01 | H1: (PC) Pergunta 01 [Monitoramento] | I1: (PC) Pergunta 02 | J1: (PC) Pergunta 02 [Monitoramento] | K1: (PC) Pergunta 03 | L1: (PC) Pergunta 03 [Monitoramento] | M1: (PC) Pergunta 04 | N1: (PC) Pergunta 04 [Monitoramento] | O1: (PC) Pergunta 05 | P1: (PC) Pergunta 05 [Monitoramento] | Q1: (PC) Pergunta 06 | R1: (PC) Pergunta 06 [Monitoramento] | S1: (PC) Pergunta 07 | T1: (PC) Pergunta 07 [Monitoramento] | U1: (PC) Pergunta 08 | V1: (PC) Pergunta 08 [Monitoramento] | W1: (PC) Pergunta 09 | X1: (PC) Pergunta 09 [Monitoramento] | Y1: (PC) Pergunta 10 | Z1: (PC) Pergunta 10 [Monitoramento] | AA1: (PC) Pergunta 11 | AB1: (PC) Pergunta 11 [Monitoramento] | AC1: (PC) Pergunta 12 | AD1: (PC) Pergunta 12 [Monitoramento] | AE1: (PC) Pergunta 13 | AF1: (PC) Pergunta 13 [Monitoramento] | AG1: (PC) Pergunta 14 | AH1: (PC) Pergunta 14 [Monitoramento] | AI1: (PC) Pergunta 15 | AJ1: (PC) Pergunta 15 [Monitoramento] | AK1: (PC) Pergunta 16 | AL1: (PC) Pergunta 16 [Monitoramento] | AM1: (PC) Pergunta 17 | AN1: (PC) Pergunta 17 [Monitoramento] | AO1: (PC) Pergunta 18 | AP1: (PC) Pergunta 18 [Monitoramento] | AQ1: (PC) Pergunta 19 | AR1: (PC) Pergunta 19 [Monitoramento] | AS1: (PC) Pergunta 20 | AT1: (PC) Pergunta 20 [Monitoramento] | AU1: (PC) Pergunta 21 | AV1: (PC) Pergunta 21 [Monitoramento] | AW1: (PC) Pergunta 22 | AX1: (PC) Pergunta 22 [Monitoramento] | AY1: (PC) Pergunta 23 | AZ1: (PC) Pergunta 23 [Monitoramento] | BA1: (PC) Pergunta 24 | BB1: (PC) Pergunta 24 [Monitoramento] | BC1: (PC) Pergunta 25 | BD1: (PC) Pergunta 25 [Monitoramento] | BE1: (PC) Pergunta 26 | BF1: (PC) Pergunta 26 [Monitoramento] | BG1: (PC) Pergunta 27 | BH1: (PC) Pergunta 27 [Monitoramento] | BI1: (PC) Pergunta 28 | BJ1: (PC) Pergunta 28 [Monitoramento] | BK1: (PC) Pergunta 29 | BL1: (PC) Pergunta 29 [Monitoramento] | BM1: (PC) Pergunta 30 | BN1: (PC) Pergunta 30 [Monitoramento] | BO1: (PC) Pergunta 31 | BP1: (PC) Pergunta 31 [Monitoramento] | BQ1: (PC) Pergunta 32 | BR1: (PC) Pergunta 32 [Monitoramento] | BS1: (PC) Não Conformidade ? (Físico) | BT1: (PC) Status Mecânica (Físico) | BU1: (PC) Mecânica Concluída: | BV1: (PC) Status Elétrica (Físico) | BW1: (PC) Elétrica Concluída: | BX1: (PC) Status Checklist (Físico) | BY1: (PC) Checklist Concluído: | BZ1: (CE) Etapa | CA1: (CE) Pergunta 01 | CB1: (CE) Pergunta 01 [Monitoramento] | CC1: (CE) Pergunta 02 | CD1: (CE) Pergunta 02 [Monitoramento] | CE1: (CE) Pergunta 03 | CF1: (CE) Pergunta 03 [Monitoramento] | CG1: (CE) Pergunta 04 | CH1: (CE) Pergunta 04 [Monitoramento] | CI1: (CE) Pergunta 05 | CJ1: (CE) Pergunta 05 [Monitoramento] | CK1: (CE) Pergunta 06 | CL1: (CE) Pergunta 06 [Monitoramento] | CM1: (CE) Pergunta 07 | CN1: (CE) Pergunta 07 [Monitoramento] | CO1: (CE) Pergunta 08 | CP1: (CE) Pergunta 08 [Monitoramento] | CQ1: (CE) Pergunta 09 | CR1: (CE) Pergunta 09 [Monitoramento] | CS1: (CE) Pergunta 10 | CT1: (CE) Pergunta 10 [Monitoramento] | CU1: (CE) Pergunta 11 | CV1: (CE) Pergunta 11 [Monitoramento] | CW1: (CE) Pergunta 12 | CX1: (CE) Pergunta 12 [Monitoramento] | CY1: (CE) Pergunta 13 | CZ1: (CE) Pergunta 13 [Monitoramento] | DA1: (CE) Pergunta 14 | DB1: (CE) Pergunta 14 [Monitoramento] | DC1: (CE) Pergunta 15 | DD1: (CE) Pergunta 15 [Monitoramento] | DE1: (CE) Não Conformidade ? (Físico) | DF1: (CE) Status Mecânica (Físico) | DG1: (CE) Mecânica Concluída: | DH1: (CE) Status Elétrica (Físico) | DI1: (CE) Elétrica Concluída: | DJ1: (CE) Status Checklist (Físico) | DK1: (CE) Checklist Concluído: | DL1: (DF) Etapa | DM1: (DF) Pergunta 01 | DN1: (DF) Pergunta 01 [Monitoramento] | DO1: (DF) Pergunta 02 | DP1: (DF) Pergunta 02 [Monitoramento] | DQ1: (DF) Pergunta 03 | DR1: (DF) Pergunta 03 [Monitoramento] | DS1: (DF) Pergunta 04 | DT1: (DF) Pergunta 04 [Monitoramento] | DU1: (DF) Pergunta 05 | DV1: (DF) Pergunta 05 [Monitoramento] | DW1: (DF) Pergunta 06 | DX1: (DF) Pergunta 06 [Monitoramento] | DY1: (DF) Pergunta 07 | DZ1: (DF) Pergunta 07 [Monitoramento] | EA1: (DF) Pergunta 08 | EB1: (DF) Pergunta 08 [Monitoramento] | EC1: (DF) Pergunta 09 | ED1: (DF) Pergunta 09 [Monitoramento] | EE1: (DF) Pergunta 10 | EF1: (DF) Pergunta 10 [Monitoramento] | EG1: (DF) Pergunta 11 | EH1: (DF) Pergunta 11 [Monitoramento] | EI1: (DF) Não Conformidade ? (Físico) | EJ1: (DF) Status Checklist (Físico) | EK1: (DF) Checklist Concluído: | EL1: (DQ) Etapa | EM1: (DQ) Pergunta 01 | EN1: (DQ) Pergunta 01 [Monitoramento] | EO1: (DQ) Pergunta 02 | EP1: (DQ) Pergunta 02 [Monitoramento] | EQ1: (DQ) Pergunta 03 | ER1: (DQ) Pergunta 03 [Monitoramento] | ES1: (DQ) Pergunta 04 | ET1: (DQ) Pergunta 04 [Monitoramento] | EU1: (DQ) Pergunta 05 | EV1: (DQ) Pergunta 05 [Monitoramento] | EW1: (DQ) Pergunta 06 | EX1: (DQ) Pergunta 06 [Monitoramento] | EY1: (DQ) Pergunta 07 | EZ1: (DQ) Pergunta 07 [Monitoramento] | FA1: (DQ) Pergunta 08 | FB1: (DQ) Pergunta 08 [Monitoramento] | FC1: (DQ) Pergunta 09 | FD1: (DQ) Pergunta 09 [Monitoramento] | FE1: (DQ) Pergunta 10 | FF1: (DQ) Pergunta 10 [Monitoramento] | FG1: (DQ) Pergunta 11 | FH1: (DQ) Pergunta 11 [Monitoramento] | FI1: (DQ) Não Conformidade ? (Físico) | FJ1: (DQ) Status Checklist (Físico) | FK1: (DQ) Checklist Concluído: | FL1: Observação: | FM1: Observação Registrada em: | FN1: Status do Questionário (Físico) | FO1: Status do Questionário Concluído: | FP1: Última atualização: | FQ1: Imagem do Equipamento: | FR1: Imagem do Equipamento Registrada em: | FS1: Imagem da Plaqueta do Motor: | FT1: Imagem da Plaqueta do Motor Registrada em: | FU1: Imagem (Display) | FV1: Imagem Indisponível | FW1: Imagem Indisponível [Monitoramento]
A2: 10&20 - R.P.E | B2: 03C650 - Esteira de Saída do Difusor | C2: Esteira Metálica | D2: 03C650 | E2: Esteira Transversal Saída Do Difusor (Esteira Metálica) | F2: Pré-Comissionamento | G2: Conforme | H2: Roniel Figueiredo - 14/03/2026 10:10:06 | I2: Conforme | J2: Roniel Figueiredo - 14/03/2026 10:10:10 | K2: Conforme | L2: Roniel Figueiredo - 14/03/2026 10:10:14 | M2: Conforme | N2: Roniel Figueiredo - 14/03/2026 10:10:15 | O2: Conforme | P2: Roniel Figueiredo - 05/03/2026 08:57:12 | Q2: Conforme | R2: Roniel Figueiredo - 14/03/2026 10:10:19 | S2: Conforme | T2: Roniel Figueiredo - 05/03/2026 08:57:18 | U2: Conforme | V2: Roniel Figueiredo - 05/03/2026 08:57:21 | W2: Conforme | X2: Roniel Figueiredo - 05/03/2026 08:57:29 | Y2: Conforme | Z2: Roniel Figueiredo - 05/03/2026 08:57:33 | AA2: Conforme | AB2: Roniel Figueiredo - 05/03/2026 08:57:39 | AC2: Conforme | AD2: Roniel Figueiredo - 05/03/2026 08:57:44 | AE2: Conforme | AF2: Roniel Figueiredo - 05/03/2026 08:57:48 | AG2: Conforme | AH2: Roniel Figueiredo - 05/03/2026 08:57:51 | AI2: Conforme | AJ2: Roniel Figueiredo - 14/03/2026 10:10:26 | AK2: Conforme | AL2: Roniel Figueiredo - 20/03/2026 10:23:50 | AM2: Conforme | AN2: Roniel Figueiredo - 20/03/2026 10:23:51 | AO2: Conforme | AP2: Roniel Figueiredo - 19/03/2026 08:25:00 | AQ2: Conforme | AR2: Roniel Figueiredo - 20/03/2026 10:23:57 | AS2: Conforme | AT2: Roniel Figueiredo - 20/03/2026 10:23:59 | AU2: Conforme | AV2: Roniel Figueiredo - 05/03/2026 08:58:06 | AW2: Conforme | AX2: Roniel Figueiredo - 05/03/2026 08:58:10 | AY2: Conforme | AZ2: Roniel Figueiredo - 05/03/2026 08:58:13 | BA2: Conforme | BB2: Roniel Figueiredo - 05/03/2026 08:58:19 | BC2: Conforme | BD2: Roniel Figueiredo - 05/03/2026 08:58:23 | BE2: Conforme | BF2: Roniel Figueiredo - 05/03/2026 08:58:29 | BG2: Conforme | BH2: Roniel Figueiredo - 05/03/2026 08:58:31 | BI2: Conforme | BJ2: Roniel Figueiredo - 05/03/2026 08:58:34 | BK2: Conforme | BL2: Roniel Figueiredo - 05/03/2026 08:58:40 | BM2: Conforme | BN2: Roniel Figueiredo - 05/03/2026 08:58:43 | BO2: Conforme | BP2: Roniel Figueiredo - 05/03/2026 08:58:47 | BS2: Não | BT2: Sim | BU2: 46095.424 | BV2: Sim | BW2: 46101.433 | BX2: Sim | BY2: 46101.433 | BZ2: Comissionamento Estático | CA2: Conforme | CB2: Roniel Figueiredo - 21/03/2026 11:01:26 | CC2: Conforme | CD2: Roniel Figueiredo - 21/03/2026 11:01:30 | CE2: Conforme | CF2: Roniel Figueiredo - 21/03/2026 11:01:36 | CG2: Conforme | CH2: Roniel Figueiredo - 21/03/2026 11:01:39 | DE2: Não | DF2: Sim | DG2: 46102.459 | DH2: Sim | DI2: 46102.459 | DJ2: Sim | DK2: 46102.459 | DL2: Dinâmico Frio | DM2: Conforme | DN2: Roniel Figueiredo - 02/04/2026 08:53:16 | DO2: Conforme | DP2: Roniel Figueiredo - 02/04/2026 08:53:17 | DQ2: Conforme | DR2: Roniel Figueiredo - 02/04/2026 08:53:18 | DS2: Conforme | DT2: Roniel Figueiredo - 02/04/2026 08:53:19 | DU2: Conforme | DV2: Roniel Figueiredo - 02/04/2026 08:53:26 | DW2: Conforme | DX2: Roniel Figueiredo - 02/04/2026 08:53:25 | DY2: Conforme | DZ2: Roniel Figueiredo - 02/04/2026 08:53:24 | EA2: Conforme | EB2: Roniel Figueiredo - 02/04/2026 08:53:23 | EI2: Não | EJ2: Sim | EK2: 46114.37 | EL2: Dinâmico Quente | FI2: Não | FJ2: Não | FN2: Pendente | FP2: Roniel Figueiredo - 02/04/2026 08:53:26 | FQ2: Base de Dados_Images/03C650.Imagem do Equipamento-.115701.jpg | FR2: Roniel Figueiredo - 05/03/2026 08:58:47 | FU2: =FQ2 -> Base de Dados_Images/03C650.Imagem do Equipamento-.115701.jpg
A3: 10&20 - R.P.E | B3: 03C650 - Esteira de Saída do Difusor | C3: Motoredutor | D3: 03-ES-650-M01 | E3: Acionamento Esteira De Saída Do Difusor | F3: Pré-Comissionamento | G3: Conforme | H3: Roniel Figueiredo - 14/03/2026 10:07:35 | I3: Conforme | J3: Roniel Figueiredo - 14/03/2026 10:07:38 | K3: Conforme | L3: Roniel Figueiredo - 14/03/2026 10:07:42 | M3: Conforme | N3: Roniel Figueiredo - 14/03/2026 10:07:45 | O3: Conforme | P3: Roniel Figueiredo - 14/03/2026 10:07:49 | Q3: Conforme | R3: Roniel Figueiredo - 14/03/2026 10:07:55 | S3: Conforme | T3: Roniel Figueiredo - 14/03/2026 10:07:58 | U3: Conforme | V3: Roniel Figueiredo - 20/03/2026 10:24:17 | W3: Conforme | X3: Roniel Figueiredo - 20/03/2026 10:24:18 | Y3: Conforme | Z3: Roniel Figueiredo - 14/03/2026 10:08:04 | AA3: Conforme | AB3: Roniel Figueiredo - 20/03/2026 10:24:21 | AC3: Conforme | AD3: Roniel Figueiredo - 20/03/2026 10:24:23 | AE3: Conforme | AF3: Roniel Figueiredo - 14/03/2026 10:08:14 | BS3: Não | BT3: Sim | BU3: 46095.422 | BV3: Sim | BW3: 46101.434 | BX3: Sim | BY3: 46101.434 | BZ3: Comissionamento Estático | CA3: Conforme | CB3: Roniel Figueiredo - 21/03/2026 11:01:50 | CC3: Conforme | CD3: Roniel Figueiredo - 21/03/2026 11:01:55 | CE3: Conforme | CF3: Roniel Figueiredo - 21/03/2026 11:01:57 | CG3: Conforme | CH3: Roniel Figueiredo - 21/03/2026 11:02:00 | DE3: Não | DF3: Sim | DG3: 46102.46 | DH3: Sim | DI3: 46102.46 | DJ3: Sim | DK3: 46102.46 | DL3: Dinâmico Frio | DM3: Conforme | DN3: Roniel Figueiredo - 02/04/2026 08:53:37 | DO3: Conforme | DP3: Roniel Figueiredo - 02/04/2026 08:53:38 | DQ3: Conforme | DR3: Roniel Figueiredo - 02/04/2026 08:53:39 | DS3: Conforme | DT3: Roniel Figueiredo - 02/04/2026 08:53:40 | DU3: Conforme | DV3: Roniel Figueiredo - 02/04/2026 08:53:45 | EI3: Não | EJ3: Sim | EK3: 46114.371 | EL3: Dinâmico Quente | FI3: Não | FJ3: Não | FN3: Pendente | FP3: Roniel Figueiredo - 02/04/2026 08:53:45 | FQ3: Base de Dados_Images/03-ES-650-M01.Imagem do Equipamento-.131029.jpg | FR3: Roniel Figueiredo - 14/03/2026 10:09:51 | FS3: Base de Dados_Images/03-ES-650-M01.Imagem da Plaqueta do Motor-.131035.jpg | FT3: Roniel Figueiredo - 14/03/2026 10:09:51 | FU3: =FQ3 -> Base de Dados_Images/03-ES-650-M01.Imagem do Equipamento-.131029.jpg
A4: 10&20 - R.P.E | B4: 03C650 - Esteira de Saída do Difusor | C4: Transmissor | D4: 03-SS-650-B01 | E4: Zero Speed | F4: Pré-Comissionamento | G4: Conforme | H4: Roniel Figueiredo - 05/03/2026 09:19:28 | I4: Conforme | J4: Roniel Figueiredo - 05/03/2026 09:19:29 | K4: Conforme | L4: Roniel Figueiredo - 05/03/2026 09:19:30 | M4: Conforme | N4: Roniel Figueiredo - 05/03/2026 09:19:32 | BS4: Não | BT4: Sim | BU4: 46086.389 | BV4: Sim | BW4: 46086.389 | BX4: Sim | BY4: 46086.389 | BZ4: Comissionamento Estático | CA4: Conforme | CB4: Roniel Figueiredo - 21/03/2026 11:02:11 | CC4: Conforme | CD4: Roniel Figueiredo - 21/03/2026 11:02:15 | CE4: Conforme | CF4: Roniel Figueiredo - 21/03/2026 11:02:13 | DE4: Não | DF4: Não Aplica | DH4: Sim | DI4: 46102.46 | DJ4: Sim | DK4: 46102.46 | DL4: Dinâmico Frio | DM4: Conforme | DN4: Roniel Figueiredo - 02/04/2026 08:53:56 | DO4: Conforme | DP4: Roniel Figueiredo - 02/04/2026 08:54:01 | EI4: Não | EJ4: Sim | EK4: 46114.371 | EL4: Dinâmico Quente | FI4: Não | FJ4: Não | FN4: Pendente | FP4: Roniel Figueiredo - 02/04/2026 08:54:01 | FQ4: Base de Dados_Images/03-SS-650-B01.Imagem do Equipamento-.121925.jpg | FR4: Roniel Figueiredo - 05/03/2026 09:19:32 | FU4: =FQ4 -> Base de Dados_Images/03-SS-650-B01.Imagem do Equipamento-.121925.jpg
A13: 10&20 - R.P.E | B13: 03H070 - Aquecedor 01 | C13: Transmissor | D13: 03-TIT-070-Y01 | E13: Transmissor De Temperatura Do Caldo | F13: Pré-Comissionamento | G13: Conforme | H13: Gilmar de Sousa - 04/02/2026 10:17:51 | I13: Conforme | J13: Gilmar de Sousa - 04/02/2026 10:17:52 | K13: Conforme | L13: Gilmar de Sousa - 04/02/2026 10:17:53 | M13: Conforme | N13: Gilmar de Sousa - 04/02/2026 10:17:54 | BS13: Não | BT13: Sim | BU13: 46057.429 | BV13: Sim | BW13: 46057.429 | BX13: Sim | BY13: 46057.429 | BZ13: Comissionamento Estático | CA13: Conforme | CB13: Roniel Figueiredo - 10/03/2026 16:40:33 | CC13: Conforme | CD13: Roniel Figueiredo - 11/03/2026 09:26:30 | CE13: Conforme | CF13: Roniel Figueiredo - 11/03/2026 09:26:33 | DE13: Não | DF13: Não Aplica | DH13: Sim | DI13: 46092.393 | DJ13: Sim | DK13: 46092.393 | DL13: Dinâmico Frio | EI13: Não | EJ13: Não | EL13: Dinâmico Quente | FI13: Não | FJ13: Não | FN13: Pendente | FP13: Roniel Figueiredo - 11/03/2026 09:26:33 | FQ13: Base de Dados_Images/03-TIT-070-Y01.Imagem do Equipamento-.172823.jpg | FR13: Gilmar de Sousa - 04/02/2026 10:17:54 | FU13: =FQ13 -> Base de Dados_Images/03-TIT-070-Y01.Imagem do Equipamento-.172823.jpg
A14: 10&20 - R.P.E | B14: 03H070 - Aquecedor 01 | C14: Trocador De Calor/Evaporador/Aquecedor | D14: 03H070 | E14: Aquecedor 01 | F14: Pré-Comissionamento | G14: Conforme | H14: Roniel Figueiredo - 20/02/2026 15:33:30 | I14: Conforme | J14: Roniel Figueiredo - 20/02/2026 15:33:34 | K14: Conforme | L14: Roniel Figueiredo - 09/03/2026 16:23:31 | M14: Conforme | N14: Roniel Figueiredo - 09/03/2026 16:23:34 | O14: Conforme | P14: Roniel Figueiredo - 09/03/2026 16:23:37 | Q14: Conforme | R14: Roniel Figueiredo - 20/02/2026 15:33:58 | S14: Conforme | T14: Roniel Figueiredo - 20/02/2026 15:34:14 | U14: Conforme | V14: Roniel Figueiredo - 20/02/2026 15:34:18 | BS14: Não | BT14: Sim | BU14: 46090.683 | BV14: Sim | BW14: 46073.649 | BX14: Sim | BY14: 46090.683 | BZ14: Comissionamento Estático | DE14: Não | DF14: Não Aplica | DH14: Não Aplica | DJ14: Não Aplica | DL14: Dinâmico Frio | EI14: Não | EJ14: Não | EL14: Dinâmico Quente | FI14: Não | FJ14: Não | FN14: Pendente | FP14: Roniel Figueiredo - 09/03/2026 16:23:37 | FQ14: Base de Dados_Images/03H070.Imagem do Equipamento-.192325.jpg | FR14: Roniel Figueiredo - 09/03/2026 16:23:37 | FU14: =FQ14 -> Base de Dados_Images/03H070.Imagem do Equipamento-.192325.jpg
A15: 10&20 - R.P.E | B15: 03H070 - Aquecedor 01 | C15: Válvula Pneumatica | D15: 03-TIT-070-Y01 XV | E15: Válvula De Temperatura Do Caldo | F15: Pré-Comissionamento | G15: Conforme | H15: Gilmar de Sousa - 04/02/2026 10:09:25 | I15: Conforme | J15: Gilmar de Sousa - 04/02/2026 10:09:27 | K15: Conforme | L15: Gilmar de Sousa - 04/02/2026 10:09:30 | M15: Conforme | N15: Gilmar de Sousa - 04/02/2026 10:09:32 | O15: Conforme | P15: Gilmar de Sousa - 04/02/2026 10:09:35 | Q15: Conforme | R15: Gilmar de Sousa - 04/02/2026 10:09:37 | S15: Conforme | T15: Gilmar de Sousa - 04/02/2026 10:09:42 | U15: Conforme | V15: Gilmar de Sousa - 04/02/2026 10:09:40 | BS15: Não | BT15: Não Aplica | BV15: Sim | BW15: 46057.423 | BX15: Sim | BY15: 46057.423 | BZ15: Comissionamento Estático | DE15: Não | DF15: Não Aplica | DH15: Não | DJ15: Não | DL15: Dinâmico Frio | EI15: Não | EJ15: Não | EL15: Dinâmico Quente | FI15: Não | FJ15: Não | FN15: Pendente | FP15: Gilmar de Sousa - 04/02/2026 10:09:42 | FQ15: Base de Dados_Images/03-TIT-070-Y01 XV.Imagem do Equipamento-.111619.jpg | FR15: Gilmar de Sousa - 03/02/2026 10:58:48 | FU15: =FQ15 -> Base de Dados_Images/03-TIT-070-Y01 XV.Imagem do Equipamento-.111619.jpg
A16: 10&20 - R.P.E | B16: 03H080 - Aquecedor 02 | C16: Transmissor | D16: 03-TIT-080-Y01 | E16: Transmissor De Temperatura Do Caldo | F16: Pré-Comissionamento | G16: Conforme | H16: Gilmar de Sousa - 04/02/2026 10:19:56 | I16: Conforme | J16: Gilmar de Sousa - 04/02/2026 10:19:58 | K16: Conforme | L16: Gilmar de Sousa - 04/02/2026 10:19:59 | M16: Conforme | N16: Gilmar de Sousa - 04/02/2026 10:20:00 | BS16: Não | BT16: Sim | BU16: 46057.431 | BV16: Sim | BW16: 46057.431 | BX16: Sim | BY16: 46057.431 | BZ16: Comissionamento Estático | CA16: Conforme | CB16: Roniel Figueiredo - 11/03/2026 09:27:24 | CC16: Conforme | CD16: Roniel Figueiredo - 11/03/2026 09:27:27 | CE16: Conforme | CF16: Roniel Figueiredo - 11/03/2026 09:27:30 | DE16: Não | DF16: Não Aplica | DH16: Sim | DI16: 46092.394 | DJ16: Sim | DK16: 46092.394 | DL16: Dinâmico Frio | EI16: Não | EJ16: Não | EL16: Dinâmico Quente | FI16: Não | FJ16: Não | FN16: Pendente | FP16: Roniel Figueiredo - 11/03/2026 09:27:30 | FQ16: Base de Dados_Images/03-TIT-080-Y01.Imagem do Equipamento-.172935.jpg | FR16: Gilmar de Sousa - 04/02/2026 10:20:00 | FU16: =FQ16 -> Base de Dados_Images/03-TIT-080-Y01.Imagem do Equipamento-.172935.jpg
A17: 10&20 - R.P.E | B17: 03H080 - Aquecedor 02 | C17: Trocador De Calor/Evaporador/Aquecedor | D17: 03H080 | E17: Aquecedor 02 | F17: Pré-Comissionamento | G17: Conforme | H17: Roniel Figueiredo - 09/03/2026 16:24:30 | I17: Conforme | J17: Roniel Figueiredo - 09/03/2026 16:24:31 | K17: Conforme | L17: Roniel Figueiredo - 09/03/2026 16:24:35 | M17: Conforme | N17: Roniel Figueiredo - 09/03/2026 16:24:36 | O17: Conforme | P17: Roniel Figueiredo - 09/03/2026 16:24:40 | Q17: Conforme | R17: Roniel Figueiredo - 09/03/2026 16:24:41 | S17: Conforme | T17: Roniel Figueiredo - 09/03/2026 16:24:42 | U17: Conforme | V17: Roniel Figueiredo - 09/03/2026 16:24:46 | BS17: Não | BT17: Sim | BU17: 46090.684 | BV17: Sim | BW17: 46090.684 | BX17: Sim | BY17: 46090.684 | BZ17: Comissionamento Estático | DE17: Não | DF17: Não Aplica | DH17: Não Aplica | DJ17: Não Aplica | DL17: Dinâmico Frio | EI17: Não | EJ17: Não | EL17: Dinâmico Quente | FI17: Não | FJ17: Não | FN17: Pendente | FP17: Roniel Figueiredo - 09/03/2026 16:24:46 | FQ17: Base de Dados_Images/03H080.Imagem do Equipamento-.192425.jpg | FR17: Roniel Figueiredo - 09/03/2026 16:24:46 | FU17: =FQ17 -> Base de Dados_Images/03H080.Imagem do Equipamento-.192425.jpg
A18: 10&20 - R.P.E | B18: 03H080 - Aquecedor 02 | C18: Válvula Pneumatica | D18: 03-TIT-080-Y01 XV | E18: Válvula De Temperatura Do Caldo | F18: Pré-Comissionamento | G18: Conforme | H18: Gilmar de Sousa - 04/02/2026 10:18:43 | I18: Conforme | J18: Gilmar de Sousa - 04/02/2026 10:18:45 | K18: Conforme | L18: Gilmar de Sousa - 04/02/2026 10:18:46 | M18: Conforme | N18: Gilmar de Sousa - 04/02/2026 10:18:47 | O18: Conforme | P18: Gilmar de Sousa - 04/02/2026 10:18:50 | Q18: Conforme | R18: Gilmar de Sousa - 04/02/2026 10:18:51 | S18: Conforme | T18: Gilmar de Sousa - 04/02/2026 10:18:52 | U18: Conforme | V18: Gilmar de Sousa - 04/02/2026 10:18:53 | BS18: Não | BT18: Não Aplica | BV18: Sim | BW18: 46057.43 | BX18: Sim | BY18: 46057.43 | BZ18: Comissionamento Estático | DE18: Não | DF18: Não Aplica | DH18: Não | DJ18: Não | DL18: Dinâmico Frio | EI18: Não | EJ18: Não | EL18: Dinâmico Quente | FI18: Não | FJ18: Não | FN18: Pendente | FP18: Gilmar de Sousa - 04/02/2026 10:18:53 | FQ18: Base de Dados_Images/03-TIT-080-Y01 XV.Imagem do Equipamento-.172850.jpg | FR18: Gilmar de Sousa - 04/02/2026 10:18:53 | FU18: =FQ18 -> Base de Dados_Images/03-TIT-080-Y01 XV.Imagem do Equipamento-.172850.jpg
A19: 10&20 - R.P.E | B19: 03H090 - Aquecedor 03 | C19: Transmissor | D19: 03-TIT-090-Y01 | E19: Transmissor De Temperatura Do Caldo | F19: Pré-Comissionamento | G19: Conforme | H19: Gilmar de Sousa - 04/02/2026 10:22:14 | I19: Conforme | J19: Gilmar de Sousa - 04/02/2026 10:22:16 | K19: Conforme | L19: Gilmar de Sousa - 04/02/2026 10:22:17 | M19: Conforme | N19: Gilmar de Sousa - 04/02/2026 10:22:20 | BS19: Não | BT19: Sim | BU19: 46057.432 | BV19: Sim | BW19: 46057.432 | BX19: Sim | BY19: 46057.432 | BZ19: Comissionamento Estático | CA19: Conforme | CB19: Roniel Figueiredo - 11/03/2026 09:27:46 | CC19: Conforme | CD19: Roniel Figueiredo - 11/03/2026 09:27:49 | CE19: Conforme | CF19: Roniel Figueiredo - 11/03/2026 09:27:55 | DE19: Não | DF19: Não Aplica | DH19: Sim | DI19: 46092.394 | DJ19: Sim | DK19: 46092.394 | DL19: Dinâmico Frio | DM19: Conforme | DN19: Roniel Figueiredo - 21/03/2026 11:03:39 | DO19: Conforme | DP19: Roniel Figueiredo - 21/03/2026 11:03:42 | EI19: Não | EJ19: Sim | EK19: 46102.461 | EL19: Dinâmico Quente | FI19: Não | FJ19: Não | FN19: Pendente | FP19: Roniel Figueiredo - 21/03/2026 11:03:42 | FQ19: Base de Dados_Images/03-TIT-090-Y01.Imagem do Equipamento-.173101.jpg | FR19: Gilmar de Sousa - 04/02/2026 10:22:20 | FU19: =FQ19 -> Base de Dados_Images/03-TIT-090-Y01.Imagem do Equipamento-.173101.jpg
A20: 10&20 - R.P.E | B20: 03H090 - Aquecedor 03 | C20: Trocador De Calor/Evaporador/Aquecedor | D20: 03H090 | E20: Aquecedor 03 | F20: Pré-Comissionamento | G20: Conforme | H20: Roniel Figueiredo - 09/03/2026 16:26:33 | I20: Conforme | J20: Roniel Figueiredo - 09/03/2026 16:26:35 | K20: Conforme | L20: Roniel Figueiredo - 09/03/2026 16:26:42 | M20: Conforme | N20: Roniel Figueiredo - 09/03/2026 16:26:47 | O20: Conforme | P20: Roniel Figueiredo - 09/03/2026 16:26:51 | Q20: Conforme | R20: Roniel Figueiredo - 09/03/2026 16:26:54 | S20: Conforme | T20: Roniel Figueiredo - 09/03/2026 16:26:58 | U20: Conforme | V20: Roniel Figueiredo - 09/03/2026 16:27:06 | BS20: Não | BT20: Sim | BU20: 46090.685 | BV20: Sim | BW20: 46090.685 | BX20: Sim | BY20: 46090.685 | BZ20: Comissionamento Estático | DE20: Não | DF20: Não Aplica | DH20: Não Aplica | DJ20: Não Aplica | DL20: Dinâmico Frio | DM20: Conforme | DN20: Roniel Figueiredo - 21/03/2026 11:03:54 | DO20: Conforme | DP20: Roniel Figueiredo - 21/03/2026 11:03:56 | DQ20: Conforme | DR20: Roniel Figueiredo - 21/03/2026 11:03:58 | EI20: Não | EJ20: Sim | EK20: 46102.461 | EL20: Dinâmico Quente | FI20: Não | FJ20: Não | FN20: Pendente | FP20: Roniel Figueiredo - 21/03/2026 11:03:58 | FQ20: Base de Dados_Images/03H090.Imagem do Equipamento-.193253.jpg | FR20: Roniel Figueiredo - 10/03/2026 12:00:35 | FU20: =FQ20 -> Base de Dados_Images/03H090.Imagem do Equipamento-.193253.jpg
A21: 10&20 - R.P.E | B21: 03H090 - Aquecedor 03 | C21: Válvula Pneumatica | D21: 03-TIT-090-Y01 XV | E21: Válvula De Temperatura Do Caldo | F21: Pré-Comissionamento | G21: Conforme | H21: Gilmar de Sousa - 04/02/2026 10:21:16 | I21: Conforme | J21: Gilmar de Sousa - 04/02/2026 10:21:18 | K21: Conforme | L21: Gilmar de Sousa - 04/02/2026 10:21:19 | M21: Conforme | N21: Gilmar de Sousa - 04/02/2026 10:21:21 | O21: Conforme | P21: Gilmar de Sousa - 04/02/2026 10:21:22 | Q21: Conforme | R21: Gilmar de Sousa - 04/02/2026 10:21:30 | S21: Conforme | T21: Gilmar de Sousa - 04/02/2026 10:21:25 | U21: Conforme | V21: Gilmar de Sousa - 04/02/2026 10:21:23 | BS21: Não | BT21: Não Aplica | BV21: Sim | BW21: 46057.432 | BX21: Sim | BY21: 46057.432 | BZ21: Comissionamento Estático | CA21: Conforme | CB21: Roniel Figueiredo - 13/03/2026 11:28:46 | CC21: Conforme | CD21: Roniel Figueiredo - 13/03/2026 11:29:22 | DE21: Não | DF21: Não Aplica | DH21: Sim | DI21: 46094.479 | DJ21: Sim | DK21: 46094.479 | DL21: Dinâmico Frio | DM21: Conforme | DN21: Roniel Figueiredo - 21/03/2026 11:03:25 | EI21: Não | EJ21: Sim | EK21: 46102.461 | EL21: Dinâmico Quente | FI21: Não | FJ21: Não | FN21: Pendente | FP21: Roniel Figueiredo - 21/03/2026 11:03:25 | FQ21: Base de Dados_Images/03-TIT-090-Y01 XV.Imagem do Equipamento-.173004.jpg | FR21: Gilmar de Sousa - 04/02/2026 10:21:30 | FU21: =FQ21 -> Base de Dados_Images/03-TIT-090-Y01 XV.Imagem do Equipamento-.173004.jpg
A22: 10&20 - R.P.E | B22: 03H130 - DCH de caldo prensado | C22: Tanque | D22: 03H130 | E22: DCH de caldo prensado | F22: Pré-Comissionamento | G22: Conforme | H22: Roniel Figueiredo - 11/02/2026 12:06:15 | I22: Conforme | J22: Roniel Figueiredo - 11/02/2026 12:06:17 | K22: Conforme | L22: Roniel Figueiredo - 11/02/2026 12:06:20 | M22: Conforme | N22: Roniel Figueiredo - 11/02/2026 12:06:23 | O22: Conforme | P22: Roniel Figueiredo - 11/02/2026 12:06:25 | Q22: Conforme | R22: Roniel Figueiredo - 11/02/2026 12:06:28 | S22: Conforme | T22: Roniel Figueiredo - 11/02/2026 12:06:31 | U22: Conforme | V22: Roniel Figueiredo - 11/02/2026 12:06:37 | W22: Conforme | X22: Roniel Figueiredo - 11/02/2026 12:06:40 | BS22: Não | BT22: Sim | BU22: 46064.505 | BV22: Sim | BW22: 46064.505 | BX22: Sim | BY22: 46064.505 | BZ22: Comissionamento Estático | DE22: Não | DF22: Não Aplica | DH22: Não Aplica | DJ22: Não Aplica | DL22: Dinâmico Frio | EI22: Não | EJ22: Não | EL22: Dinâmico Quente | FI22: Não | FJ22: Não | FN22: Pendente | FP22: Roniel Figueiredo - 11/02/2026 12:06:40 | FQ22: Base de Dados_Images/03H130.Imagem do Equipamento-.150614.jpg | FR22: Roniel Figueiredo - 11/02/2026 12:06:40 | FU22: =FQ22 -> Base de Dados_Images/03H130.Imagem do Equipamento-.150614.jpg
A23: 10&20 - R.P.E | B23: 03H130 - DCH de caldo prensado | C23: Transmissor | D23: 03-TIT-130-B01 | E23: Temperatura Da Saída Do Aquecedor Vapor 1 | F23: Pré-Comissionamento | G23: Conforme | H23: Roniel Figueiredo - 02/02/2026 10:48:11 | I23: Conforme | J23: Roniel Figueiredo - 02/02/2026 10:48:13 | K23: Conforme | L23: Roniel Figueiredo - 02/02/2026 10:48:27 | M23: Conforme | N23: Roniel Figueiredo - 02/02/2026 10:48:21 | BS23: Não | BT23: Sim | BU23: 46055.45 | BV23: Sim | BW23: 46055.45 | BX23: Sim | BY23: 46055.45 | BZ23: Comissionamento Estático | CA23: Não Conforme | CB23: Roniel Figueiredo - 07/04/2026 09:27:07 | CC23: Não Conforme | CD23: Roniel Figueiredo - 07/04/2026 09:27:14 | CE23: Não Conforme | CF23: Roniel Figueiredo - 07/04/2026 09:27:13 | DE23: Sim | DF23: Não Aplica | DH23: Não | DJ23: Não | DL23: Dinâmico Frio | EI23: Não | EJ23: Não | EL23: Dinâmico Quente | FI23: Não | FJ23: Não | FL23: Transmisor fora de rede | FM23: Roniel Figueiredo - 07/04/2026 09:28:31 | FN23: Pendente | FP23: Roniel Figueiredo - 07/04/2026 09:28:31 | FQ23: Base de Dados_Images/03-TIT-130-B01.Imagem do Equipamento-.134809.jpg | FR23: Roniel Figueiredo - 02/02/2026 10:48:27 | FU23: =FQ23 -> Base de Dados_Images/03-TIT-130-B01.Imagem do Equipamento-.134809.jpg
A24: 10&20 - R.P.E | B24: 03H130 - DCH de caldo prensado | C24: Transmissor | D24: 03-TIT-130-Y02 | E24: Transmissor De Temperatura Do Caldo | F24: Pré-Comissionamento | G24: Conforme | H24: Ana Clara Santos Jacinto Andrade Jeronimo - 30/01/2026 08:13:51 | I24: Conforme | J24: Ana Clara Santos Jacinto Andrade Jeronimo - 30/01/2026 08:13:54 | K24: Conforme | L24: Ana Clara Santos Jacinto Andrade Jeronimo - 30/01/2026 08:13:59 | M24: Conforme | N24: Ana Clara Santos Jacinto Andrade Jeronimo - 30/01/2026 08:14:02 | BS24: Não | BT24: Sim | BU24: 46052.343 | BV24: Sim | BW24: 46052.343 | BX24: Sim | BY24: 46052.343 | BZ24: Comissionamento Estático | CA24: Não Conforme | CB24: Roniel Figueiredo - 07/04/2026 09:27:28 | CC24: Não Conforme | CD24: Roniel Figueiredo - 07/04/2026 09:27:30 | CE24: Não Conforme | CF24: Roniel Figueiredo - 07/04/2026 09:27:32 | DE24: Sim | DF24: Não Aplica | DH24: Não | DJ24: Não | DL24: Dinâmico Frio | EI24: Não | EJ24: Não | EL24: Dinâmico Quente | FI24: Não | FJ24: Não | FL24: Transmisor fora de rede | FM24: Roniel Figueiredo - 07/04/2026 09:27:55 | FN24: Pendente | FP24: Roniel Figueiredo - 07/04/2026 09:27:55 | FQ24: Base de Dados_Images/03-TIT-130-Y02.Imagem do Equipamento-.111347.jpg | FR24: Ana Clara Santos Jacinto Andrade Jeronimo - 30/01/2026 08:14:02 | FU24: =FQ24 -> Base de Dados_Images/03-TIT-130-Y02.Imagem do Equipamento-.111347.jpg
A25: 10&20 - R.P.E | B25: 03H130 - DCH de caldo prensado | C25: Válvula Pneumatica | D25: 03-TIT-130-Y02 XV | E25: Válvula Controle De Temperatura Do Caldo | F25: Pré-Comissionamento | G25: Conforme | H25: Gilmar de Sousa - 04/02/2026 08:47:52 | I25: Conforme | J25: Ana Clara Santos Jacinto Andrade Jeronimo - 30/01/2026 08:09:39 | K25: Conforme | L25: Ana Clara Santos Jacinto Andrade Jeronimo - 30/01/2026 08:09:44 | M25: Conforme | N25: Ana Clara Santos Jacinto Andrade Jeronimo - 30/01/2026 08:09:47 | O25: Conforme | P25: Ana Clara Santos Jacinto Andrade Jeronimo - 30/01/2026 08:09:56 | Q25: Conforme | R25: Ana Clara Santos Jacinto Andrade Jeronimo - 30/01/2026 08:09:59 | S25: Conforme | T25: Ana Clara Santos Jacinto Andrade Jeronimo - 30/01/2026 08:10:01 | U25: Conforme | V25: Ana Clara Santos Jacinto Andrade Jeronimo - 30/01/2026 08:10:03 | BS25: Não | BT25: Não Aplica | BV25: Sim | BW25: 46057.367 | BX25: Sim | BY25: 46057.367 | BZ25: Comissionamento Estático | CA25: Conforme | CB25: Roniel Figueiredo - 04/04/2026 10:18:13 | CC25: Conforme | CD25: Roniel Figueiredo - 04/04/2026 10:18:14 | DE25: Não | DF25: Não Aplica | DH25: Sim | DI25: 46116.429 | DJ25: Sim | DK25: 46116.429 | DL25: Dinâmico Frio | EI25: Não | EJ25: Não | EL25: Dinâmico Quente | FI25: Não | FJ25: Não | FN25: Pendente | FP25: Roniel Figueiredo - 04/04/2026 10:18:14 | FQ25: Base de Dados_Images/03-TIT-130-Y02 XV.Imagem do Equipamento-.155550.jpg | FR25: Ana Clara Santos Jacinto Andrade Jeronimo - 22/01/2026 12:55:45 | FU25: =FQ25 -> Base de Dados_Images/03-TIT-130-Y02 XV.Imagem do Equipamento-.155550.jpg
A26: 10&20 - R.P.E | B26: 03H135 - Tanque de embebição | C26: Tanque | D26: 03H135 | E26: Tanque De Embebição do Difusor | F26: Pré-Comissionamento | G26: Conforme | H26: Roniel Figueiredo - 11/02/2026 12:11:11 | I26: Conforme | J26: Roniel Figueiredo - 11/02/2026 12:11:15 | K26: Conforme | L26: Roniel Figueiredo - 11/02/2026 12:11:16 | M26: Conforme | N26: Roniel Figueiredo - 11/02/2026 12:11:19 | O26: Conforme | P26: Roniel Figueiredo - 11/02/2026 12:11:28 | Q26: Conforme | R26: Roniel Figueiredo - 11/02/2026 12:11:24 | S26: Conforme | T26: Roniel Figueiredo - 11/02/2026 12:11:32 | U26: Conforme | V26: Roniel Figueiredo - 11/02/2026 12:11:34 | W26: Conforme | X26: Roniel Figueiredo - 11/02/2026 12:11:37 | BS26: Não | BT26: Sim | BU26: 46064.508 | BV26: Sim | BW26: 46064.508 | BX26: Sim | BY26: 46064.508 | BZ26: Comissionamento Estático | DE26: Não | DF26: Não Aplica | DH26: Não Aplica | DJ26: Não Aplica | DL26: Dinâmico Frio | EI26: Não | EJ26: Não | EL26: Dinâmico Quente | FI26: Não | FJ26: Não | FN26: Pendente | FP26: Roniel Figueiredo - 11/02/2026 12:11:37 | FQ26: Base de Dados_Images/03H135.Imagem do Equipamento-.151112.jpg | FR26: Roniel Figueiredo - 11/02/2026 12:11:37 | FU26: =FQ26 -> Base de Dados_Images/03H135.Imagem do Equipamento-.151112.jpg
A27: 10&20 - R.P.E | B27: 03H135 - Tanque de embebição | C27: Transmissor | D27: 03-TIT-135-B02 | E27: Temperatura Da Saída Do Aquecedor Vapor 1 | F27: Pré-Comissionamento | G27: Conforme | H27: Roniel Figueiredo - 02/02/2026 10:29:10 | I27: Conforme | J27: Roniel Figueiredo - 02/02/2026 10:29:12 | K27: Conforme | L27: Roniel Figueiredo - 02/02/2026 10:29:14 | M27: Conforme | N27: Roniel Figueiredo - 02/02/2026 10:29:17 | BS27: Não | BT27: Sim | BU27: 46055.437 | BV27: Sim | BW27: 46055.437 | BX27: Sim | BY27: 46055.437 | BZ27: Comissionamento Estático | CA27: Conforme | CB27: Roniel Figueiredo - 25/03/2026 10:53:13 | CC27: Conforme | CD27: Roniel Figueiredo - 25/03/2026 10:53:15 | CE27: Conforme | CF27: Roniel Figueiredo - 25/03/2026 10:53:18 | DE27: Não | DF27: Não Aplica | DH27: Sim | DI27: 46106.454 | DJ27: Sim | DK27: 46106.454 | DL27: Dinâmico Frio | EI27: Não | EJ27: Não | EL27: Dinâmico Quente | FI27: Não | FJ27: Não | FN27: Pendente | FP27: Roniel Figueiredo - 25/03/2026 10:53:18 | FQ27: Base de Dados_Images/03-TIT-135-B02.Imagem do Equipamento-.132910.jpg | FR27: Roniel Figueiredo - 02/02/2026 10:29:17 | FU27: =FQ27 -> Base de Dados_Images/03-TIT-135-B02.Imagem do Equipamento-.132910.jpg
A28: 10&20 - R.P.E | B28: 03H135 - Tanque de embebição | C28: Transmissor | D28: 03-TIT-135-Y01 | E28: Transmissor De Temperatura De Alimentação De Água Bruta | F28: Pré-Comissionamento | G28: Conforme | H28: Roniel Figueiredo - 02/02/2026 10:32:41 | I28: Conforme | J28: Roniel Figueiredo - 02/02/2026 10:32:46 | K28: Conforme | L28: Roniel Figueiredo - 02/02/2026 10:32:53 | M28: Conforme | N28: Roniel Figueiredo - 02/02/2026 10:32:55 | BS28: Não | BT28: Sim | BU28: 46055.439 | BV28: Sim | BW28: 46055.44 | BX28: Sim | BY28: 46055.44 | BZ28: Comissionamento Estático | CA28: Conforme | CB28: Roniel Figueiredo - 11/03/2026 10:02:32 | CC28: Conforme | CD28: Roniel Figueiredo - 11/03/2026 10:02:33 | CE28: Conforme | CF28: Roniel Figueiredo - 11/03/2026 10:02:36 | DE28: Não | DF28: Não Aplica | DH28: Sim | DI28: 46092.418 | DJ28: Sim | DK28: 46092.418 | DL28: Dinâmico Frio | EI28: Não | EJ28: Não | EL28: Dinâmico Quente | FI28: Não | FJ28: Não | FN28: Pendente | FP28: Roniel Figueiredo - 11/03/2026 10:02:36 | FQ28: Base de Dados_Images/03-TIT-135-Y01.Imagem do Equipamento-.133153.jpg | FR28: Roniel Figueiredo - 02/02/2026 10:32:55 | FU28: =FQ28 -> Base de Dados_Images/03-TIT-135-Y01.Imagem do Equipamento-.133153.jpg
A29: 10&20 - R.P.E | B29: 03H135 - Tanque de embebição | C29: Transmissor | D29: 03-FIT-135-Y01 | E29: Transmissor De Vazão De Alimentação De Água Bruta | F29: Pré-Comissionamento | G29: Conforme | H29: Roniel Figueiredo - 02/02/2026 10:34:47 | I29: Conforme | J29: Roniel Figueiredo - 02/02/2026 10:34:59 | K29: Conforme | L29: Roniel Figueiredo - 02/02/2026 10:35:02 | M29: Conforme | N29: Roniel Figueiredo - 02/02/2026 10:34:52 | BS29: Não | BT29: Sim | BU29: 46055.441 | BV29: Sim | BW29: 46055.441 | BX29: Sim | BY29: 46055.441 | BZ29: Comissionamento Estático | CA29: Conforme | CB29: Roniel Figueiredo - 11/03/2026 10:03:07 | CC29: Conforme | CD29: Roniel Figueiredo - 11/03/2026 10:03:09 | CE29: Conforme | CF29: Roniel Figueiredo - 11/03/2026 10:03:12 | DE29: Não | DF29: Não Aplica | DH29: Sim | DI29: 46092.419 | DJ29: Sim | DK29: 46092.419 | DL29: Dinâmico Frio | EI29: Não | EJ29: Não | EL29: Dinâmico Quente | FI29: Não | FJ29: Não | FN29: Pendente | FP29: Roniel Figueiredo - 11/03/2026 10:03:12 | FQ29: Base de Dados_Images/03-FIT-135-Y01.Imagem do Equipamento-.133714.jpg | FR29: Roniel Figueiredo - 02/02/2026 10:35:02 | FU29: =FQ29 -> Base de Dados_Images/03-FIT-135-Y01.Imagem do Equipamento-.133714.jpg
A30: 10&20 - R.P.E | B30: 03H135 - Tanque de embebição | C30: Válvula Pneumatica | D30: 03-TIT-135-Y01 XV | E30: Válvula De Controle De Temperatura De Alimentação De Água Bruta | F30: Pré-Comissionamento | G30: Conforme | H30: Roniel Figueiredo - 02/02/2026 10:43:41 | I30: Conforme | J30: Roniel Figueiredo - 02/02/2026 10:43:45 | K30: Conforme | L30: Roniel Figueiredo - 02/02/2026 10:43:48 | M30: Conforme | N30: Roniel Figueiredo - 02/02/2026 10:43:54 | O30: Conforme | P30: Roniel Figueiredo - 02/02/2026 10:43:58 | Q30: Conforme | R30: Roniel Figueiredo - 02/02/2026 10:44:01 | S30: Conforme | T30: Roniel Figueiredo - 02/02/2026 10:44:06 | U30: Conforme | V30: Roniel Figueiredo - 02/02/2026 10:44:10 | BS30: Não | BT30: Não Aplica | BV30: Sim | BW30: 46055.447 | BX30: Sim | BY30: 46055.447 | BZ30: Comissionamento Estático | CA30: Conforme | CB30: Roniel Figueiredo - 28/03/2026 09:02:17 | CC30: Conforme | CD30: Roniel Figueiredo - 28/03/2026 09:02:20 | DE30: Não | DF30: Não Aplica | DH30: Sim | DI30: 46109.377 | DJ30: Sim | DK30: 46109.377 | DL30: Dinâmico Frio | EI30: Não | EJ30: Não | EL30: Dinâmico Quente | FI30: Não | FJ30: Não | FN30: Pendente | FP30: Roniel Figueiredo - 28/03/2026 09:02:20 | FQ30: Base de Dados_Images/03-TIT-135-Y01 XV.Imagem do Equipamento-.134255.jpg | FR30: Roniel Figueiredo - 02/02/2026 10:42:46 | FU30: =FQ30 -> Base de Dados_Images/03-TIT-135-Y01 XV.Imagem do Equipamento-.134255.jpg
A31: 10&20 - R.P.E | B31: 03H135 - Tanque de embebição | C31: Válvula Pneumatica | D31: 03-FIT-135-Y01 XV | E31: Válvula De Controle De Vazão De Alimentação De Água Bruta | F31: Pré-Comissionamento | G31: Conforme | H31: Roniel Figueiredo - 02/02/2026 10:46:14 | I31: Conforme | J31: Roniel Figueiredo - 02/02/2026 10:46:16 | K31: Conforme | L31: Roniel Figueiredo - 02/02/2026 10:46:20 | M31: Conforme | N31: Roniel Figueiredo - 02/02/2026 10:46:24 | O31: Conforme | P31: Roniel Figueiredo - 02/02/2026 10:46:26 | Q31: Conforme | R31: Roniel Figueiredo - 02/02/2026 10:46:27 | S31: Conforme | T31: Roniel Figueiredo - 02/02/2026 10:46:33 | U31: Conforme | V31: Roniel Figueiredo - 02/02/2026 10:46:35 | BS31: Não | BT31: Não Aplica | BV31: Sim | BW31: 46055.449 | BX31: Sim | BY31: 46055.449 | BZ31: Comissionamento Estático | DE31: Não | DF31: Não Aplica | DH31: Não | DJ31: Não | DL31: Dinâmico Frio | EI31: Não | EJ31: Não | EL31: Dinâmico Quente | FI31: Não | FJ31: Não | FN31: Pendente | FP31: Roniel Figueiredo - 02/02/2026 10:46:35 | FQ31: Base de Dados_Images/03-FIT-135-Y01 XV.Imagem do Equipamento-.134518.jpg | FR31: Roniel Figueiredo - 02/02/2026 10:45:08 | FU31: =FQ31 -> Base de Dados_Images/03-FIT-135-Y01 XV.Imagem do Equipamento-.134518.jpg
A32: 10&20 - R.P.E | B32: 03S550 - Peneira | C32: Motoredutor | D32: 03-ES-550-M01 | E32: Peneira Rotativa | F32: Pré-Comissionamento | G32: Conforme | H32: Gleymilson Alves Bezerra - 02/02/2026 16:19:01 | I32: Conforme | J32: Gleymilson Alves Bezerra - 02/02/2026 16:19:20 | K32: Conforme | L32: Gleymilson Alves Bezerra - 02/02/2026 16:19:32 | M32: Conforme | N32: Gleymilson Alves Bezerra - 02/02/2026 16:19:38 | O32: Conforme | P32: Gleymilson Alves Bezerra - 02/02/2026 16:19:44 | Q32: Conforme | R32: Gleymilson Alves Bezerra - 02/02/2026 16:19:47 | S32: Conforme | T32: Gleymilson Alves Bezerra - 02/02/2026 16:20:05 | U32: Conforme | V32: Gleymilson Alves Bezerra - 02/02/2026 16:20:09 | W32: Conforme | X32: Gleymilson Alves Bezerra - 02/02/2026 16:20:17 | Y32: Conforme | Z32: Gleymilson Alves Bezerra - 02/02/2026 16:20:29 | AA32: Conforme | AB32: Gleymilson Alves Bezerra - 02/02/2026 16:20:34 | AC32: Conforme | AD32: Gleymilson Alves Bezerra - 02/02/2026 16:20:51 | AE32: Conforme | AF32: Gleymilson Alves Bezerra - 02/02/2026 16:21:13 | BS32: Não | BT32: Sim | BU32: 46055.68 | BV32: Sim | BW32: 46055.681 | BX32: Sim | BY32: 46055.681 | BZ32: Comissionamento Estático | CA32: Conforme | CB32: Roniel Figueiredo - 05/03/2026 08:26:19 | CC32: Conforme | CD32: Roniel Figueiredo - 05/03/2026 08:26:21 | CE32: Conforme | CF32: Roniel Figueiredo - 05/03/2026 08:26:25 | CG32: Conforme | CH32: Roniel Figueiredo - 05/03/2026 08:26:27 | DE32: Não | DF32: Sim | DG32: 46086.352 | DH32: Sim | DI32: 46086.352 | DJ32: Sim | DK32: 46086.352 | DL32: Dinâmico Frio | DM32: Conforme | DN32: Roniel Figueiredo - 02/04/2026 09:26:16 | DO32: Conforme | DP32: Roniel Figueiredo - 02/04/2026 09:26:17 | DQ32: Conforme | DR32: Roniel Figueiredo - 02/04/2026 09:26:24 | DS32: Conforme | DT32: Roniel Figueiredo - 02/04/2026 09:26:20 | DU32: Conforme | DV32: Roniel Figueiredo - 02/04/2026 09:26:21 | EI32: Não | EJ32: Sim | EK32: 46114.393 | EL32: Dinâmico Quente | FI32: Não | FJ32: Não | FN32: Pendente | FP32: Roniel Figueiredo - 02/04/2026 09:26:24 | FQ32: Base de Dados_Images/03-ES-550-M01.Imagem do Equipamento-.191852.jpg | FR32: Gleymilson Alves Bezerra - 02/02/2026 16:19:01 | FU32: =FQ32 -> Base de Dados_Images/03-ES-550-M01.Imagem do Equipamento-.191852.jpg
A33: 10&20 - R.P.E | B33: 03S550 - Peneira | C33: Peneira Rotativa/Difusor | D33: 03S550 | E33: Peneira Rotativa | F33: Pré-Comissionamento | G33: Conforme | H33: Gleymilson Alves Bezerra - 02/02/2026 16:20:26 | I33: Conforme | J33: Gleymilson Alves Bezerra - 02/02/2026 16:20:30 | K33: Conforme | L33: Gleymilson Alves Bezerra - 02/02/2026 16:20:40 | M33: Conforme | N33: Gleymilson Alves Bezerra - 02/02/2026 16:20:44 | O33: Conforme | P33: Gleymilson Alves Bezerra - 02/02/2026 16:20:50 | Q33: Conforme | R33: Gleymilson Alves Bezerra - 02/02/2026 16:20:55 | S33: Conforme | T33: Gleymilson Alves Bezerra - 02/02/2026 16:21:33 | U33: Conforme | V33: Gleymilson Alves Bezerra - 02/02/2026 16:22:06 | W33: Conforme | X33: Gleymilson Alves Bezerra - 02/02/2026 16:22:15 | Y33: Conforme | Z33: Gleymilson Alves Bezerra - 02/02/2026 16:22:21 | AA33: Conforme | AB33: Gleymilson Alves Bezerra - 02/02/2026 16:22:26 | AC33: Conforme | AD33: Gleymilson Alves Bezerra - 02/02/2026 16:22:47 | AE33: Conforme | AF33: Gleymilson Alves Bezerra - 02/02/2026 16:22:59 | AG33: Conforme | AH33: Gleymilson Alves Bezerra - 02/02/2026 16:23:05 | AI33: Conforme | AJ33: Gleymilson Alves Bezerra - 02/02/2026 16:23:09 | BS33: Não | BT33: Sim | BU33: 46055.682 | BV33: Sim | BW33: 46055.683 | BX33: Sim | BY33: 46055.683 | BZ33: Comissionamento Estático | CA33: Conforme | CB33: Roniel Figueiredo - 05/03/2026 08:26:39 | CC33: Conforme | CD33: Roniel Figueiredo - 05/03/2026 08:26:41 | CE33: Conforme | CF33: Roniel Figueiredo - 05/03/2026 08:26:44 | CG33: Conforme | CH33: Roniel Figueiredo - 05/03/2026 08:26:46 | DE33: Não | DF33: Sim | DG33: 46086.352 | DH33: Sim | DI33: 46086.352 | DJ33: Sim | DK33: 46086.352 | DL33: Dinâmico Frio | DM33: Conforme | DN33: Roniel Figueiredo - 02/04/2026 09:26:47 | DO33: Conforme | DP33: Roniel Figueiredo - 02/04/2026 09:26:49 | DQ33: Conforme | DR33: Roniel Figueiredo - 02/04/2026 09:26:50 | EI33: Não | EJ33: Sim | EK33: 46114.394 | EL33: Dinâmico Quente | FI33: Não | FJ33: Não | FN33: Pendente | FP33: Roniel Figueiredo - 02/04/2026 09:26:50 | FQ33: Base de Dados_Images/03S550.Imagem do Equipamento-.192020.jpg | FR33: Gleymilson Alves Bezerra - 02/02/2026 16:20:55 | FU33: =FQ33 -> Base de Dados_Images/03S550.Imagem do Equipamento-.192020.jpg
A34: 10&20 - R.P.E | B34: 03T590 - Tanque de condensado dos aquecedores | C34: Motor E Bomba | D34: 03-ES-170-M01 | E34: Bomba De Condensado | F34: Pré-Comissionamento | G34: Conforme | H34: Roniel Figueiredo - 04/04/2026 10:26:57 | I34: Conforme | J34: Roniel Figueiredo - 04/04/2026 10:26:59 | K34: Conforme | L34: Roniel Figueiredo - 04/04/2026 10:27:02 | M34: Conforme | N34: Roniel Figueiredo - 04/04/2026 10:27:05 | O34: Conforme | P34: Roniel Figueiredo - 04/04/2026 10:27:08 | Q34: Conforme | R34: Roniel Figueiredo - 04/04/2026 10:27:10 | S34: Conforme | T34: Roniel Figueiredo - 04/04/2026 10:27:13 | U34: Conforme | V34: Roniel Figueiredo - 04/04/2026 10:27:27 | W34: Conforme | X34: Roniel Figueiredo - 04/04/2026 10:27:28 | Y34: Conforme | Z34: Roniel Figueiredo - 04/04/2026 10:27:34 | AA34: Conforme | AB34: Roniel Figueiredo - 04/04/2026 10:27:38 | AC34: Conforme | AD34: Roniel Figueiredo - 04/04/2026 10:27:36 | AE34: Conforme | AF34: Roniel Figueiredo - 04/04/2026 10:27:42 | AG34: Conforme | AH34: Roniel Figueiredo - 04/04/2026 10:27:44 | AI34: Conforme | AJ34: Roniel Figueiredo - 04/04/2026 10:27:51 | AK34: Conforme | AL34: Roniel Figueiredo - 04/04/2026 10:27:52 | AM34: Conforme | AN34: Roniel Figueiredo - 04/04/2026 10:28:06 | AO34: Conforme | AP34: Roniel Figueiredo - 04/04/2026 10:27:57 | BS34: Não | BT34: Sim | BU34: 46116.436 | BV34: Sim | BW34: 46116.436 | BX34: Sim | BY34: 46116.436 | BZ34: Comissionamento Estático | CA34: Conforme | CB34: Roniel Figueiredo - 04/04/2026 10:32:23 | CC34: Conforme | CD34: Roniel Figueiredo - 04/04/2026 10:32:25 | CE34: Conforme | CF34: Roniel Figueiredo - 04/04/2026 10:32:26 | CG34: Conforme | CH34: Roniel Figueiredo - 04/04/2026 10:32:29 | CI34: Conforme | CJ34: Roniel Figueiredo - 04/04/2026 10:32:30 | CK34: Conforme | CL34: Roniel Figueiredo - 04/04/2026 10:32:31 | DE34: Não | DF34: Sim | DG34: 46116.439 | DH34: Sim | DI34: 46116.439 | DJ34: Sim | DK34: 46116.439 | DL34: Dinâmico Frio | EI34: Não | EJ34: Não | EL34: Dinâmico Quente | FI34: Não | FJ34: Não | FN34: Pendente | FP34: Roniel Figueiredo - 04/04/2026 10:32:31 | FQ34: Base de Dados_Images/03-ES-170-M01.Imagem do Equipamento-.133237.jpg | FR34: Roniel Figueiredo - 04/04/2026 10:32:31 | FS34: Base de Dados_Images/03-ES-170-M01.Imagem da Plaqueta do Motor-.133243.jpg | FT34: Roniel Figueiredo - 04/04/2026 10:32:31 | FU34: =FQ34 -> Base de Dados_Images/03-ES-170-M01.Imagem do Equipamento-.133237.jpg
A35: 10&20 - R.P.E | B35: 03T590 - Tanque de condensado dos aquecedores | C35: Tanque | D35: 03T590 | E35: Tanque De Condensado Dos Aquecedores | F35: Pré-Comissionamento | G35: Conforme | H35: Roniel Figueiredo - 14/03/2026 12:05:14 | I35: Conforme | J35: Roniel Figueiredo - 14/03/2026 12:05:19 | K35: Conforme | L35: Roniel Figueiredo - 14/03/2026 12:05:26 | M35: Conforme | N35: Roniel Figueiredo - 14/03/2026 12:05:38 | O35: Conforme | P35: Roniel Figueiredo - 14/03/2026 12:05:46 | Q35: Conforme | R35: Roniel Figueiredo - 14/03/2026 12:05:49 | S35: Conforme | T35: Roniel Figueiredo - 14/03/2026 12:05:55 | U35: Conforme | V35: Roniel Figueiredo - 14/03/2026 12:05:58 | W35: Conforme | X35: Roniel Figueiredo - 14/03/2026 12:06:00 | BS35: Não | BT35: Sim | BU35: 46095.504 | BV35: Sim | BW35: 46095.504 | BX35: Sim | BY35: 46095.504 | BZ35: Comissionamento Estático | DE35: Não | DF35: Não Aplica | DH35: Não Aplica | DJ35: Não Aplica | DL35: Dinâmico Frio | DM35: Conforme | DN35: Roniel Figueiredo - 30/03/2026 12:08:15 | DO35: Não Conforme | DP35: Roniel Figueiredo - 30/03/2026 12:08:19 | EI35: Sim | EJ35: Não | EL35: Dinâmico Quente | FI35: Não | FJ35: Não | FL35: Vazamento na parte superior do tanque | FM35: Roniel Figueiredo - 30/03/2026 12:08:55 | FN35: Pendente | FP35: Roniel Figueiredo - 30/03/2026 12:08:55 | FQ35: Base de Dados_Images/03T590.Imagem do Equipamento-.150508.jpg | FR35: Roniel Figueiredo - 14/03/2026 12:06:00 | FU35: =FQ35 -> Base de Dados_Images/03T590.Imagem do Equipamento-.150508.jpg
A36: 10&20 - R.P.E | B36: 03T590 - Tanque de condensado dos aquecedores | C36: Transmissor | D36: 03-TIT-590-B01 | E36: Temperatura Tanque De Condensado | F36: Pré-Comissionamento | G36: Conforme | H36: Ana Clara Santos Jacinto Andrade Jeronimo - 30/01/2026 10:43:29 | I36: Conforme | J36: Ana Clara Santos Jacinto Andrade Jeronimo - 30/01/2026 10:43:33 | K36: Conforme | L36: Ana Clara Santos Jacinto Andrade Jeronimo - 30/01/2026 10:43:38 | M36: Conforme | N36: Ana Clara Santos Jacinto Andrade Jeronimo - 30/01/2026 10:43:41 | BS36: Não | BT36: Sim | BU36: 46052.447 | BV36: Sim | BW36: 46052.447 | BX36: Sim | BY36: 46052.447 | BZ36: Comissionamento Estático | CA36: Conforme | CB36: Roniel Figueiredo - 25/03/2026 10:55:32 | CC36: Conforme | CD36: Roniel Figueiredo - 25/03/2026 10:55:33 | CE36: Conforme | CF36: Roniel Figueiredo - 25/03/2026 10:55:34 | DE36: Não | DF36: Não Aplica | DH36: Sim | DI36: 46106.455 | DJ36: Sim | DK36: 46106.455 | DL36: Dinâmico Frio | DM36: Conforme | DN36: Roniel Figueiredo - 03/04/2026 10:48:02 | DO36: Conforme | DP36: Roniel Figueiredo - 03/04/2026 10:48:04 | EI36: Não | EJ36: Sim | EK36: 46115.45 | EL36: Dinâmico Quente | FI36: Não | FJ36: Não | FN36: Pendente | FP36: Roniel Figueiredo - 03/04/2026 10:48:04 | FQ36: Base de Dados_Images/03-TIT-590-B01.Imagem do Equipamento-.134434.jpg | FR36: Ana Clara Santos Jacinto Andrade Jeronimo - 30/01/2026 10:43:41 | FU36: =FQ36 -> Base de Dados_Images/03-TIT-590-B01.Imagem do Equipamento-.134434.jpg
A37: 10&20 - R.P.E | B37: 03T590 - Tanque de condensado dos aquecedores | C37: Transmissor | D37: 03-FIT-170-B01 | E37: Vazão Tanque De Condensado | F37: Pré-Comissionamento | G37: Não Conforme | H37: Roniel Figueiredo - 13/03/2026 08:18:17 | I37: Não Conforme | J37: Roniel Figueiredo - 13/03/2026 08:18:26 | K37: Não Conforme | L37: Roniel Figueiredo - 13/03/2026 08:18:31 | M37: Não Conforme | N37: Roniel Figueiredo - 13/03/2026 08:18:34 | BS37: Sim | BT37: Não | BV37: Não | BX37: Não | BZ37: Comissionamento Estático | CA37: Conforme | CB37: Roniel Figueiredo - 30/03/2026 09:05:04 | CC37: Não Conforme | CD37: Roniel Figueiredo - 30/03/2026 09:05:05 | CE37: Não Conforme | CF37: Roniel Figueiredo - 30/03/2026 09:05:09 | DE37: Sim | DF37: Não Aplica | DH37: Não | DJ37: Não | DL37: Dinâmico Frio | DM37: Não Conforme | DN37: Roniel Figueiredo - 03/04/2026 11:00:45 | DO37: Não Conforme | DP37: Roniel Figueiredo - 03/04/2026 11:00:47 | EI37: Sim | EJ37: Não | EL37: Dinâmico Quente | FI37: Não | FJ37: Não | FL37: Equipamento fora do local | FM37: Roniel Figueiredo - 13/03/2026 08:18:13 | FN37: Pendente | FP37: Roniel Figueiredo - 03/04/2026 11:00:47 | FQ37: Base de Dados_Images/03-FIT-170-B01.Imagem do Equipamento-.125743.jpg | FR37: Roniel Figueiredo - 13/03/2026 08:18:34 | FU37: =FQ37 -> Base de Dados_Images/03-FIT-170-B01.Imagem do Equipamento-.125743.jpg
A38: 10&20 - R.P.E | B38: 03T590 - Tanque de condensado dos aquecedores | C38: Transmissor | D38: 03-LIT-590-B01 | E38: Nível Tanque De Condensado | F38: Pré-Comissionamento | G38: Conforme | H38: Ana Clara Santos Jacinto Andrade Jeronimo - 30/01/2026 10:25:37 | I38: Conforme | J38: Ana Clara Santos Jacinto Andrade Jeronimo - 30/01/2026 10:25:40 | K38: Conforme | L38: Ana Clara Santos Jacinto Andrade Jeronimo - 30/01/2026 10:25:44 | M38: Conforme | N38: Ana Clara Santos Jacinto Andrade Jeronimo - 30/01/2026 10:25:51 | BS38: Não | BT38: Sim | BU38: 46052.434 | BV38: Sim | BW38: 46052.435 | BX38: Sim | BY38: 46052.435 | BZ38: Comissionamento Estático | CA38: Conforme | CB38: Roniel Figueiredo - 25/03/2026 10:56:11 | CC38: Conforme | CD38: Roniel Figueiredo - 25/03/2026 10:56:13 | CE38: Conforme | CF38: Roniel Figueiredo - 25/03/2026 10:56:15 | DE38: Não | DF38: Não Aplica | DH38: Sim | DI38: 46106.456 | DJ38: Sim | DK38: 46106.456 | DL38: Dinâmico Frio | DM38: Conforme | DN38: Roniel Figueiredo - 02/04/2026 08:57:24 | DO38: Conforme | DP38: Roniel Figueiredo - 02/04/2026 08:57:25 | EI38: Não | EJ38: Sim | EK38: 46114.373 | EL38: Dinâmico Quente | FI38: Não | FJ38: Não | FN38: Pendente | FP38: Roniel Figueiredo - 02/04/2026 08:57:25 | FQ38: Base de Dados_Images/03-LIT-590-B01.Imagem do Equipamento-.134654.jpg | FR38: Ana Clara Santos Jacinto Andrade Jeronimo - 30/01/2026 10:46:48 | FU38: =FQ38 -> Base de Dados_Images/03-LIT-590-B01.Imagem do Equipamento-.134654.jpg
A39: 10&20 - R.P.E | B39: 03T590 - Tanque de condensado dos aquecedores | C39: Transmissor | D39: 03-LIT-590-B01/03-LCV-590 | E39: Válvula De Controle Nível Tanque De Condensado | F39: Pré-Comissionamento | G39: Conforme | H39: Ana Clara Santos Jacinto Andrade Jeronimo - 30/01/2026 10:24:10 | I39: Conforme | J39: Ana Clara Santos Jacinto Andrade Jeronimo - 30/01/2026 10:24:27 | K39: Conforme | L39: Ana Clara Santos Jacinto Andrade Jeronimo - 30/01/2026 10:24:29 | M39: Conforme | N39: Ana Clara Santos Jacinto Andrade Jeronimo - 30/01/2026 10:24:36 | BS39: Não | BT39: Sim | BU39: 46052.433 | BV39: Sim | BW39: 46052.434 | BX39: Sim | BY39: 46052.434 | BZ39: Comissionamento Estático | CA39: Conforme | CB39: Roniel Figueiredo - 25/03/2026 11:04:23 | CC39: Conforme | CD39: Roniel Figueiredo - 25/03/2026 11:04:24 | CE39: Conforme | CF39: Roniel Figueiredo - 25/03/2026 11:04:25 | DE39: Não | DF39: Não Aplica | DH39: Sim | DI39: 46106.461 | DJ39: Sim | DK39: 46106.461 | DL39: Dinâmico Frio | DM39: Conforme | DN39: Roniel Figueiredo - 02/04/2026 08:57:43 | DO39: Conforme | DP39: Roniel Figueiredo - 02/04/2026 08:57:44 | EI39: Não | EJ39: Sim | EK39: 46114.373 | EL39: Dinâmico Quente | FI39: Não | FJ39: Não | FN39: Pendente | FP39: Roniel Figueiredo - 02/04/2026 08:57:44 | FQ39: Base de Dados_Images/03-LIT-590-B01-03-LCV-590.Imagem do Equipamento-.132406.jpg | FR39: Ana Clara Santos Jacinto Andrade Jeronimo - 30/01/2026 10:24:36 | FU39: =FQ39 -> Base de Dados_Images/03-LIT-590-B01-03-LCV-590.Imagem do Equipamento-.132406.jpg
A40: 10&20 - R.P.E | B40: 03T590 - Tanque de condensado dos aquecedores | C40: Válvula Pneumatica | D40: 03-KS-590-Y01 | E40: Condensado Para Limpeza Da Peneira Rotativa | F40: Pré-Comissionamento | G40: Conforme | H40: Ana Clara Santos Jacinto Andrade Jeronimo - 30/01/2026 10:47:57 | I40: Conforme | J40: Ana Clara Santos Jacinto Andrade Jeronimo - 30/01/2026 10:47:59 | K40: Conforme | L40: Gilmar de Sousa - 04/02/2026 08:49:51 | M40: Conforme | N40: Ana Clara Santos Jacinto Andrade Jeronimo - 30/01/2026 10:48:20 | O40: Conforme | P40: Ana Clara Santos Jacinto Andrade Jeronimo - 30/01/2026 10:48:28 | Q40: Conforme | R40: Ana Clara Santos Jacinto Andrade Jeronimo - 30/01/2026 10:48:43 | S40: Conforme | T40: Ana Clara Santos Jacinto Andrade Jeronimo - 30/01/2026 10:48:33 | U40: Conforme | V40: Ana Clara Santos Jacinto Andrade Jeronimo - 30/01/2026 10:48:38 | BS40: Não | BT40: Não Aplica | BV40: Sim | BW40: 46057.368 | BX40: Sim | BY40: 46057.368 | BZ40: Comissionamento Estático | CA40: Conforme | CB40: Roniel Figueiredo - 07/04/2026 15:10:58 | CC40: Conforme | CD40: Roniel Figueiredo - 07/04/2026 15:10:59 | DE40: Não | DF40: Não Aplica | DH40: Sim | DI40: 46119.633 | DJ40: Sim | DK40: 46119.633 | DL40: Dinâmico Frio | DM40: Conforme | DN40: Roniel Figueiredo - 07/04/2026 15:11:07 | EI40: Não | EJ40: Sim | EK40: 46119.633 | EL40: Dinâmico Quente | FI40: Não | FJ40: Não | FN40: Pendente | FP40: Roniel Figueiredo - 07/04/2026 15:11:07 | FQ40: Base de Dados_Images/03-KS-590-Y01.Imagem do Equipamento-.134747.jpg | FR40: Ana Clara Santos Jacinto Andrade Jeronimo - 30/01/2026 10:48:43 | FU40: =FQ40 -> Base de Dados_Images/03-KS-590-Y01.Imagem do Equipamento-.134747.jpg
A41: 10&20 - R.P.E | B41: 03T590 - Tanque de condensado dos aquecedores | C41: Válvula Pneumatica | D41: 03-KS-590-Y02 | E41: Temperatura Do Caldo Na Saida Do Aquecedor Aq-3021 | F41: Pré-Comissionamento | G41: Conforme | H41: Gilmar de Sousa - 04/02/2026 10:07:52 | I41: Conforme | J41: Ana Clara Santos Jacinto Andrade Jeronimo - 30/01/2026 10:50:32 | K41: Conforme | L41: Ana Clara Santos Jacinto Andrade Jeronimo - 30/01/2026 10:50:38 | M41: Conforme | N41: Ana Clara Santos Jacinto Andrade Jeronimo - 30/01/2026 10:50:45 | O41: Conforme | P41: Ana Clara Santos Jacinto Andrade Jeronimo - 30/01/2026 10:50:50 | Q41: Conforme | R41: Ana Clara Santos Jacinto Andrade Jeronimo - 30/01/2026 10:50:57 | S41: Conforme | T41: Ana Clara Santos Jacinto Andrade Jeronimo - 30/01/2026 10:51:03 | U41: Conforme | V41: Ana Clara Santos Jacinto Andrade Jeronimo - 30/01/2026 10:51:04 | BS41: Não | BT41: Não Aplica | BV41: Sim | BW41: 46057.422 | BX41: Sim | BY41: 46057.422 | BZ41: Comissionamento Estático | CA41: Conforme | CB41: Roniel Figueiredo - 07/04/2026 15:12:21 | CC41: Conforme | CD41: Roniel Figueiredo - 07/04/2026 15:12:21 | DE41: Não | DF41: Não Aplica | DH41: Sim | DI41: 46119.634 | DJ41: Sim | DK41: 46119.634 | DL41: Dinâmico Frio | DM41: Conforme | DN41: Roniel Figueiredo - 07/04/2026 15:12:27 | EI41: Não | EJ41: Sim | EK41: 46119.634 | EL41: Dinâmico Quente | FI41: Não | FJ41: Não | FN41: Pendente | FP41: Roniel Figueiredo - 07/04/2026 15:12:27 | FQ41: Base de Dados_Images/03-KS-590-Y02.Imagem do Equipamento-.135000.jpg | FR41: Ana Clara Santos Jacinto Andrade Jeronimo - 30/01/2026 10:51:04 | FU41: =FQ41 -> Base de Dados_Images/03-KS-590-Y02.Imagem do Equipamento-.135000.jpg
A42: 10&20 - R.P.E | B42: 03T770 - Tanque de Caldo Prensado | C42: Motor E Bomba | D42: 03-ES-820-M01 | E42: Bomba De Recirculação Caldo Residual Prensagem | F42: Pré-Comissionamento | G42: Conforme | H42: Roniel Figueiredo - 03/04/2026 09:55:33 | I42: Conforme | J42: Roniel Figueiredo - 03/04/2026 09:55:34 | K42: Conforme | L42: Roniel Figueiredo - 03/04/2026 09:55:37 | M42: Conforme | N42: Roniel Figueiredo - 03/04/2026 09:55:39 | O42: Conforme | P42: Roniel Figueiredo - 03/04/2026 09:55:42 | Q42: Conforme | R42: Roniel Figueiredo - 03/04/2026 09:55:46 | S42: Conforme | T42: Roniel Figueiredo - 03/04/2026 09:55:48 | U42: Conforme | V42: Roniel Figueiredo - 03/04/2026 09:55:49 | W42: Não Aplicável | X42: Roniel Figueiredo - 03/04/2026 09:56:24 | Y42: Não Aplicável | Z42: Roniel Figueiredo - 03/04/2026 09:56:28 | AA42: Conforme | AB42: Roniel Figueiredo - 03/04/2026 09:56:38 | AC42: Conforme | AD42: Roniel Figueiredo - 03/04/2026 09:56:41 | AE42: Conforme | AF42: Roniel Figueiredo - 03/04/2026 09:56:42 | AG42: Não Aplicável | AH42: Roniel Figueiredo - 03/04/2026 09:56:52 | AI42: Conforme | AJ42: Roniel Figueiredo - 03/04/2026 09:56:55 | AK42: Conforme | AL42: Roniel Figueiredo - 03/04/2026 09:57:05 | AM42: Conforme | AN42: Roniel Figueiredo - 03/04/2026 09:57:09 | AO42: Conforme | AP42: Roniel Figueiredo - 03/04/2026 09:57:13 | BS42: Não | BT42: Sim | BU42: 46115.414 | BV42: Sim | BW42: 46115.415 | BX42: Sim | BY42: 46115.415 | BZ42: Comissionamento Estático | DE42: Não | DF42: Não | DH42: Não | DJ42: Não | DL42: Dinâmico Frio | EI42: Não | EJ42: Não | EL42: Dinâmico Quente | FI42: Não | FJ42: Não | FN42: Pendente | FP42: Roniel Figueiredo - 03/04/2026 09:57:13 | FQ42: Base de Dados_Images/03-ES-820-M01.Imagem do Equipamento-.125530.jpg | FR42: Roniel Figueiredo - 03/04/2026 09:57:13 | FU42: =FQ42 -> Base de Dados_Images/03-ES-820-M01.Imagem do Equipamento-.125530.jpg
A43: 10&20 - R.P.E | B43: 03T770 - Tanque de Caldo Prensado | C43: Motor E Bomba | D43: 03-ES-820-M02 | E43: Bomba De Recirculação Caldo Residual Prensagem | F43: Pré-Comissionamento | G43: Conforme | H43: Roniel Figueiredo - 03/04/2026 09:59:53 | I43: Conforme | J43: Roniel Figueiredo - 03/04/2026 09:59:55 | K43: Conforme | L43: Roniel Figueiredo - 03/04/2026 10:03:55 | M43: Conforme | N43: Roniel Figueiredo - 03/04/2026 10:03:36 | O43: Conforme | P43: Roniel Figueiredo - 03/04/2026 10:04:03 | Q43: Conforme | R43: Roniel Figueiredo - 03/04/2026 10:03:57 | S43: Conforme | T43: Roniel Figueiredo - 03/04/2026 10:04:05 | U43: Conforme | V43: Roniel Figueiredo - 03/04/2026 10:04:09 | W43: Conforme | X43: Roniel Figueiredo - 03/04/2026 10:04:11 | Y43: Não Aplicável | Z43: Roniel Figueiredo - 03/04/2026 10:04:15 | AA43: Conforme | AB43: Roniel Figueiredo - 03/04/2026 10:04:19 | AC43: Conforme | AD43: Roniel Figueiredo - 03/04/2026 10:04:22 | AE43: Conforme | AF43: Roniel Figueiredo - 03/04/2026 10:04:24 | AG43: Conforme | AH43: Roniel Figueiredo - 03/04/2026 10:04:26 | AI43: Conforme | AJ43: Roniel Figueiredo - 03/04/2026 10:04:29 | AK43: Conforme | AL43: Roniel Figueiredo - 03/04/2026 10:04:30 | AM43: Conforme | AN43: Roniel Figueiredo - 03/04/2026 10:04:33 | AO43: Conforme | AP43: Roniel Figueiredo - 03/04/2026 10:04:35 | BS43: Não | BT43: Sim | BU43: 46115.42 | BV43: Sim | BW43: 46115.42 | BX43: Sim | BY43: 46115.42 | BZ43: Comissionamento Estático | DE43: Não | DF43: Não | DH43: Não | DJ43: Não | DL43: Dinâmico Frio | EI43: Não | EJ43: Não | EL43: Dinâmico Quente | FI43: Não | FJ43: Não | FN43: Pendente | FP43: Roniel Figueiredo - 03/04/2026 10:04:35 | FQ43: Base de Dados_Images/03-ES-820-M02.Imagem do Equipamento-.125939.jpg | FR43: Roniel Figueiredo - 03/04/2026 09:59:55 | FS43: Base de Dados_Images/03-ES-820-M02.Imagem da Plaqueta do Motor-.125939.jpg | FT43: Roniel Figueiredo - 03/04/2026 09:59:55 | FU43: =FQ43 -> Base de Dados_Images/03-ES-820-M02.Imagem do Equipamento-.125939.jpg
A44: 10&20 - R.P.E | B44: 03T770 - Tanque de Caldo Prensado | C44: Tanque | D44: 03T770 | E44: Tanque De Caldo Prensado | F44: Pré-Comissionamento | BS44: Não | BT44: Não | BV44: Não | BX44: Não | BZ44: Comissionamento Estático | DE44: Não | DF44: Não Aplica | DH44: Não Aplica | DJ44: Não Aplica | DL44: Dinâmico Frio | EI44: Não | EJ44: Não | EL44: Dinâmico Quente | FI44: Não | FJ44: Não | FN44: Pendente | FU44: =FQ44
