Workbook

Sheet Base de Dados
A1: Área | B1: Sistema | C1: Tipo | D1: TAG | E1: Descrição | F1: (PC) Etapa | G1: (PC) Pergunta 01 | H1: (PC) Pergunta 01 [Monitoramento] | I1: (PC) Pergunta 02 | J1: (PC) Pergunta 02 [Monitoramento] | K1: (PC) Pergunta 03 | L1: (PC) Pergunta 03 [Monitoramento] | M1: (PC) Pergunta 04 | N1: (PC) Pergunta 04 [Monitoramento] | O1: (PC) Pergunta 05 | P1: (PC) Pergunta 05 [Monitoramento] | Q1: (PC) Pergunta 06 | R1: (PC) Pergunta 06 [Monitoramento] | S1: (PC) Pergunta 07 | T1: (PC) Pergunta 07 [Monitoramento] | U1: (PC) Pergunta 08 | V1: (PC) Pergunta 08 [Monitoramento] | W1: (PC) Pergunta 09 | X1: (PC) Pergunta 09 [Monitoramento] | Y1: (PC) Pergunta 10 | Z1: (PC) Pergunta 10 [Monitoramento] | AA1: (PC) Pergunta 11 | AB1: (PC) Pergunta 11 [Monitoramento] | AC1: (PC) Pergunta 12 | AD1: (PC) Pergunta 12 [Monitoramento] | AE1: (PC) Pergunta 13 | AF1: (PC) Pergunta 13 [Monitoramento] | AG1: (PC) Pergunta 14 | AH1: (PC) Pergunta 14 [Monitoramento] | AI1: (PC) Pergunta 15 | AJ1: (PC) Pergunta 15 [Monitoramento] | AK1: (PC) Pergunta 16 | AL1: (PC) Pergunta 16 [Monitoramento] | AM1: (PC) Pergunta 17 | AN1: (PC) Pergunta 17 [Monitoramento] | AO1: (PC) Pergunta 18 | AP1: (PC) Pergunta 18 [Monitoramento] | AQ1: (PC) Pergunta 19 | AR1: (PC) Pergunta 19 [Monitoramento] | AS1: (PC) Pergunta 20 | AT1: (PC) Pergunta 20 [Monitoramento] | AU1: (PC) Pergunta 21 | AV1: (PC) Pergunta 21 [Monitoramento] | AW1: (PC) Pergunta 22 | AX1: (PC) Pergunta 22 [Monitoramento] | AY1: (PC) Pergunta 23 | AZ1: (PC) Pergunta 23 [Monitoramento] | BA1: (PC) Pergunta 24 | BB1: (PC) Pergunta 24 [Monitoramento] | BC1: (PC) Pergunta 25 | BD1: (PC) Pergunta 25 [Monitoramento] | BE1: (PC) Pergunta 26 | BF1: (PC) Pergunta 26 [Monitoramento] | BG1: (PC) Pergunta 27 | BH1: (PC) Pergunta 27 [Monitoramento] | BI1: (PC) Pergunta 28 | BJ1: (PC) Pergunta 28 [Monitoramento] | BK1: (PC) Pergunta 29 | BL1: (PC) Pergunta 29 [Monitoramento] | BM1: (PC) Pergunta 30 | BN1: (PC) Pergunta 30 [Monitoramento] | BO1: (PC) Pergunta 31 | BP1: (PC) Pergunta 31 [Monitoramento] | BQ1: (PC) Pergunta 32 | BR1: (PC) Pergunta 32 [Monitoramento] | BS1: (PC) Não Conformidade ? (Físico) | BT1: (PC) Status Mecânica (Físico) | BU1: (PC) Mecânica Concluída: | BV1: (PC) Status Elétrica (Físico) | BW1: (PC) Elétrica Concluída: | BX1: (PC) Status Checklist (Físico) | BY1: (PC) Checklist Concluído: | BZ1: (CE) Etapa | CA1: (CE) Pergunta 01 | CB1: (CE) Pergunta 01 [Monitoramento] | CC1: (CE) Pergunta 02 | CD1: (CE) Pergunta 02 [Monitoramento] | CE1: (CE) Pergunta 03 | CF1: (CE) Pergunta 03 [Monitoramento] | CG1: (CE) Pergunta 04 | CH1: (CE) Pergunta 04 [Monitoramento] | CI1: (CE) Pergunta 05 | CJ1: (CE) Pergunta 05 [Monitoramento] | CK1: (CE) Pergunta 06 | CL1: (CE) Pergunta 06 [Monitoramento] | CM1: (CE) Pergunta 07 | CN1: (CE) Pergunta 07 [Monitoramento] | CO1: (CE) Pergunta 08 | CP1: (CE) Pergunta 08 [Monitoramento] | CQ1: (CE) Pergunta 09 | CR1: (CE) Pergunta 09 [Monitoramento] | CS1: (CE) Pergunta 10 | CT1: (CE) Pergunta 10 [Monitoramento] | CU1: (CE) Pergunta 11 | CV1: (CE) Pergunta 11 [Monitoramento] | CW1: (CE) Pergunta 12 | CX1: (CE) Pergunta 12 [Monitoramento] | CY1: (CE) Pergunta 13 | CZ1: (CE) Pergunta 13 [Monitoramento] | DA1: (CE) Pergunta 14 | DB1: (CE) Pergunta 14 [Monitoramento] | DC1: (CE) Pergunta 15 | DD1: (CE) Pergunta 15 [Monitoramento] | DE1: (CE) Não Conformidade ? (Físico) | DF1: (CE) Status Mecânica (Físico) | DG1: (CE) Mecânica Concluída: | DH1: (CE) Status Elétrica (Físico) | DI1: (CE) Elétrica Concluída: | DJ1: (CE) Status Checklist (Físico) | DK1: (CE) Checklist Concluído: | DL1: (DF) Etapa | DM1: (DF) Pergunta 01 | DN1: (DF) Pergunta 01 [Monitoramento] | DO1: (DF) Pergunta 02 | DP1: (DF) Pergunta 02 [Monitoramento] | DQ1: (DF) Pergunta 03 | DR1: (DF) Pergunta 03 [Monitoramento] | DS1: (DF) Pergunta 04 | DT1: (DF) Pergunta 04 [Monitoramento] | DU1: (DF) Pergunta 05 | DV1: (DF) Pergunta 05 [Monitoramento] | DW1: (DF) Pergunta 06 | DX1: (DF) Pergunta 06 [Monitoramento] | DY1: (DF) Pergunta 07 | DZ1: (DF) Pergunta 07 [Monitoramento] | EA1: (DF) Pergunta 08 | EB1: (DF) Pergunta 08 [Monitoramento] | EC1: (DF) Pergunta 09 | ED1: (DF) Pergunta 09 [Monitoramento] | EE1: (DF) Pergunta 10 | EF1: (DF) Pergunta 10 [Monitoramento] | EG1: (DF) Pergunta 11 | EH1: (DF) Pergunta 11 [Monitoramento] | EI1: (DF) Não Conformidade ? (Físico) | EJ1: (DF) Status Checklist (Físico) | EK1: (DF) Checklist Concluído: | EL1: (DQ) Etapa | EM1: (DQ) Pergunta 01 | EN1: (DQ) Pergunta 01 [Monitoramento] | EO1: (DQ) Pergunta 02 | EP1: (DQ) Pergunta 02 [Monitoramento] | EQ1: (DQ) Pergunta 03 | ER1: (DQ) Pergunta 03 [Monitoramento] | ES1: (DQ) Pergunta 04 | ET1: (DQ) Pergunta 04 [Monitoramento] | EU1: (DQ) Pergunta 05 | EV1: (DQ) Pergunta 05 [Monitoramento] | EW1: (DQ) Pergunta 06 | EX1: (DQ) Pergunta 06 [Monitoramento] | EY1: (DQ) Pergunta 07 | EZ1: (DQ) Pergunta 07 [Monitoramento] | FA1: (DQ) Pergunta 08 | FB1: (DQ) Pergunta 08 [Monitoramento] | FC1: (DQ) Pergunta 09 | FD1: (DQ) Pergunta 09 [Monitoramento] | FE1: (DQ) Pergunta 10 | FF1: (DQ) Pergunta 10 [Monitoramento] | FG1: (DQ) Pergunta 11 | FH1: (DQ) Pergunta 11 [Monitoramento] | FI1: (DQ) Não Conformidade ? (Físico) | FJ1: (DQ) Status Checklist (Físico) | FK1: (DQ) Checklist Concluído: | FL1: Observação: | FM1: Observação Registrada em: | FN1: Status do Questionário (Físico) | FO1: Status do Questionário Concluído: | FP1: Última atualização: | FQ1: Imagem do Equipamento: | FR1: Imagem do Equipamento Registrada em: | FS1: Imagem da Plaqueta do Motor: | FT1: Imagem da Plaqueta do Motor Registrada em: | FU1: Imagem (Display) | FV1: Imagem Indisponível | FW1: Imagem Indisponível [Monitoramento]
A2: 10&20 - R.P.E | B2: Caldo Prensado | C2: Motor e Bomba | D2: BC-2022 | E2: Bomba Nº1 De Caldo Prensado | F2: Pré-Comissionamento | G2: Conforme | H2: Wesley Soares - 28/01/2026 07:45:45 | I2: Conforme | J2: Bruno Borges - 27/01/2026 11:03:55 | K2: Conforme | L2: Bruno Borges - 27/01/2026 11:03:57 | M2: Conforme | N2: Bruno Borges - 27/01/2026 11:03:59 | O2: Conforme | P2: Bruno Borges - 27/01/2026 11:04:01 | Q2: Conforme | R2: Bruno Borges - 27/01/2026 11:04:03 | S2: Conforme | T2: Bruno Borges - 27/01/2026 11:04:21 | U2: Conforme | V2: Bruno Borges - 10/03/2026 09:48:34 | W2: Conforme | X2: Bruno Borges - 27/01/2026 11:05:02 | Y2: Não Aplicável | Z2: Bruno Borges - 27/01/2026 11:05:05 | AA2: Conforme | AB2: Wesley Soares - 27/01/2026 08:18:11 | AC2: Conforme | AD2: Wesley Soares - 27/01/2026 08:18:19 | AE2: Conforme | AF2: Wesley Soares - 27/01/2026 08:18:24 | AG2: Conforme | AH2: Wesley Soares - 27/01/2026 08:18:28 | AI2: Conforme | AJ2: Wesley Soares - 27/01/2026 08:18:49 | AK2: Conforme | AL2: Wesley Soares - 27/01/2026 08:18:58 | AM2: Não Aplicável | AN2: Bruno Borges - 27/01/2026 10:55:30 | AO2: Não Aplicável | AP2: Bruno Borges - 27/01/2026 10:55:30 | BS2: Não | BT2: Sim | BU2: 46091.409 | BV2: Sim | BW2: 46050.323 | BX2: Sim | BY2: 46091.409 | BZ2: Comissionamento Estático | CA2: Conforme | CB2: Bruno Borges - 10/03/2026 09:48:39 | CC2: Conforme | CD2: Bruno Borges - 10/03/2026 09:48:40 | CE2: Conforme | CF2: Bruno Borges - 10/03/2026 09:48:41 | CG2: Conforme | CH2: Wesley Soares - 16/03/2026 08:32:47 | CI2: Conforme | CJ2: Wesley Soares - 16/03/2026 08:32:49 | CK2: Não Aplicável | CL2: Glaucia Massuia - 16/03/2026 14:31:01 | DE2: Não | DF2: Sim | DG2: 46091.409 | DH2: Sim | DI2: 46097.605 | DJ2: Sim | DK2: 46097.605 | DL2: Dinâmico Frio | DM2: Conforme | DN2: Marcelo Pagioro - 23/03/2026 07:36:23 | DO2: Conforme | DP2: Marcelo Pagioro - 23/03/2026 07:36:25 | DQ2: Conforme | DR2: Marcelo Pagioro - 23/03/2026 07:36:27 | DS2: Conforme | DT2: Marcelo Pagioro - 23/03/2026 07:36:29 | EI2: Não | EJ2: Sim | EK2: 46104.317 | EL2: Dinâmico Quente | EM2: Conforme | EN2: Marcelo Pagioro - 23/03/2026 13:00:31 | EO2: Conforme | EP2: Marcelo Pagioro - 23/03/2026 13:00:32 | EQ2: Conforme | ER2: Marcelo Pagioro - 23/03/2026 13:00:35 | ES2: Conforme | ET2: Marcelo Pagioro - 23/03/2026 13:00:36 | FI2: Não | FJ2: Sim | FK2: 46104.542 | FN2: Feito | FO2: 46104.542 | FP2: Marcelo Pagioro - 23/03/2026 13:00:36 | FQ2: Base de Dados_Images/BC-2022.Imagem do Equipamento-.130419.jpg | FR2: Humberto Luiz - 22/01/2026 10:04:14 | FS2: Base de Dados_Images/BC-2022.Imagem da Plaqueta do Motor-.130500.jpg | FT2: Humberto Luiz - 22/01/2026 10:04:55 | FU2: =FQ2 -> Base de Dados_Images/BC-2022.Imagem do Equipamento-.130419.jpg
A3: 10&20 - R.P.E | B3: Caldo Prensado | C3: Motor e Bomba | D3: BC-2023 | E3: Bomba Nº2 De Caldo Prensado | F3: Pré-Comissionamento | G3: Conforme | H3: Wesley Soares - 28/01/2026 07:45:14 | I3: Conforme | J3: Marcelo Pagioro - 23/03/2026 07:36:43 | K3: Conforme | L3: Marcelo Pagioro - 23/03/2026 07:36:45 | M3: Conforme | N3: Marcelo Pagioro - 23/03/2026 07:36:46 | O3: Conforme | P3: Marcelo Pagioro - 23/03/2026 07:36:49 | Q3: Conforme | R3: Marcelo Pagioro - 23/03/2026 07:36:50 | S3: Conforme | T3: Marcelo Pagioro - 23/03/2026 07:36:52 | U3: Conforme | V3: Marcelo Pagioro - 23/03/2026 07:36:55 | W3: Conforme | X3: Marcelo Pagioro - 23/03/2026 07:36:56 | Y3: Conforme | Z3: Marcelo Pagioro - 23/03/2026 07:36:59 | AA3: Conforme | AB3: Wesley Soares - 27/01/2026 08:25:31 | AC3: Conforme | AD3: Wesley Soares - 27/01/2026 08:25:34 | AE3: Conforme | AF3: Wesley Soares - 27/01/2026 08:25:38 | AG3: Conforme | AH3: Wesley Soares - 27/01/2026 08:25:42 | AI3: Conforme | AJ3: Wesley Soares - 27/01/2026 08:25:45 | AK3: Conforme | AL3: Wesley Soares - 28/01/2026 07:44:46 | AM3: Não Aplicável | AN3: Marcelo Pagioro - 23/03/2026 07:37:08 | AO3: Não Aplicável | AP3: Marcelo Pagioro - 23/03/2026 07:37:11 | BS3: Não | BT3: Sim | BU3: 46104.317 | BV3: Sim | BW3: 46050.323 | BX3: Sim | BY3: 46104.317 | BZ3: Comissionamento Estático | CA3: Conforme | CB3: Marcelo Pagioro - 23/03/2026 07:37:18 | CC3: Conforme | CD3: Marcelo Pagioro - 23/03/2026 07:37:19 | CE3: Conforme | CF3: Marcelo Pagioro - 23/03/2026 07:37:21 | CG3: Conforme | CH3: Marcelo Pagioro - 23/03/2026 07:37:22 | CI3: Conforme | CJ3: Marcelo Pagioro - 23/03/2026 07:37:24 | CK3: Conforme | CL3: Marcelo Pagioro - 23/03/2026 07:37:27 | DE3: Não | DF3: Sim | DG3: 46104.318 | DH3: Sim | DI3: 46104.318 | DJ3: Sim | DK3: 46104.318 | DL3: Dinâmico Frio | DM3: Conforme | DN3: Marcelo Pagioro - 23/03/2026 07:37:34 | DO3: Conforme | DP3: Marcelo Pagioro - 23/03/2026 07:37:35 | DQ3: Conforme | DR3: Marcelo Pagioro - 23/03/2026 07:37:37 | DS3: Conforme | DT3: Marcelo Pagioro - 23/03/2026 07:37:39 | EI3: Não | EJ3: Sim | EK3: 46104.318 | EL3: Dinâmico Quente | EM3: Conforme | EN3: Marcelo Pagioro - 23/03/2026 13:00:48 | EO3: Conforme | EP3: Marcelo Pagioro - 23/03/2026 13:00:56 | EQ3: Conforme | ER3: Marcelo Pagioro - 23/03/2026 13:00:59 | ES3: Conforme | ET3: Marcelo Pagioro - 23/03/2026 13:01:02 | FI3: Não | FJ3: Sim | FK3: 46104.542 | FN3: Feito | FO3: 46104.542 | FP3: Marcelo Pagioro - 23/03/2026 13:01:02 | FQ3: Base de Dados_Images/BC-2023.Imagem do Equipamento-.112503.jpg | FR3: Wesley Soares - 27/01/2026 08:25:06 | FS3: Base de Dados_Images/BC-2023.Imagem da Plaqueta do Motor-.112503.jpg | FT3: Wesley Soares - 27/01/2026 08:25:06 | FU3: =FQ3 -> Base de Dados_Images/BC-2023.Imagem do Equipamento-.112503.jpg
A4: 10&20 - R.P.E | B4: Caldo Prensado | C4: Tanque | D4: TQ-2002 | E4: Tanque De Caldo Prensado | F4: Pré-Comissionamento | G4: Conforme | H4: Bruno Borges - 29/01/2026 08:30:50 | I4: Conforme | J4: Bruno Borges - 29/01/2026 08:30:52 | K4: Conforme | L4: Bruno Borges - 29/01/2026 08:30:54 | M4: Conforme | N4: Bruno Borges - 29/01/2026 08:30:56 | O4: Conforme | P4: Bruno Borges - 29/01/2026 08:30:59 | Q4: Conforme | R4: Bruno Borges - 29/01/2026 08:31:00 | S4: Conforme | T4: Bruno Borges - 29/01/2026 08:31:02 | U4: Não Aplicável | V4: Bruno Borges - 29/01/2026 08:40:27 | W4: Não Aplicável | X4: Bruno Borges - 29/01/2026 08:40:30 | BS4: Não | BT4: Sim | BU4: 46051.355 | BV4: Sim | BW4: 46051.361 | BX4: Sim | BY4: 46051.361 | BZ4: Comissionamento Estático | DE4: Não | DF4: Não Aplica | DH4: Não Aplica | DJ4: Não Aplica | DL4: Dinâmico Frio | DM4: Conforme | DN4: Marcelo Pagioro - 23/03/2026 07:37:48 | DO4: Conforme | DP4: Marcelo Pagioro - 23/03/2026 07:37:49 | EI4: Não | EJ4: Sim | EK4: 46104.318 | EL4: Dinâmico Quente | EM4: Conforme | EN4: Marcelo Pagioro - 23/03/2026 13:01:11 | EO4: Conforme | EP4: Marcelo Pagioro - 23/03/2026 13:01:12 | EQ4: Não Aplicável | ER4: Marcelo Pagioro - 23/03/2026 13:01:25 | ES4: Conforme | ET4: Marcelo Pagioro - 23/03/2026 13:01:29 | FI4: Não | FJ4: Sim | FK4: 46104.543 | FN4: Feito | FO4: 46104.543 | FP4: Marcelo Pagioro - 23/03/2026 13:01:29 | FQ4: Base de Dados_Images/TQ-2002.Imagem do Equipamento-.153725.jpg | FR4: Humberto Luiz - 22/01/2026 12:37:11 | FU4: =FQ4 -> Base de Dados_Images/TQ-2002.Imagem do Equipamento-.153725.jpg
A5: 10&20 - R.P.E | B5: Caldo Prensado | C5: Transmissor | D5: LIT-2023 | E5: Transmissor De Nível Do Tanque De Caldo Prensado | F5: Pré-Comissionamento | G5: Conforme | H5: Bruno Borges - 13/03/2026 12:52:01 | I5: Conforme | J5: Marcos Domingues - 28/02/2026 20:03:44 | K5: Conforme | L5: Marcos Domingues - 28/02/2026 20:03:49 | M5: Conforme | N5: Marcos Domingues - 28/02/2026 20:03:51 | BS5: Não | BT5: Sim | BU5: 46094.536 | BV5: Sim | BW5: 46081.836 | BX5: Sim | BY5: 46094.536 | BZ5: Comissionamento Estático | CA5: Conforme | CB5: Wesley Soares - 16/03/2026 08:34:10 | CC5: Conforme | CD5: Wesley Soares - 16/03/2026 08:34:13 | CE5: Conforme | CF5: Wesley Soares - 16/03/2026 08:34:15 | DE5: Não | DF5: Não Aplica | DH5: Sim | DI5: 46097.357 | DJ5: Sim | DK5: 46097.357 | DL5: Dinâmico Frio | DM5: Conforme | DN5: Marcelo Pagioro - 23/03/2026 07:37:59 | DO5: Conforme | DP5: Marcelo Pagioro - 23/03/2026 07:38:03 | EI5: Não | EJ5: Sim | EK5: 46104.318 | EL5: Dinâmico Quente | EM5: Conforme | EN5: Glaucia Massuia - 23/03/2026 13:02:15 | EO5: Conforme | EP5: Glaucia Massuia - 23/03/2026 13:02:17 | FI5: Não | FJ5: Sim | FK5: 46104.543 | FN5: Feito | FO5: 46104.543 | FP5: Glaucia Massuia - 23/03/2026 13:02:17 | FQ5: Base de Dados_Images/LIT-2023.Imagem do Equipamento-.085426.jpg | FR5: Marcos Domingues - 01/03/2026 05:54:20 | FU5: =FQ5 -> Base de Dados_Images/LIT-2023.Imagem do Equipamento-.085426.jpg
A6: 10&20 - R.P.E | B6: Desaguador | C6: Esteira Metálica | D6: EA-2001 | E6: Esteira Metálica Do Terno Desaguador | F6: Pré-Comissionamento | G6: Conforme | H6: Bruno Borges - 13/03/2026 12:53:13 | I6: Conforme | J6: Bruno Borges - 13/03/2026 12:53:16 | K6: Conforme | L6: Bruno Borges - 13/03/2026 12:53:18 | M6: Conforme | N6: Bruno Borges - 13/03/2026 12:53:19 | O6: Conforme | P6: Bruno Borges - 13/03/2026 12:53:21 | Q6: Conforme | R6: Bruno Borges - 13/03/2026 12:53:23 | S6: Conforme | T6: Bruno Borges - 13/03/2026 12:53:25 | U6: Conforme | V6: Bruno Borges - 13/03/2026 12:53:34 | W6: Conforme | X6: Bruno Borges - 13/03/2026 12:53:36 | Y6: Conforme | Z6: Bruno Borges - 13/03/2026 12:53:38 | AA6: Conforme | AB6: Bruno Borges - 13/03/2026 12:53:40 | AC6: Conforme | AD6: Bruno Borges - 13/03/2026 12:53:48 | AE6: Conforme | AF6: Bruno Borges - 13/03/2026 12:53:50 | AG6: Conforme | AH6: Bruno Borges - 13/03/2026 12:53:51 | AI6: Conforme | AJ6: Marcos Domingues - 13/03/2026 09:45:27 | AK6: Conforme | AL6: Marcos Domingues - 13/03/2026 09:45:27 | AM6: Conforme | AN6: Marcos Domingues - 13/03/2026 09:45:28 | AO6: Conforme | AP6: Marcos Domingues - 13/03/2026 09:45:31 | AQ6: Conforme | AR6: Marcos Domingues - 13/03/2026 09:45:30 | AS6: Conforme | AT6: Marcos Domingues - 13/03/2026 09:45:32 | AU6: Conforme | AV6: Júlio Cezar Alves Santana - 18/03/2026 10:35:20 | AW6: Conforme | AX6: Júlio Cezar Alves Santana - 18/03/2026 10:35:45 | AY6: Conforme | AZ6: Júlio Cezar Alves Santana - 18/03/2026 10:35:47 | BA6: Conforme | BB6: Júlio Cezar Alves Santana - 18/03/2026 10:35:50 | BC6: Não Aplicável | BD6: Júlio Cezar Alves Santana - 18/03/2026 10:37:06 | BE6: Conforme | BF6: Júlio Cezar Alves Santana - 18/03/2026 10:37:10 | BG6: Conforme | BH6: Júlio Cezar Alves Santana - 18/03/2026 10:37:11 | BI6: Conforme | BJ6: Júlio Cezar Alves Santana - 18/03/2026 10:37:14 | BK6: Não Aplicável | BL6: Júlio Cezar Alves Santana - 18/03/2026 10:37:17 | BM6: Conforme | BN6: Júlio Cezar Alves Santana - 18/03/2026 10:37:20 | BO6: Conforme | BP6: Júlio Cezar Alves Santana - 18/03/2026 10:37:23 | BS6: Não | BT6: Sim | BU6: 46094.537 | BV6: Sim | BW6: 46094.407 | BX6: Sim | BY6: 46099.443 | BZ6: Comissionamento Estático | CA6: Conforme | CB6: Bruno Borges - 13/03/2026 12:54:07 | CC6: Conforme | CD6: Wesley Soares - 16/03/2026 08:35:00 | CE6: Conforme | CF6: Wesley Soares - 16/03/2026 08:35:02 | CG6: Conforme | CH6: Wesley Soares - 16/03/2026 08:35:13 | DE6: Não | DF6: Sim | DG6: 46094.538 | DH6: Sim | DI6: 46097.358 | DJ6: Sim | DK6: 46097.358 | DL6: Dinâmico Frio | DM6: Conforme | DN6: Wesley Soares - 16/03/2026 08:35:20 | DO6: Conforme | DP6: Wesley Soares - 16/03/2026 08:35:21 | DQ6: Conforme | DR6: Humberto Luiz - 17/03/2026 09:00:31 | DS6: Conforme | DT6: Wesley Soares - 16/03/2026 08:35:34 | DU6: Não Aplicável | DV6: Humberto Luiz - 17/03/2026 08:51:47 | DW6: Conforme | DX6: Wesley Soares - 16/03/2026 08:35:46 | DY6: Não Aplicável | DZ6: Júlio Cezar Alves Santana - 19/03/2026 07:17:14 | EA6: Não Aplicável | EB6: Júlio Cezar Alves Santana - 19/03/2026 07:17:16 | EI6: Não | EJ6: Sim | EK6: 46100.304 | EL6: Dinâmico Quente | EM6: Conforme | EN6: Marcelo Pagioro - 23/03/2026 10:52:03 | EO6: Conforme | EP6: Marcelo Pagioro - 23/03/2026 10:52:04 | EQ6: Conforme | ER6: Marcelo Pagioro - 23/03/2026 10:52:06 | FI6: Não | FJ6: Sim | FK6: 46104.453 | FN6: Feito | FO6: 46104.453 | FP6: Marcelo Pagioro - 23/03/2026 10:52:06 | FQ6: Base de Dados_Images/EA-2001.Imagem do Equipamento-.124005.jpg | FR6: Marcos Domingues - 13/03/2026 09:39:58 | FU6: =FQ6 -> Base de Dados_Images/EA-2001.Imagem do Equipamento-.124005.jpg
A7: 10&20 - R.P.E | B7: Desaguador | C7: Motor e Bomba | D7: MO-045-01 | E7: Bomba Sistema Hidraulico Do Terno Desaguador | F7: Pré-Comissionamento | G7: Conforme | H7: Wesley Soares - 27/01/2026 08:29:50 | I7: Conforme | J7: Bruno Borges - 27/01/2026 10:49:02 | K7: Conforme | L7: Bruno Borges - 27/01/2026 10:49:04 | M7: Conforme | N7: Bruno Borges - 27/01/2026 10:49:06 | O7: Conforme | P7: Bruno Borges - 27/01/2026 10:49:08 | Q7: Conforme | R7: Bruno Borges - 27/01/2026 10:49:10 | S7: Conforme | T7: Bruno Borges - 27/01/2026 10:49:12 | U7: Conforme | V7: Bruno Borges - 27/01/2026 10:49:16 | W7: Conforme | X7: Bruno Borges - 27/01/2026 10:49:37 | Y7: Não Aplicável | Z7: Bruno Borges - 27/01/2026 10:49:34 | AA7: Conforme | AB7: Wesley Soares - 27/01/2026 08:30:00 | AC7: Conforme | AD7: Wesley Soares - 27/01/2026 08:30:02 | AE7: Conforme | AF7: Wesley Soares - 27/01/2026 08:30:04 | AG7: Conforme | AH7: Wesley Soares - 27/01/2026 08:30:12 | AI7: Conforme | AJ7: Wesley Soares - 27/01/2026 08:53:37 | AK7: Conforme | AL7: Wesley Soares - 27/01/2026 08:41:58 | AM7: Não Aplicável | AN7: Luiz Augusto - 03/02/2026 11:53:32 | AO7: Não Aplicável | AP7: Luiz Augusto - 03/02/2026 11:57:15 | BS7: Não | BT7: Sim | BU7: 46049.451 | BV7: Sim | BW7: 46049.371 | BX7: Sim | BY7: 46056.498 | BZ7: Comissionamento Estático | CA7: Conforme | CB7: Bruno Borges - 10/03/2026 09:48:56 | CC7: Não Aplicável | CD7: Alexandre Fernandes - 19/02/2026 08:49:38 | CE7: Não Aplicável | CF7: Alexandre Fernandes - 19/02/2026 08:51:39 | CG7: Não Aplicável | CH7: Wesley Soares - 19/02/2026 16:27:22 | CI7: Conforme | CJ7: Wesley Soares - 19/02/2026 16:27:28 | CK7: Não Aplicável | CL7: Wesley Soares - 19/02/2026 16:27:43 | DE7: Não | DF7: Sim | DG7: 46091.409 | DH7: Sim | DI7: 46072.686 | DJ7: Sim | DK7: 46091.409 | DL7: Dinâmico Frio | DM7: Conforme | DN7: Wesley Soares - 16/03/2026 08:36:56 | DO7: Conforme | DP7: Wesley Soares - 16/03/2026 08:36:58 | DQ7: Conforme | DR7: Wesley Soares - 16/03/2026 08:37:00 | DS7: Conforme | DT7: Wesley Soares - 16/03/2026 08:37:02 | EI7: Não | EJ7: Sim | EK7: 46097.359 | EL7: Dinâmico Quente | EM7: Conforme | EN7: Glaucia Massuia - 23/03/2026 10:57:27 | EO7: Conforme | EP7: Marcelo Pagioro - 23/03/2026 10:52:49 | EQ7: Conforme | ER7: Marcelo Pagioro - 23/03/2026 10:52:50 | ES7: Conforme | ET7: Marcelo Pagioro - 23/03/2026 10:52:53 | FI7: Não | FJ7: Sim | FK7: 46104.457 | FN7: Feito | FO7: 46104.457 | FP7: Glaucia Massuia - 23/03/2026 10:57:27 | FQ7: Base de Dados_Images/MO-045-01.Imagem do Equipamento-.144758.jpg | FR7: Humberto Luiz - 22/01/2026 11:47:35 | FS7: Base de Dados_Images/MO-045-01.Imagem da Plaqueta do Motor-.144758.jpg | FT7: Humberto Luiz - 22/01/2026 11:47:52 | FU7: =FQ7 -> Base de Dados_Images/MO-045-01.Imagem do Equipamento-.144758.jpg
A8: 10&20 - R.P.E | B8: Desaguador | C8: Motor e Bomba | D8: MO-046-01 | E8: Bomba De Lubrificação Do Rolo Inferior De Terno Desaguador | F8: Pré-Comissionamento | G8: Conforme | H8: Wesley Soares - 27/01/2026 08:55:42 | I8: Conforme | J8: Bruno Borges - 27/01/2026 10:49:52 | K8: Conforme | L8: Bruno Borges - 27/01/2026 10:49:54 | M8: Conforme | N8: Bruno Borges - 27/01/2026 10:49:55 | O8: Conforme | P8: Bruno Borges - 27/01/2026 10:49:59 | Q8: Conforme | R8: Bruno Borges - 27/01/2026 10:50:20 | S8: Conforme | T8: Bruno Borges - 27/01/2026 10:50:22 | U8: Conforme | V8: Bruno Borges - 27/01/2026 10:50:23 | W8: Conforme | X8: Bruno Borges - 27/01/2026 10:50:27 | Y8: Conforme | Z8: Bruno Borges - 27/01/2026 10:50:29 | AA8: Conforme | AB8: Wesley Soares - 27/01/2026 08:55:50 | AC8: Conforme | AD8: Wesley Soares - 27/01/2026 08:55:53 | AE8: Conforme | AF8: Wesley Soares - 27/01/2026 08:55:55 | AG8: Conforme | AH8: Wesley Soares - 27/01/2026 08:56:00 | AI8: Conforme | AJ8: Wesley Soares - 27/01/2026 08:56:06 | AK8: Conforme | AL8: Wesley Soares - 27/01/2026 08:56:10 | AM8: Não Aplicável | AN8: Luiz Augusto - 03/02/2026 11:54:09 | AO8: Não Aplicável | AP8: Luiz Augusto - 03/02/2026 11:57:28 | BS8: Não | BT8: Sim | BU8: 46049.452 | BV8: Sim | BW8: 46049.372 | BX8: Sim | BY8: 46056.498 | BZ8: Comissionamento Estático | CA8: Conforme | CB8: Alexandre Fernandes - 19/02/2026 08:53:24 | CC8: Não Aplicável | CD8: Alexandre Fernandes - 19/02/2026 08:54:21 | CE8: Conforme | CF8: Alexandre Fernandes - 19/02/2026 08:55:27 | CG8: Não Aplicável | CH8: Wesley Soares - 19/02/2026 16:28:01 | CI8: Conforme | CJ8: Wesley Soares - 19/02/2026 16:28:04 | CK8: Não Aplicável | CL8: Wesley Soares - 19/02/2026 16:28:07 | DE8: Não | DF8: Sim | DG8: 46072.372 | DH8: Sim | DI8: 46072.686 | DJ8: Sim | DK8: 46072.686 | DL8: Dinâmico Frio | DM8: Não Aplicável | DN8: Humberto Luiz - 17/03/2026 09:22:41 | DO8: Não Aplicável | DP8: Humberto Luiz - 17/03/2026 09:22:45 | DQ8: Conforme | DR8: Humberto Luiz - 17/03/2026 09:22:25 | DS8: Conforme | DT8: Humberto Luiz - 17/03/2026 09:22:28 | EI8: Não | EJ8: Sim | EK8: 46098.391 | EL8: Dinâmico Quente | EM8: Conforme | EN8: Glaucia Massuia - 23/03/2026 10:57:10 | EO8: Conforme | EP8: Marcelo Pagioro - 23/03/2026 10:54:26 | EQ8: Conforme | ER8: Glaucia Massuia - 23/03/2026 10:57:12 | ES8: Conforme | ET8: Marcelo Pagioro - 23/03/2026 10:54:07 | FI8: Não | FJ8: Sim | FK8: 46104.456 | FN8: Feito | FO8: 46104.456 | FP8: Glaucia Massuia - 23/03/2026 10:57:12 | FQ8: Base de Dados_Images/MO-046-01.Imagem do Equipamento-.145204.jpg | FR8: Humberto Luiz - 22/01/2026 11:51:44 | FS8: Base de Dados_Images/MO-046-01.Imagem da Plaqueta do Motor-.145204.jpg | FT8: Humberto Luiz - 22/01/2026 11:51:58 | FU8: =FQ8 -> Base de Dados_Images/MO-046-01.Imagem do Equipamento-.145204.jpg
A9: 10&20 - R.P.E | B9: Desaguador | C9: Motor e Bomba | D9: MO-047-01 | E9: Bomba De Lubrificação Do Rolo Superior De Terno Desaguador | F9: Pré-Comissionamento | G9: Conforme | H9: Wesley Soares - 27/01/2026 08:56:26 | I9: Conforme | J9: Bruno Borges - 02/02/2026 08:14:18 | K9: Conforme | L9: Bruno Borges - 02/02/2026 08:14:20 | M9: Conforme | N9: Bruno Borges - 02/02/2026 08:14:23 | O9: Conforme | P9: Bruno Borges - 02/02/2026 08:14:24 | Q9: Conforme | R9: Bruno Borges - 02/02/2026 08:14:26 | S9: Conforme | T9: Bruno Borges - 02/02/2026 08:14:26 | U9: Conforme | V9: Bruno Borges - 02/02/2026 08:14:29 | W9: Conforme | X9: Bruno Borges - 02/02/2026 08:14:29 | Y9: Conforme | Z9: Bruno Borges - 02/02/2026 08:14:32 | AA9: Conforme | AB9: Wesley Soares - 27/01/2026 08:56:38 | AC9: Conforme | AD9: Wesley Soares - 27/01/2026 08:56:41 | AE9: Conforme | AF9: Wesley Soares - 27/01/2026 08:56:43 | AG9: Conforme | AH9: Wesley Soares - 27/01/2026 08:56:45 | AI9: Conforme | AJ9: Wesley Soares - 27/01/2026 08:56:47 | AK9: Conforme | AL9: Wesley Soares - 27/01/2026 08:56:48 | AM9: Não Aplicável | AN9: Bruno Borges - 02/02/2026 08:16:28 | AO9: Não Aplicável | AP9: Bruno Borges - 02/02/2026 08:16:29 | BS9: Não | BT9: Sim | BU9: 46055.343 | BV9: Sim | BW9: 46049.373 | BX9: Sim | BY9: 46055.345 | BZ9: Comissionamento Estático | CA9: Conforme | CB9: Alexandre Fernandes - 19/02/2026 08:56:37 | CC9: Não Aplicável | CD9: Alexandre Fernandes - 19/02/2026 08:56:49 | CE9: Conforme | CF9: Alexandre Fernandes - 19/02/2026 08:57:05 | CG9: Não Aplicável | CH9: Wesley Soares - 19/02/2026 16:28:22 | CI9: Conforme | CJ9: Wesley Soares - 19/02/2026 16:28:25 | CK9: Não Aplicável | CL9: Wesley Soares - 19/02/2026 16:28:29 | DE9: Não | DF9: Sim | DG9: 46072.373 | DH9: Sim | DI9: 46072.686 | DJ9: Sim | DK9: 46072.686 | DL9: Dinâmico Frio | DM9: Conforme | DN9: Wesley Soares - 16/03/2026 08:37:11 | DO9: Conforme | DP9: Wesley Soares - 16/03/2026 08:37:12 | DQ9: Conforme | DR9: Wesley Soares - 16/03/2026 08:37:13 | DS9: Conforme | DT9: Wesley Soares - 16/03/2026 08:37:15 | EI9: Não | EJ9: Sim | EK9: 46097.359 | EL9: Dinâmico Quente | EM9: Conforme | EN9: Marcelo Pagioro - 23/03/2026 10:56:11 | EO9: Conforme | EP9: Marcelo Pagioro - 23/03/2026 10:56:13 | EQ9: Conforme | ER9: Marcelo Pagioro - 23/03/2026 10:56:15 | ES9: Conforme | ET9: Marcelo Pagioro - 23/03/2026 10:56:18 | FI9: Não | FJ9: Sim | FK9: 46104.456 | FN9: Feito | FO9: 46104.456 | FP9: Marcelo Pagioro - 23/03/2026 10:56:18 | FQ9: Base de Dados_Images/MO-047-01.Imagem do Equipamento-.145331.jpg | FR9: Humberto Luiz - 22/01/2026 11:52:57 | FS9: Base de Dados_Images/MO-047-01.Imagem da Plaqueta do Motor-.145331.jpg | FT9: Humberto Luiz - 22/01/2026 11:53:26 | FU9: =FQ9 -> Base de Dados_Images/MO-047-01.Imagem do Equipamento-.145331.jpg
A10: 10&20 - R.P.E | B10: Desaguador | C10: Rolo Desaguador | D10: TM-2001 | E10: Terno Desaguador | F10: Pré-Comissionamento | G10: Conforme | H10: Bruno Borges - 02/02/2026 08:16:53 | I10: Conforme | J10: Bruno Borges - 02/02/2026 08:16:54 | K10: Conforme | L10: Bruno Borges - 02/02/2026 08:16:55 | M10: Conforme | N10: Bruno Borges - 02/02/2026 08:16:57 | O10: Conforme | P10: Bruno Borges - 02/02/2026 08:16:59 | Q10: Conforme | R10: Bruno Borges - 02/02/2026 08:17:01 | S10: Conforme | T10: Bruno Borges - 02/02/2026 08:17:02 | U10: Conforme | V10: Bruno Borges - 02/02/2026 08:17:05 | W10: Conforme | X10: Bruno Borges - 02/02/2026 08:17:06 | Y10: Conforme | Z10: Bruno Borges - 02/02/2026 08:17:09 | AA10: Conforme | AB10: Bruno Borges - 02/02/2026 08:17:10 | AC10: Conforme | AD10: Bruno Borges - 02/02/2026 08:17:13 | AE10: Conforme | AF10: Bruno Borges - 02/02/2026 08:17:18 | AG10: Conforme | AH10: Bruno Borges - 02/02/2026 08:17:20 | AI10: Conforme | AJ10: Bruno Borges - 02/02/2026 08:17:22 | AK10: Conforme | AL10: Bruno Borges - 02/02/2026 08:17:24 | AM10: Conforme | AN10: Wesley Soares - 27/01/2026 08:57:58 | AO10: Conforme | AP10: Wesley Soares - 27/01/2026 08:58:02 | AQ10: Conforme | AR10: Wesley Soares - 27/01/2026 08:58:06 | AS10: Conforme | AT10: Wesley Soares - 27/01/2026 08:58:08 | AU10: Conforme | AV10: Wesley Soares - 27/01/2026 08:58:12 | AW10: Conforme | AX10: Wesley Soares - 27/01/2026 08:58:15 | BS10: Não | BT10: Sim | BU10: 46055.345 | BV10: Sim | BW10: 46049.374 | BX10: Sim | BY10: 46055.345 | BZ10: Comissionamento Estático | CA10: Conforme | CB10: Alexandre Fernandes - 19/02/2026 08:58:51 | CC10: Conforme | CD10: Wesley Soares - 19/02/2026 16:28:52 | CE10: Conforme | CF10: Wesley Soares - 19/02/2026 16:28:55 | CG10: Não Aplicável | CH10: Wesley Soares - 19/02/2026 16:29:05 | DE10: Não | DF10: Sim | DG10: 46072.374 | DH10: Sim | DI10: 46072.687 | DJ10: Sim | DK10: 46072.687 | DL10: Dinâmico Frio | DM10: Conforme | DN10: Glaucia Massuia - 19/03/2026 14:25:14 | DO10: Conforme | DP10: Glaucia Massuia - 19/03/2026 14:25:15 | DQ10: Conforme | DR10: Glaucia Massuia - 19/03/2026 14:25:15 | DS10: Conforme | DT10: Glaucia Massuia - 19/03/2026 14:25:17 | DU10: Não Aplicável | DV10: Glaucia Massuia - 19/03/2026 14:25:25 | DW10: Conforme | DX10: Glaucia Massuia - 19/03/2026 14:25:20 | EI10: Não | EJ10: Sim | EK10: 46100.601 | EL10: Dinâmico Quente | FI10: Não | FJ10: Não Aplica | FN10: Feito | FO10: 46100.601 | FP10: Glaucia Massuia - 19/03/2026 14:25:25 | FQ10: Base de Dados_Images/TM-2001.Imagem do Equipamento-.150156.jpg | FR10: Humberto Luiz - 22/01/2026 12:01:51 | FU10: =FQ10 -> Base de Dados_Images/TM-2001.Imagem do Equipamento-.150156.jpg
A11: 10&20 - R.P.E | B11: Desaguador | C11: Rolo Desaguador | D11: TM-2002 | E11: Rolo Superior Do Terno Desaguador | F11: Pré-Comissionamento | G11: Conforme | H11: Bruno Borges - 02/02/2026 08:17:33 | I11: Conforme | J11: Bruno Borges - 02/02/2026 08:17:37 | K11: Conforme | L11: Bruno Borges - 02/02/2026 08:17:38 | M11: Conforme | N11: Bruno Borges - 02/02/2026 08:17:42 | O11: Conforme | P11: Bruno Borges - 02/02/2026 08:17:43 | Q11: Conforme | R11: Bruno Borges - 02/02/2026 08:17:45 | S11: Conforme | T11: Bruno Borges - 02/02/2026 08:17:45 | U11: Conforme | V11: Bruno Borges - 02/02/2026 08:17:48 | W11: Conforme | X11: Bruno Borges - 02/02/2026 08:17:48 | Y11: Conforme | Z11: Bruno Borges - 02/02/2026 08:17:49 | AA11: Conforme | AB11: Bruno Borges - 02/02/2026 08:17:56 | AC11: Conforme | AD11: Bruno Borges - 02/02/2026 08:17:56 | AE11: Conforme | AF11: Bruno Borges - 02/02/2026 08:17:57 | AG11: Conforme | AH11: Bruno Borges - 02/02/2026 08:18:10 | AI11: Conforme | AJ11: Bruno Borges - 02/02/2026 08:18:11 | AK11: Conforme | AL11: Bruno Borges - 02/02/2026 08:18:14 | AM11: Conforme | AN11: Wesley Soares - 27/01/2026 08:58:49 | AO11: Conforme | AP11: Wesley Soares - 27/01/2026 08:58:52 | AQ11: Conforme | AR11: Wesley Soares - 27/01/2026 08:58:54 | AS11: Conforme | AT11: Wesley Soares - 27/01/2026 08:58:57 | AU11: Conforme | AV11: Wesley Soares - 27/01/2026 08:58:59 | AW11: Conforme | AX11: Wesley Soares - 27/01/2026 08:59:01 | BS11: Não | BT11: Sim | BU11: 46055.346 | BV11: Sim | BW11: 46049.374 | BX11: Sim | BY11: 46055.346 | BZ11: Comissionamento Estático | CA11: Conforme | CB11: Alexandre Fernandes - 19/02/2026 08:59:39 | CC11: Conforme | CD11: Wesley Soares - 19/02/2026 16:29:23 | CE11: Conforme | CF11: Wesley Soares - 19/02/2026 16:29:25 | CG11: Não Aplicável | CH11: Wesley Soares - 19/02/2026 16:29:27 | DE11: Não | DF11: Sim | DG11: 46072.375 | DH11: Sim | DI11: 46072.687 | DJ11: Sim | DK11: 46072.687 | DL11: Dinâmico Frio | DM11: Conforme | DN11: Glaucia Massuia - 19/03/2026 14:26:13 | DO11: Conforme | DP11: Glaucia Massuia - 19/03/2026 14:25:50 | DQ11: Conforme | DR11: Glaucia Massuia - 19/03/2026 14:25:50 | DS11: Conforme | DT11: Glaucia Massuia - 19/03/2026 14:25:49 | DU11: Não Aplicável | DV11: Glaucia Massuia - 19/03/2026 14:25:48 | DW11: Conforme | DX11: Glaucia Massuia - 19/03/2026 14:25:49 | EI11: Não | EJ11: Sim | EK11: 46100.602 | EL11: Dinâmico Quente | FI11: Não | FJ11: Não Aplica | FN11: Feito | FO11: 46100.602 | FP11: Glaucia Massuia - 19/03/2026 14:26:13 | FQ11: Base de Dados_Images/TM-2002.Imagem do Equipamento-.145519.jpg | FR11: Humberto Luiz - 22/01/2026 11:55:11 | FU11: =FQ11 -> Base de Dados_Images/TM-2002.Imagem do Equipamento-.145519.jpg
A12: 10&20 - R.P.E | B12: Desaguador | C12: Rolo Desaguador | D12: TM-2003 | E12: Rolo Inferior Do Terno Desaguador | F12: Pré-Comissionamento | G12: Conforme | H12: Bruno Borges - 02/02/2026 08:18:22 | I12: Conforme | J12: Bruno Borges - 02/02/2026 08:18:23 | K12: Conforme | L12: Bruno Borges - 02/02/2026 08:18:23 | M12: Conforme | N12: Bruno Borges - 02/02/2026 08:18:25 | O12: Conforme | P12: Bruno Borges - 02/02/2026 08:18:26 | Q12: Conforme | R12: Bruno Borges - 02/02/2026 08:18:28 | S12: Conforme | T12: Bruno Borges - 02/02/2026 08:18:28 | U12: Conforme | V12: Bruno Borges - 02/02/2026 08:18:30 | W12: Conforme | X12: Bruno Borges - 02/02/2026 08:18:30 | Y12: Conforme | Z12: Bruno Borges - 02/02/2026 08:18:32 | AA12: Conforme | AB12: Bruno Borges - 02/02/2026 08:18:33 | AC12: Conforme | AD12: Bruno Borges - 02/02/2026 08:18:35 | AE12: Conforme | AF12: Bruno Borges - 02/02/2026 08:18:36 | AG12: Conforme | AH12: Bruno Borges - 02/02/2026 08:18:38 | AI12: Conforme | AJ12: Bruno Borges - 02/02/2026 08:18:38 | AK12: Conforme | AL12: Bruno Borges - 02/02/2026 08:18:40 | AM12: Conforme | AN12: Wesley Soares - 27/01/2026 08:59:36 | AO12: Conforme | AP12: Wesley Soares - 27/01/2026 08:59:38 | AQ12: Conforme | AR12: Wesley Soares - 27/01/2026 08:59:39 | AS12: Conforme | AT12: Wesley Soares - 27/01/2026 08:59:41 | AU12: Conforme | AV12: Wesley Soares - 27/01/2026 08:59:44 | AW12: Conforme | AX12: Wesley Soares - 27/01/2026 08:59:45 | BS12: Não | BT12: Sim | BU12: 46055.346 | BV12: Sim | BW12: 46049.375 | BX12: Sim | BY12: 46055.346 | BZ12: Comissionamento Estático | CA12: Conforme | CB12: Alexandre Fernandes - 19/02/2026 09:00:26 | CC12: Conforme | CD12: Wesley Soares - 19/02/2026 16:29:41 | CE12: Conforme | CF12: Wesley Soares - 19/02/2026 16:29:44 | CG12: Não Aplicável | CH12: Wesley Soares - 19/02/2026 16:29:46 | DE12: Não | DF12: Sim | DG12: 46072.375 | DH12: Sim | DI12: 46072.687 | DJ12: Sim | DK12: 46072.687 | DL12: Dinâmico Frio | DM12: Conforme | DN12: Glaucia Massuia - 19/03/2026 14:26:19 | DO12: Conforme | DP12: Glaucia Massuia - 19/03/2026 14:26:06 | DQ12: Conforme | DR12: Glaucia Massuia - 19/03/2026 14:26:05 | DS12: Conforme | DT12: Glaucia Massuia - 19/03/2026 14:26:05 | DU12: Não Aplicável | DV12: Glaucia Massuia - 19/03/2026 14:26:03 | DW12: Conforme | DX12: Glaucia Massuia - 19/03/2026 14:26:04 | EI12: Não | EJ12: Sim | EK12: 46100.602 | EL12: Dinâmico Quente | FI12: Não | FJ12: Não Aplica | FN12: Feito | FO12: 46100.602 | FP12: Glaucia Massuia - 19/03/2026 14:26:19 | FQ12: Base de Dados_Images/TM-2003.Imagem do Equipamento-.145620.jpg | FR12: Humberto Luiz - 22/01/2026 11:56:14 | FU12: =FQ12 -> Base de Dados_Images/TM-2003.Imagem do Equipamento-.145620.jpg
A13: 10&20 - R.P.E | B13: Desaguador | C13: Transmissor | D13: LIT-9002-15 | E13: Transmissor De Nível Do Chute Donelly Do Terno Desaguador | F13: Pré-Comissionamento | G13: Conforme | H13: Bruno Borges - 02/02/2026 08:18:47 | I13: Conforme | J13: Wesley Soares - 11/02/2026 11:30:09 | K13: Conforme | L13: Wesley Soares - 11/02/2026 11:30:09 | M13: Conforme | N13: Wesley Soares - 11/02/2026 11:30:10 | BS13: Não | BT13: Sim | BU13: 46055.346 | BV13: Sim | BW13: 46064.479 | BX13: Sim | BY13: 46064.479 | BZ13: Comissionamento Estático | CA13: Conforme | CB13: Wesley Soares - 16/03/2026 08:37:22 | CC13: Conforme | CD13: Wesley Soares - 16/03/2026 08:37:24 | CE13: Conforme | CF13: Wesley Soares - 16/03/2026 08:37:26 | DE13: Não | DF13: Não Aplica | DH13: Sim | DI13: 46097.359 | DJ13: Sim | DK13: 46097.359 | DL13: Dinâmico Frio | DM13: Conforme | DN13: Wesley Soares - 16/03/2026 08:37:30 | DO13: Conforme | DP13: Wesley Soares - 16/03/2026 08:37:31 | EI13: Não | EJ13: Sim | EK13: 46097.359 | EL13: Dinâmico Quente | EM13: Conforme | EN13: Marcelo Pagioro - 23/03/2026 10:56:27 | EO13: Conforme | EP13: Marcelo Pagioro - 23/03/2026 10:56:28 | FI13: Não | FJ13: Sim | FK13: 46104.456 | FN13: Feito | FO13: 46104.456 | FP13: Marcelo Pagioro - 23/03/2026 10:56:28 | FQ13: Base de Dados_Images/LIT-9002-15.Imagem do Equipamento-.145756.jpg | FR13: Humberto Luiz - 22/01/2026 11:57:51 | FU13: =FQ13 -> Base de Dados_Images/LIT-9002-15.Imagem do Equipamento-.145756.jpg
A14: 10&20 - R.P.E | B14: Desaguador | C14: Transmissor | D14: ZSH-9002-15 | E14: Chave De Nível Alto Do Terno Desaguador | F14: Pré-Comissionamento | G14: Conforme | H14: Bruno Borges - 02/02/2026 08:18:59 | I14: Conforme | J14: Wesley Soares - 11/02/2026 11:30:23 | K14: Conforme | L14: Wesley Soares - 11/02/2026 11:30:24 | M14: Conforme | N14: Wesley Soares - 11/02/2026 11:30:24 | BS14: Não | BT14: Sim | BU14: 46055.347 | BV14: Sim | BW14: 46064.479 | BX14: Sim | BY14: 46064.479 | BZ14: Comissionamento Estático | CA14: Conforme | CB14: Wesley Soares - 16/03/2026 08:37:38 | CC14: Conforme | CD14: Wesley Soares - 16/03/2026 08:37:39 | CE14: Conforme | CF14: Wesley Soares - 16/03/2026 08:37:40 | DE14: Não | DF14: Não Aplica | DH14: Sim | DI14: 46097.359 | DJ14: Sim | DK14: 46097.359 | DL14: Dinâmico Frio | DM14: Conforme | DN14: Wesley Soares - 16/03/2026 08:37:44 | DO14: Conforme | DP14: Wesley Soares - 16/03/2026 08:37:45 | EI14: Não | EJ14: Sim | EK14: 46097.36 | EL14: Dinâmico Quente | EM14: Conforme | EN14: Marcelo Pagioro - 23/03/2026 10:56:52 | EO14: Conforme | EP14: Marcelo Pagioro - 23/03/2026 10:56:54 | FI14: Não | FJ14: Sim | FK14: 46104.456 | FN14: Feito | FO14: 46104.456 | FP14: Marcelo Pagioro - 23/03/2026 10:56:54 | FQ14: Base de Dados_Images/ZSH-9002-15.Imagem do Equipamento-.145849.jpg | FR14: Humberto Luiz - 22/01/2026 11:58:42 | FU14: =FQ14 -> Base de Dados_Images/ZSH-9002-15.Imagem do Equipamento-.145849.jpg
A15: 10&20 - R.P.E | B15: Desfibrador | C15: Desfibrador/Picador | D15: DE-2001 | E15: Desfibrador | F15: Pré-Comissionamento | G15: Conforme | H15: Bruno Borges - 04/03/2026 07:49:13 | I15: Conforme | J15: Bruno Borges - 04/03/2026 07:49:15 | K15: Conforme | L15: Bruno Borges - 04/03/2026 07:49:16 | M15: Conforme | N15: Bruno Borges - 04/03/2026 07:49:24 | O15: Não Aplicável | P15: Bruno Borges - 04/03/2026 07:49:44 | Q15: Não Aplicável | R15: Bruno Borges - 04/03/2026 07:49:43 | S15: Conforme | T15: Bruno Borges - 04/03/2026 07:49:49 | U15: Conforme | V15: Bruno Borges - 04/03/2026 07:49:52 | W15: Conforme | X15: Bruno Borges - 04/03/2026 07:49:54 | Y15: Conforme | Z15: Marcos Domingues - 03/03/2026 08:51:21 | AA15: Conforme | AB15: Marcos Domingues - 03/03/2026 08:51:28 | AC15: Conforme | AD15: Marcos Domingues - 03/03/2026 08:51:28 | AE15: Conforme | AF15: Marcos Domingues - 03/03/2026 08:51:31 | AG15: Não Aplicável | AH15: Marcos Domingues - 03/03/2026 08:51:57 | AI15: Conforme | AJ15: Marcos Domingues - 03/03/2026 08:51:58 | AK15: Conforme | AL15: Júlio Cezar Alves Santana - 13/03/2026 14:04:43 | AM15: Conforme | AN15: Júlio Cezar Alves Santana - 13/03/2026 14:04:42 | AO15: Conforme | AP15: Warlei Carvalho - 18/03/2026 08:52:43 | BS15: Não | BT15: Sim | BU15: 46085.326 | BV15: Sim | BW15: 46084.369 | BX15: Sim | BY15: 46099.37 | BZ15: Comissionamento Estático | CA15: Conforme | CB15: Bruno Borges - 04/03/2026 07:50:03 | CC15: Conforme | CD15: Bruno Borges - 04/03/2026 07:50:04 | CE15: Conforme | CF15: Bruno Borges - 04/03/2026 07:50:06 | CG15: Conforme | CH15: Wesley Soares - 16/03/2026 08:39:16 | CI15: Conforme | CJ15: Wesley Soares - 16/03/2026 08:39:19 | CK15: Conforme | CL15: Wesley Soares - 16/03/2026 08:39:22 | CM15: Conforme | CN15: Wesley Soares - 16/03/2026 08:39:26 | CO15: Conforme | CP15: Wesley Soares - 16/03/2026 08:39:27 | DE15: Não | DF15: Sim | DG15: 46085.326 | DH15: Sim | DI15: 46097.361 | DJ15: Sim | DK15: 46097.361 | DL15: Dinâmico Frio | DM15: Conforme | DN15: Wesley Soares - 16/03/2026 08:39:34 | DO15: Conforme | DP15: Wesley Soares - 16/03/2026 08:39:37 | DQ15: Conforme | DR15: Humberto Luiz - 17/03/2026 09:04:02 | DS15: Conforme | DT15: Wesley Soares - 16/03/2026 08:39:44 | DU15: Conforme | DV15: Wesley Soares - 16/03/2026 08:39:49 | DW15: Conforme | DX15: Humberto Luiz - 17/03/2026 09:04:12 | DY15: Conforme | DZ15: Wesley Soares - 16/03/2026 08:40:03 | EA15: Conforme | EB15: Warlei Carvalho - 18/03/2026 08:52:20 | EI15: Não | EJ15: Sim | EK15: 46099.37 | EL15: Dinâmico Quente | EM15: Conforme | EN15: Júlio Cezar Alves Santana - 21/03/2026 14:08:13 | FI15: Não | FJ15: Sim | FK15: 46102.589 | FN15: Feito | FO15: 46102.589 | FP15: Júlio Cezar Alves Santana - 21/03/2026 14:08:13 | FQ15: Base de Dados_Images/DE-2001.Imagem do Equipamento-.115115.jpg | FR15: Marcos Domingues - 03/03/2026 08:51:31 | FU15: =FQ15 -> Base de Dados_Images/DE-2001.Imagem do Equipamento-.115115.jpg
A16: 10&20 - R.P.E | B16: Desfibrador | C16: Eletroímã | D16: EL-2001 | E16: Eletroíma Da Esteira Rápica De Cana Desfibrada | F16: Pré-Comissionamento | G16: Conforme | H16: Bruno Borges - 04/03/2026 07:50:15 | I16: Conforme | J16: Marcelo Pagioro - 23/03/2026 07:53:24 | K16: Conforme | L16: Marcelo Pagioro - 23/03/2026 07:53:26 | M16: Conforme | N16: Marcelo Pagioro - 23/03/2026 07:53:28 | O16: Conforme | P16: Marcelo Pagioro - 23/03/2026 07:53:31 | Q16: Conforme | R16: Marcelo Pagioro - 23/03/2026 07:53:33 | S16: Conforme | T16: Marcelo Pagioro - 23/03/2026 07:53:35 | BS16: Não | BT16: Sim | BU16: 46104.329 | BV16: Sim | BW16: 46104.329 | BX16: Sim | BY16: 46104.329 | BZ16: Comissionamento Estático | DE16: Não | DF16: Não Aplica | DH16: Não Aplica | DJ16: Não Aplica | DL16: Dinâmico Frio | DM16: Conforme | DN16: Marcelo Pagioro - 23/03/2026 07:53:42 | DO16: Não Aplicável | DP16: Marcelo Pagioro - 23/03/2026 07:53:47 | DQ16: Conforme | DR16: Glaucia Massuia - 24/03/2026 16:27:50 | EI16: Não | EJ16: Sim | EK16: 46105.686 | EL16: Dinâmico Quente | EM16: Conforme | EN16: Glaucia Massuia - 24/03/2026 16:27:54 | EO16: Conforme | EP16: Glaucia Massuia - 24/03/2026 16:27:55 | EQ16: Conforme | ER16: Glaucia Massuia - 24/03/2026 16:27:56 | FI16: Não | FJ16: Sim | FK16: 46105.686 | FN16: Feito | FO16: 46105.686 | FP16: Glaucia Massuia - 24/03/2026 16:27:56 | FQ16: Base de Dados_Images/EL-2001.Imagem do Equipamento-.115252.jpg | FR16: Marcos Domingues - 03/03/2026 08:52:46 | FU16: =FQ16 -> Base de Dados_Images/EL-2001.Imagem do Equipamento-.115252.jpg
A17: 10&20 - R.P.E | B17: Desfibrador | C17: Esteira de Borracha | D17: EB-2001 | E17: Esteira Rápida De Cana Desfibrada | F17: Pré-Comissionamento | G17: Conforme | H17: Glaucia Massuia - 18/03/2026 08:39:00 | I17: Conforme | J17: Bruno Borges - 29/01/2026 08:21:27 | K17: Conforme | L17: Bruno Borges - 29/01/2026 08:21:31 | M17: Conforme | N17: Bruno Borges - 29/01/2026 08:21:34 | O17: Conforme | P17: Bruno Borges - 29/01/2026 08:21:36 | Q17: Conforme | R17: Bruno Borges - 29/01/2026 08:21:38 | S17: Conforme | T17: Bruno Borges - 29/01/2026 08:21:41 | U17: Conforme | V17: Bruno Borges - 29/01/2026 08:21:45 | W17: Conforme | X17: Bruno Borges - 29/01/2026 08:21:51 | Y17: Conforme | Z17: Bruno Borges - 29/01/2026 08:22:03 | AA17: Conforme | AB17: Bruno Borges - 29/01/2026 08:22:07 | AC17: Conforme | AD17: Bruno Borges - 29/01/2026 08:22:11 | AE17: Conforme | AF17: Bruno Borges - 29/01/2026 08:22:14 | AG17: Conforme | AH17: Bruno Borges - 29/01/2026 08:22:22 | AI17: Conforme | AJ17: Bruno Borges - 29/01/2026 08:22:26 | AK17: Não Aplicável | AL17: Humberto Luiz - 17/03/2026 08:44:00 | AM17: Conforme | AN17: Bruno Borges - 29/01/2026 08:22:39 | AO17: Conforme | AP17: Humberto Luiz - 17/03/2026 08:44:25 | AQ17: Conforme | AR17: Marcelo Pagioro - 23/03/2026 07:54:25 | AS17: Conforme | AT17: Wesley Soares - 27/01/2026 09:12:25 | AU17: Conforme | AV17: Wesley Soares - 27/01/2026 09:12:26 | AW17: Conforme | AX17: Wesley Soares - 27/01/2026 09:12:29 | AY17: Conforme | AZ17: Wesley Soares - 27/01/2026 09:12:30 | BA17: Conforme | BB17: Wesley Soares - 27/01/2026 09:12:33 | BC17: Conforme | BD17: Wesley Soares - 27/01/2026 09:12:35 | BE17: Conforme | BF17: Alex Gomes Ferreira - 26/02/2026 09:31:26 | BG17: Conforme | BH17: Marcelo Pagioro - 24/03/2026 08:26:43 | BI17: Não Conforme | BJ17: Luiz Augusto - 11/02/2026 12:34:46 | BK17: Conforme | BL17: Marcelo Pagioro - 23/03/2026 07:54:44 | BM17: Conforme | BN17: Luiz Augusto - 11/02/2026 12:34:53 | BS17: Sim | BT17: Sim | BU17: 46104.329 | BV17: Sim | BW17: 46079.397 | BX17: Não | BZ17: Comissionamento Estático | CA17: Conforme | CB17: Bruno Borges - 10/03/2026 09:49:20 | CC17: Conforme | CD17: Bruno Borges - 10/03/2026 09:49:20 | CE17: Conforme | CF17: Alex Gomes Ferreira - 26/02/2026 09:31:42 | CG17: Conforme | CH17: Alex Gomes Ferreira - 26/02/2026 09:31:44 | CI17: Conforme | CJ17: Alex Gomes Ferreira - 26/02/2026 09:31:56 | DE17: Não | DF17: Sim | DG17: 46091.409 | DH17: Sim | DI17: 46079.397 | DJ17: Sim | DK17: 46091.409 | DL17: Dinâmico Frio | DM17: Conforme | DN17: Wesley Soares - 16/03/2026 08:41:23 | DO17: Conforme | DP17: Wesley Soares - 16/03/2026 08:41:26 | DQ17: Conforme | DR17: Wesley Soares - 16/03/2026 08:41:28 | DS17: Conforme | DT17: Humberto Luiz - 17/03/2026 08:45:08 | DU17: Conforme | DV17: Wesley Soares - 16/03/2026 08:41:33 | DW17: Conforme | DX17: Marcelo Pagioro - 23/03/2026 07:55:00 | DY17: Conforme | DZ17: Marcelo Pagioro - 23/03/2026 07:55:02 | EA17: Conforme | EB17: Marcelo Pagioro - 23/03/2026 07:55:11 | EC17: Conforme | ED17: Marcelo Pagioro - 23/03/2026 07:55:16 | EE17: Conforme | EF17: Marcelo Pagioro - 23/03/2026 07:55:22 | EG17: Conforme | EI17: Não | EJ17: Sim | EK17: 46104.33 | EL17: Dinâmico Quente | EM17: Conforme | EN17: Wesley Soares - 16/03/2026 08:41:55 | EO17: Conforme | EP17: Wesley Soares - 16/03/2026 08:41:58 | EQ17: Conforme | ER17: Marcelo Pagioro - 23/03/2026 13:02:29 | ES17: Conforme | ET17: Marcelo Pagioro - 23/03/2026 13:02:32 | EU17: Conforme | EV17: Marcelo Pagioro - 23/03/2026 13:02:34 | EW17: Conforme | EX17: Marcelo Pagioro - 23/03/2026 13:02:39 | EY17: Conforme | EZ17: Marcelo Pagioro - 23/03/2026 13:02:43 | FA17: Conforme | FB17: Marcelo Pagioro - 23/03/2026 13:02:51 | FI17: Não | FJ17: Sim | FK17: 46104.544 | FN17: Pendente | FP17: Marcelo Pagioro - 24/03/2026 08:26:43 | FQ17: Base de Dados_Images/EB-2001.Imagem do Equipamento-.115035.jpg | FR17: Humberto Luiz - 22/01/2026 08:50:28 | FU17: =FQ17 -> Base de Dados_Images/EB-2001.Imagem do Equipamento-.115035.jpg
A18: 10&20 - R.P.E | B18: Desfibrador | C18: Esteira de Borracha | D18: ER-2001 | E18: Esteira De Retorno De Cana Desfibrada | F18: Pré-Comissionamento | G18: Conforme | H18: Glaucia Massuia - 18/03/2026 08:39:15 | I18: Conforme | J18: Bruno Borges - 29/01/2026 08:31:55 | K18: Conforme | L18: Bruno Borges - 29/01/2026 08:31:56 | M18: Conforme | N18: Bruno Borges - 29/01/2026 08:31:57 | O18: Conforme | P18: Bruno Borges - 29/01/2026 08:32:00 | Q18: Conforme | R18: Bruno Borges - 29/01/2026 08:32:00 | S18: Conforme | T18: Bruno Borges - 29/01/2026 08:32:02 | U18: Conforme | V18: Bruno Borges - 29/01/2026 08:32:03 | W18: Conforme | X18: Bruno Borges - 29/01/2026 08:32:06 | Y18: Conforme | Z18: Bruno Borges - 29/01/2026 08:32:06 | AA18: Conforme | AB18: Bruno Borges - 29/01/2026 08:32:09 | AC18: Conforme | AD18: Bruno Borges - 29/01/2026 08:32:09 | AE18: Conforme | AF18: Bruno Borges - 29/01/2026 08:32:10 | AG18: Conforme | AH18: Bruno Borges - 29/01/2026 08:32:12 | AI18: Conforme | AJ18: Bruno Borges - 29/01/2026 08:32:13 | AK18: Não Aplicável | AL18: Bruno Borges - 29/01/2026 08:32:17 | AM18: Conforme | AN18: Bruno Borges - 29/01/2026 08:32:17 | AO18: Conforme | AP18: Bruno Borges - 29/01/2026 08:32:18 | AQ18: Conforme | AR18: Marcelo Pagioro - 24/03/2026 08:25:19 | AS18: Conforme | AT18: Wesley Soares - 27/01/2026 09:13:24 | AU18: Conforme | AV18: Wesley Soares - 27/01/2026 09:13:25 | AW18: Conforme | AX18: Wesley Soares - 27/01/2026 09:13:27 | AY18: Conforme | AZ18: Wesley Soares - 27/01/2026 09:13:29 | BA18: Conforme | BB18: Wesley Soares - 27/01/2026 09:13:30 | BC18: Conforme | BD18: Wesley Soares - 27/01/2026 09:13:32 | BE18: Conforme | BF18: Marcelo Pagioro - 24/03/2026 08:25:27 | BG18: Não Aplicável | BH18: Luiz Augusto - 12/02/2026 16:26:03 | BI18: Não Conforme | BJ18: Luiz Augusto - 11/02/2026 12:37:59 | BK18: Conforme | BL18: Marcelo Pagioro - 24/03/2026 08:25:46 | BM18: Conforme | BN18: Luiz Augusto - 11/02/2026 12:37:53 | BS18: Sim | BT18: Sim | BU18: 46105.351 | BV18: Sim | BW18: 46105.351 | BX18: Não | BZ18: Comissionamento Estático | CA18: Conforme | CB18: Alexandre Fernandes - 19/02/2026 09:38:34 | CC18: Conforme | CD18: Alexandre Fernandes - 19/02/2026 09:37:09 | CE18: Conforme | CF18: Wesley Soares - 16/03/2026 08:43:27 | CG18: Conforme | CH18: Wesley Soares - 16/03/2026 08:43:28 | CI18: Conforme | CJ18: Wesley Soares - 16/03/2026 08:43:31 | DE18: Não | DF18: Sim | DG18: 46072.402 | DH18: Sim | DI18: 46097.364 | DJ18: Sim | DK18: 46097.364 | DL18: Dinâmico Frio | DM18: Conforme | DN18: Humberto Luiz - 20/03/2026 09:52:23 | DO18: Conforme | DP18: Humberto Luiz - 17/03/2026 09:07:28 | DQ18: Conforme | DR18: Humberto Luiz - 17/03/2026 09:07:32 | DS18: Conforme | DT18: Humberto Luiz - 17/03/2026 09:07:40 | DU18: Conforme | DV18: Marcelo Pagioro - 23/03/2026 07:55:59 | DW18: Conforme | DX18: Marcelo Pagioro - 23/03/2026 07:56:01 | DY18: Conforme | DZ18: Marcelo Pagioro - 23/03/2026 13:03:18 | EA18: Conforme | EB18: Marcelo Pagioro - 23/03/2026 07:56:05 | EC18: Conforme | ED18: Marcelo Pagioro - 23/03/2026 07:56:07 | EE18: Conforme | EF18: Marcelo Pagioro - 23/03/2026 07:56:09 | EG18: Conforme | EI18: Não | EJ18: Sim | EK18: 46104.544 | EL18: Dinâmico Quente | EM18: Conforme | EN18: Wesley Soares - 16/03/2026 08:43:38 | EO18: Conforme | EP18: Wesley Soares - 16/03/2026 08:43:39 | EQ18: Conforme | ER18: Marcelo Pagioro - 23/03/2026 13:03:28 | ES18: Conforme | ET18: Marcelo Pagioro - 23/03/2026 13:03:29 | EU18: Conforme | EV18: Marcelo Pagioro - 23/03/2026 13:03:32 | EW18: Conforme | EX18: Marcelo Pagioro - 23/03/2026 13:03:35 | EY18: Conforme | EZ18: Marcelo Pagioro - 23/03/2026 13:03:38 | FA18: Conforme | FB18: Marcelo Pagioro - 23/03/2026 13:03:41 | FI18: Não | FJ18: Sim | FK18: 46104.544 | FN18: Pendente | FP18: Marcelo Pagioro - 24/03/2026 08:25:46 | FQ18: Base de Dados_Images/ER-2001.Imagem do Equipamento-.141832.jpg | FR18: Humberto Luiz - 22/01/2026 11:18:27 | FU18: =FQ18 -> Base de Dados_Images/ER-2001.Imagem do Equipamento-.141832.jpg
A19: 10&20 - R.P.E | B19: Desfibrador | C19: Motor e Bomba | D19: SX2005 | E19: Bomba Lub. Turbina Desfibrador | F19: Pré-Comissionamento | G19: Conforme | H19: Marcos Domingues - 10/03/2026 17:05:24 | I19: Conforme | J19: Bruno Borges - 13/03/2026 12:43:30 | K19: Conforme | L19: Bruno Borges - 13/03/2026 12:43:33 | M19: Conforme | N19: Bruno Borges - 13/03/2026 12:43:34 | O19: Conforme | P19: Bruno Borges - 13/03/2026 12:43:36 | Q19: Conforme | R19: Bruno Borges - 13/03/2026 12:43:38 | S19: Conforme | T19: Bruno Borges - 13/03/2026 12:43:42 | U19: Conforme | V19: Bruno Borges - 13/03/2026 12:43:45 | W19: Conforme | X19: Bruno Borges - 13/03/2026 12:43:47 | Y19: Não Aplicável | Z19: Bruno Borges - 13/03/2026 12:44:24 | AA19: Conforme | AB19: Marcos Domingues - 10/03/2026 17:05:31 | AC19: Conforme | AD19: Marcos Domingues - 10/03/2026 17:05:32 | AE19: Conforme | AF19: Marcos Domingues - 10/03/2026 17:05:34 | AG19: Conforme | AH19: Marcos Domingues - 10/03/2026 17:11:32 | AI19: Conforme | AJ19: Marcos Domingues - 10/03/2026 17:12:08 | AK19: Conforme | AL19: Marcos Domingues - 10/03/2026 17:12:01 | AM19: Não Aplicável | AN19: Bruno Borges - 13/03/2026 12:44:37 | AO19: Não Aplicável | AP19: Bruno Borges - 13/03/2026 12:44:39 | BS19: Não | BT19: Sim | BU19: 46094.531 | BV19: Sim | BW19: 46091.717 | BX19: Sim | BY19: 46094.531 | BZ19: Comissionamento Estático | CA19: Conforme | CB19: Bruno Borges - 13/03/2026 12:44:47 | CC19: Conforme | CD19: Bruno Borges - 13/03/2026 12:44:50 | CE19: Conforme | CF19: Bruno Borges - 13/03/2026 12:44:50 | CG19: Conforme | CH19: Marcos Domingues - 13/03/2026 11:45:23 | CI19: Conforme | CJ19: Marcos Domingues - 13/03/2026 11:45:01 | CK19: Conforme | CL19: Marcos Domingues - 13/03/2026 11:44:59 | DE19: Não | DF19: Sim | DG19: 46094.531 | DH19: Sim | DI19: 46094.49 | DJ19: Sim | DK19: 46094.531 | DL19: Dinâmico Frio | DM19: Conforme | DN19: Glaucia Massuia - 13/03/2026 13:06:25 | DO19: Conforme | DP19: Glaucia Massuia - 13/03/2026 13:06:28 | DQ19: Conforme | DR19: Glaucia Massuia - 13/03/2026 13:06:31 | DS19: Conforme | DT19: Glaucia Massuia - 13/03/2026 13:08:47 | EI19: Não | EJ19: Sim | EK19: 46094.548 | EL19: Dinâmico Quente | EM19: Conforme | EN19: Wesley Soares - 16/03/2026 08:43:55 | EO19: Conforme | EP19: Wesley Soares - 16/03/2026 08:43:57 | EQ19: Conforme | ER19: Wesley Soares - 16/03/2026 08:43:59 | ES19: Conforme | ET19: Wesley Soares - 16/03/2026 08:44:00 | FI19: Não | FJ19: Sim | FK19: 46097.364 | FN19: Feito | FO19: 46097.364 | FP19: Wesley Soares - 16/03/2026 08:44:00 | FQ19: Base de Dados_Images/SX2005.Imagem do Equipamento-.201240.jpg | FR19: Marcos Domingues - 10/03/2026 17:12:33 | FU19: =FQ19 -> Base de Dados_Images/SX2005.Imagem do Equipamento-.201240.jpg
A20: 10&20 - R.P.E | B20: Desfibrador | C20: PSV | D20: 10014512 | E20: Turbina - Desfibrador | F20: Pré-Comissionamento | G20: Conforme | H20: Bruno Borges - 14/03/2026 09:44:09 | I20: Conforme | J20: Bruno Borges - 14/03/2026 09:44:11 | K20: Conforme | L20: Bruno Borges - 14/03/2026 09:44:14 | M20: Conforme | N20: Bruno Borges - 14/03/2026 09:44:17 | O20: Conforme | P20: Bruno Borges - 14/03/2026 09:44:20 | BS20: Não | BT20: Sim | BU20: 46095.406 | BV20: Não Aplica | BX20: Sim | BY20: 46095.406 | BZ20: Comissionamento Estático | CA20: Conforme | CB20: Bruno Borges - 14/03/2026 09:44:27 | DE20: Não | DF20: Sim | DG20: 46095.406 | DH20: Não Aplica | DJ20: Sim | DK20: 46095.406 | DL20: Dinâmico Frio | EI20: Não | EJ20: Não Aplica | EL20: Dinâmico Quente | EM20: Conforme | EN20: Wesley Soares - 16/03/2026 08:44:14 | FI20: Não | FJ20: Sim | FK20: 46097.364 | FN20: Feito | FO20: 46097.364 | FP20: Wesley Soares - 16/03/2026 08:44:14 | FQ20: Base de Dados_Images/10014512.Imagem do Equipamento-.171622.jpg | FR20: Glaucia Massuia - 10/03/2026 14:16:17 | FU20: =FQ20 -> Base de Dados_Images/10014512.Imagem do Equipamento-.171622.jpg
A21: 10&20 - R.P.E | B21: Desfibrador | C21: Transmissor | D21: PSH-9005-17 | E21: Pressão Muito Alta De Vapor De Escape - Desfibrador | F21: Pré-Comissionamento | G21: Conforme | H21: Bruno Borges - 06/02/2026 08:23:04 | I21: Conforme | J21: Wesley Soares - 05/02/2026 14:56:32 | K21: Conforme | L21: Wesley Soares - 05/02/2026 14:56:35 | M21: Conforme | N21: Wesley Soares - 05/02/2026 14:56:37 | BS21: Não | BT21: Sim | BU21: 46059.349 | BV21: Sim | BW21: 46058.623 | BX21: Sim | BY21: 46059.349 | BZ21: Comissionamento Estático | CA21: Conforme | CB21: Marcos Domingues - 10/03/2026 18:20:47 | CC21: Não Aplicável | CD21: Marcos Domingues - 10/03/2026 18:20:49 | CE21: Não Aplicável | CF21: Marcos Domingues - 10/03/2026 18:20:49 | DE21: Não | DF21: Não Aplica | DH21: Sim | DI21: 46091.764 | DJ21: Sim | DK21: 46091.764 | DL21: Dinâmico Frio | DM21: Conforme | DN21: Alex Gomes Ferreira - 12/03/2026 19:42:32 | DO21: Conforme | DP21: Alex Gomes Ferreira - 12/03/2026 19:42:29 | EI21: Não | EJ21: Sim | EK21: 46093.821 | EL21: Dinâmico Quente | EM21: Conforme | EN21: Wesley Soares - 16/03/2026 08:44:22 | EO21: Conforme | EP21: Wesley Soares - 16/03/2026 08:44:24 | FI21: Não | FJ21: Sim | FK21: 46097.364 | FN21: Feito | FO21: 46097.364 | FP21: Wesley Soares - 16/03/2026 08:44:24 | FQ21: Base de Dados_Images/PSH-9005-17.Imagem do Equipamento-.175631.jpg | FR21: Wesley Soares - 05/02/2026 14:56:37 | FU21: =FQ21 -> Base de Dados_Images/PSH-9005-17.Imagem do Equipamento-.175631.jpg
A22: 10&20 - R.P.E | B22: Desfibrador | C22: Transmissor | D22: TT-9024-01 | E22: Temp. Mancal Axial Externo Turb. Desfibrador | F22: Pré-Comissionamento | G22: Conforme | H22: Bruno Borges - 04/03/2026 07:46:39 | I22: Conforme | J22: Marcos Domingues - 02/03/2026 16:31:38 | K22: Conforme | L22: Marcos Domingues - 02/03/2026 16:31:38 | M22: Conforme | N22: Marcos Domingues - 02/03/2026 16:31:39 | BS22: Não | BT22: Sim | BU22: 46085.324 | BV22: Sim | BW22: 46083.689 | BX22: Sim | BY22: 46085.324 | BZ22: Comissionamento Estático | CA22: Conforme | CB22: Marcos Domingues - 10/03/2026 22:34:43 | CC22: Não Aplicável | CD22: Marcos Domingues - 10/03/2026 22:34:43 | CE22: Não Aplicável | CF22: Marcos Domingues - 10/03/2026 22:34:44 | DE22: Não | DF22: Não Aplica | DH22: Sim | DI22: 46091.941 | DJ22: Sim | DK22: 46091.941 | DL22: Dinâmico Frio | DM22: Conforme | DN22: Marcos Domingues - 13/03/2026 11:19:38 | DO22: Conforme | DP22: Marcos Domingues - 13/03/2026 11:19:38 | EI22: Não | EJ22: Sim | EK22: 46094.472 | EL22: Dinâmico Quente | EM22: Conforme | EN22: Wesley Soares - 16/03/2026 08:45:16 | EO22: Conforme | EP22: Wesley Soares - 16/03/2026 08:45:17 | FI22: Não | FJ22: Sim | FK22: 46097.365 | FN22: Feito | FO22: 46097.365 | FP22: Wesley Soares - 16/03/2026 08:45:17 | FQ22: Base de Dados_Images/TT-9024-01.Imagem do Equipamento-.193138.jpg | FR22: Marcos Domingues - 02/03/2026 16:31:39 | FU22: =FQ22 -> Base de Dados_Images/TT-9024-01.Imagem do Equipamento-.193138.jpg
A23: 10&20 - R.P.E | B23: Desfibrador | C23: Transmissor | D23: TT-9025-01 | E23: Temp. Mancal Axial Interno Turb. Desfibrador | F23: Pré-Comissionamento | G23: Conforme | H23: Bruno Borges - 04/03/2026 07:46:46 | I23: Conforme | J23: Marcos Domingues - 02/03/2026 16:30:57 | K23: Conforme | L23: Marcos Domingues - 02/03/2026 16:30:57 | M23: Conforme | N23: Marcos Domingues - 02/03/2026 16:30:57 | BS23: Não | BT23: Sim | BU23: 46085.324 | BV23: Sim | BW23: 46083.688 | BX23: Sim | BY23: 46085.324 | BZ23: Comissionamento Estático | CA23: Conforme | CB23: Marcos Domingues - 10/03/2026 22:34:28 | CC23: Não Aplicável | CD23: Marcos Domingues - 10/03/2026 22:34:29 | CE23: Não Aplicável | CF23: Marcos Domingues - 10/03/2026 22:34:29 | DE23: Não | DF23: Não Aplica | DH23: Sim | DI23: 46091.941 | DJ23: Sim | DK23: 46091.941 | DL23: Dinâmico Frio | DM23: Conforme | DN23: Marcos Domingues - 13/03/2026 11:19:53 | DO23: Conforme | DP23: Marcos Domingues - 13/03/2026 11:19:53 | EI23: Não | EJ23: Sim | EK23: 46094.472 | EL23: Dinâmico Quente | EM23: Conforme | EN23: Wesley Soares - 16/03/2026 08:45:26 | EO23: Conforme | EP23: Wesley Soares - 16/03/2026 08:45:27 | FI23: Não | FJ23: Sim | FK23: 46097.365 | FN23: Feito | FO23: 46097.365 | FP23: Wesley Soares - 16/03/2026 08:45:27 | FQ23: Base de Dados_Images/TT-9025-01.Imagem do Equipamento-.193058.jpg | FR23: Marcos Domingues - 02/03/2026 16:30:57 | FU23: =FQ23 -> Base de Dados_Images/TT-9025-01.Imagem do Equipamento-.193058.jpg
A24: 10&20 - R.P.E | B24: Desfibrador | C24: Transmissor | D24: TT-9026-01 | E24: Temp. Mancal Radial Anterior Turb. Desfibrador | F24: Pré-Comissionamento | G24: Conforme | H24: Bruno Borges - 04/03/2026 07:46:51 | I24: Conforme | J24: Marcos Domingues - 02/03/2026 16:30:19 | K24: Conforme | L24: Marcos Domingues - 02/03/2026 16:30:19 | M24: Conforme | N24: Marcos Domingues - 02/03/2026 16:30:20 | BS24: Não | BT24: Sim | BU24: 46085.324 | BV24: Sim | BW24: 46083.688 | BX24: Sim | BY24: 46085.324 | BZ24: Comissionamento Estático | CA24: Conforme | CB24: Alex Gomes Ferreira - 12/03/2026 20:53:50 | CC24: Não Aplicável | CD24: Alex Gomes Ferreira - 12/03/2026 20:53:54 | CE24: Não Aplicável | CF24: Alex Gomes Ferreira - 12/03/2026 20:53:56 | DE24: Não | DF24: Não Aplica | DH24: Sim | DI24: 46093.871 | DJ24: Sim | DK24: 46093.871 | DL24: Dinâmico Frio | DM24: Conforme | DN24: Alex Gomes Ferreira - 12/03/2026 20:54:01 | DO24: Conforme | DP24: Alex Gomes Ferreira - 12/03/2026 20:54:03 | EI24: Não | EJ24: Sim | EK24: 46093.871 | EL24: Dinâmico Quente | EM24: Conforme | EN24: Wesley Soares - 16/03/2026 08:45:34 | EO24: Conforme | EP24: Wesley Soares - 16/03/2026 08:45:35 | FI24: Não | FJ24: Sim | FK24: 46097.365 | FN24: Feito | FO24: 46097.365 | FP24: Wesley Soares - 16/03/2026 08:45:35 | FQ24: Base de Dados_Images/TT-9026-01.Imagem do Equipamento-.193014.jpg | FR24: Marcos Domingues - 02/03/2026 16:30:20 | FU24: =FQ24 -> Base de Dados_Images/TT-9026-01.Imagem do Equipamento-.193014.jpg
